File: StepStrainSweepPressure2_2.csv
Time,Displacement,Tensile strain (Displacement),Force
(ms),(mm),(%),(N)
"0.0000","-0.2242","-0.2577","0.0001"
"160.0000","-0.2184","-0.2510","-0.0091"
"320.0000","-0.2188","-0.2515","-0.0140"
"480.0000","-0.2193","-0.2520","-0.0162"
"640.0000","-0.2197","-0.2525","-0.0157"
"800.0000","-0.2200","-0.2529","-0.0162"
"960.0000","-0.2203","-0.2532","-0.0155"
"1120.0000","-0.2204","-0.2534","-0.0172"
"1280.0000","-0.2206","-0.2535","-0.0175"
"1440.0001","-0.2206","-0.2536","-0.0168"
"1600.0000","-0.2207","-0.2537","-0.0170"
"1760.0000","-0.2207","-0.2537","-0.0169"
"1920.0000","-0.2208","-0.2538","-0.0164"
"2079.9999","-0.2208","-0.2538","-0.0167"
"2240.0000","-0.2208","-0.2538","-0.0165"
"2400.0001","-0.2208","-0.2538","-0.0167"
"2559.9999","-0.2208","-0.2538","-0.0174"
"2720.0000","-0.2208","-0.2538","-0.0172"
"2880.0001","-0.2208","-0.2538","-0.0172"
"3040.0000","-0.2208","-0.2538","-0.0167"
"3200.0000","-0.2208","-0.2538","-0.0173"
"3359.9999","-0.2208","-0.2538","-0.0173"
"3520.0000","-0.2208","-0.2538","-0.0171"
"3680.0001","-0.2208","-0.2538","-0.0174"
"3839.9999","-0.2208","-0.2538","-0.0173"
"4000.0000","-0.2208","-0.2538","-0.0177"
"4159.9998","-0.2208","-0.2538","-0.0173"
"4320.0002","-0.2208","-0.2538","-0.0172"
"4480.0000","-0.2208","-0.2538","-0.0174"
"4639.9999","-0.2208","-0.2538","-0.0171"
"4800.0002","-0.2208","-0.2538","-0.0173"
"4960.0000","-0.2208","-0.2538","-0.0175"
"5119.9999","-0.2208","-0.2538","-0.0169"
"5280.0002","-0.2208","-0.2538","-0.0173"
"5440.0001","-0.2208","-0.2538","-0.0170"
"5599.9999","-0.2208","-0.2538","-0.0175"
"5760.0002","-0.2208","-0.2538","-0.0171"
"5920.0001","-0.2208","-0.2538","-0.0174"
"6079.9999","-0.2208","-0.2538","-0.0176"
"6239.9998","-0.2208","-0.2538","-0.0175"
"6400.0001","-0.2208","-0.2538","-0.0165"
"6559.9999","-0.2208","-0.2538","-0.0183"
"6719.9998","-0.2208","-0.2538","-0.0180"
"6880.0001","-0.2208","-0.2538","-0.0179"
"7040.0000","-0.2208","-0.2538","-0.0180"
"7199.9998","-0.2208","-0.2538","-0.0181"
"7360.0001","-0.2208","-0.2538","-0.0179"
"7520.0000","-0.2208","-0.2538","-0.0182"
"7679.9998","-0.2208","-0.2538","-0.0176"
"7840.0002","-0.2208","-0.2538","-0.0175"
"8000.0000","-0.2208","-0.2538","-0.0175"
"8159.9998","-0.2208","-0.2538","-0.0181"
"8319.9997","-0.2208","-0.2538","-0.0180"
"8479.9995","-0.2208","-0.2538","-0.0180"
"8640.0003","-0.2208","-0.2538","-0.0175"
"8800.0002","-0.2208","-0.2538","-0.0176"
"8960.0000","-0.2208","-0.2538","-0.0177"
"9119.9999","-0.2208","-0.2538","-0.0177"
"9279.9997","-0.2208","-0.2538","-0.0180"
"9439.9996","-0.2208","-0.2538","-0.0174"
"9600.0004","-0.2208","-0.2538","-0.0177"
"9760.0002","-0.2208","-0.2538","-0.0175"
"9920.0001","-0.2208","-0.2538","-0.0177"
"10053.0005","-0.2252","-0.2588","-0.0251"
"10213.0003","-0.3548","-0.4079","-0.1095"
"10373.0001","-0.4874","-0.5603","-0.1651"
"10533.0000","-0.6207","-0.7135","-0.2116"
"10692.9998","-0.7540","-0.8667","-0.2534"
"10852.9997","-0.8875","-1.0201","-0.2908"
"11012.9995","-1.0210","-1.1735","-0.3269"
"11173.0003","-1.1540","-1.3264","-0.3679"
"11333.0002","-1.2872","-1.4795","-0.4293"
"11493.0000","-1.4207","-1.6330","-0.4995"
"11652.9999","-1.5540","-1.7863","-0.5759"
"11812.9997","-1.6875","-1.9396","-0.6590"
"11972.9996","-1.8207","-2.0928","-0.7428"
"12133.0004","-1.9538","-2.2458","-0.8256"
"12293.0002","-2.0873","-2.3992","-0.9077"
"12453.0001","-2.2208","-2.5526","-0.9894"
"12612.9999","-2.3541","-2.7058","-1.0726"
"12772.9998","-2.4874","-2.8590","-1.1567"
"12932.9996","-2.6206","-3.0122","-1.2410"
"13093.0004","-2.7539","-3.1655","-1.3269"
"13253.0003","-2.8875","-3.3189","-1.4152"
"13413.0001","-3.0206","-3.4720","-1.5048"
"13573.0000","-3.1538","-3.6251","-1.5969"
"13732.9998","-3.2873","-3.7785","-1.6911"
"13892.9996","-3.4206","-3.9318","-1.7881"
"14053.0005","-3.5541","-4.0851","-1.8858"
"14213.0003","-3.6874","-4.2384","-1.9867"
"14373.0001","-3.8206","-4.3915","-2.0910"
"14533.0000","-3.9540","-4.5448","-2.1978"
"14692.9998","-4.0875","-4.6983","-2.3071"
"14852.9997","-4.2207","-4.8514","-2.4166"
"15012.9995","-4.3539","-5.0045","-2.5275"
"15173.0003","-4.4872","-5.1577","-2.6396"
"15333.0002","-4.6205","-5.3110","-2.7516"
"15493.0000","-4.7541","-5.4645","-2.8653"
"15652.9999","-4.8874","-5.6177","-2.9789"
"15812.9997","-5.0206","-5.7708","-3.0932"
"15972.9996","-5.1539","-5.9241","-3.2079"
"16132.9994","-5.2872","-6.0773","-3.3231"
"16292.9993","-5.4206","-6.2306","-3.4385"
"16452.9991","-5.5542","-6.3841","-3.5555"
"16613.0009","-5.6873","-6.5371","-3.6721"
"16773.0007","-5.8205","-6.6902","-3.7895"
"16933.0006","-5.9540","-6.8436","-3.9079"
"17093.0004","-6.0873","-6.9969","-4.0267"
"17253.0003","-6.2207","-7.1503","-4.1460"
"17413.0001","-6.3541","-7.3035","-4.2653"
"17573.0000","-6.4872","-7.4566","-4.3854"
"17732.9998","-6.6207","-7.6100","-4.5062"
"17892.9996","-6.7541","-7.7633","-4.6275"
"18052.9995","-6.8873","-7.9164","-4.7494"
"18212.9993","-7.0207","-8.0698","-4.8726"
"18372.9992","-7.1540","-8.2229","-4.9967"
"18533.0009","-7.2873","-8.3762","-5.1205"
"18693.0008","-7.4208","-8.5296","-5.2462"
"18853.0006","-7.5540","-8.6828","-5.3720"
"19013.0005","-7.6871","-8.8358","-5.4983"
"19173.0003","-7.8207","-8.9893","-5.6265"
"19333.0002","-7.9541","-9.1426","-5.7556"
"19493.0000","-8.0873","-9.2958","-5.8852"
"19652.9999","-8.2207","-9.4491","-6.0155"
"19812.9997","-8.3539","-9.6022","-6.1457"
"19972.9996","-8.4873","-9.7555","-6.2773"
"20132.9994","-8.6209","-9.9090","-6.4104"
"20292.9993","-8.7540","-10.0621","-6.5433"
"20452.9991","-8.8873","-10.2152","-6.6769"
"20613.0009","-9.0205","-10.3684","-6.8126"
"20773.0007","-9.1539","-10.5217","-6.9503"
"20933.0006","-9.2875","-10.6753","-7.0907"
"21093.0004","-9.4208","-10.8285","-7.2334"
"21253.0003","-9.5539","-10.9814","-7.3768"
"21413.0001","-9.6872","-11.1347","-7.5238"
"21573.0000","-9.8206","-11.2880","-7.6728"
"21732.9998","-9.9540","-11.4414","-7.8243"
"21850.9998","-10.0138","-11.5101","-7.8509"
"22010.9997","-10.0080","-11.5034","-7.7851"
"22170.9995","-10.0040","-11.4989","-7.7325"
"22330.9994","-10.0018","-11.4963","-7.6866"
"22490.9992","-10.0008","-11.4952","-7.6463"
"22650.9991","-10.0003","-11.4946","-7.6088"
"22811.0008","-10.0001","-11.4944","-7.5737"
"22971.0007","-10.0000","-11.4942","-7.5400"
"23131.0005","-10.0000","-11.4942","-7.5083"
"23291.0004","-9.9999","-11.4942","-7.4776"
"23451.0002","-9.9999","-11.4942","-7.4502"
"23611.0001","-9.9999","-11.4942","-7.4283"
"23770.9999","-9.9999","-11.4942","-7.4068"
"23930.9998","-9.9999","-11.4942","-7.3863"
"24090.9996","-9.9999","-11.4942","-7.3614"
"24250.9995","-10.0000","-11.4942","-7.3396"
"24410.9993","-10.0000","-11.4942","-7.3216"
"24570.9991","-10.0000","-11.4942","-7.3168"
"24731.0009","-10.0000","-11.4942","-7.4152"
"24891.0007","-10.0000","-11.4942","-7.8509"
"25051.0006","-10.0000","-11.4942","-9.2468"
"25211.0004","-10.0000","-11.4942","-10.9231"
"25371.0003","-10.0000","-11.4942","-12.6533"
"25531.0001","-10.0000","-11.4942","-14.6434"
"25691.0000","-10.0000","-11.4942","-16.5686"
"25850.0004","-10.0000","-11.4942","-18.4845"
"25988.0009","-10.0000","-11.4942","-20.5224"
"26138.9999","-10.0000","-11.4942","-22.5763"
"26298.9998","-10.0000","-11.4942","-24.6218"
"26454.0005","-10.0000","-11.4942","-26.6630"
"26613.0009","-10.0000","-11.4942","-28.7192"
"26764.9994","-10.0000","-11.4942","-30.7862"
"26919.0006","-10.0000","-11.4942","-32.7495"
"26993.0000","-10.0000","-11.4942","-31.2292"
"27020.9999","-10.0000","-11.4942","-28.9811"
"27117.0006","-10.0000","-11.4942","-26.9733"
"27277.0004","-10.0000","-11.4942","-27.2655"
"27437.0003","-10.0000","-11.4942","-27.7574"
"27597.0001","-10.0000","-11.4942","-27.9677"
"27757.0000","-10.0000","-11.4942","-28.0831"
"27916.9998","-10.0000","-11.4942","-28.4499"
"28076.9997","-10.0000","-11.4942","-28.8093"
"28236.9995","-10.0000","-11.4942","-29.2707"
"28396.9994","-10.0000","-11.4942","-29.7582"
"28556.9992","-10.0000","-11.4942","-30.1548"
"28716.9991","-10.0000","-11.4942","-30.5963"
"28877.0008","-10.0000","-11.4942","-31.0554"
"29037.0007","-10.0000","-11.4942","-31.2879"
"29197.0005","-10.0000","-11.4942","-31.4587"
"29357.0004","-10.0000","-11.4942","-31.5830"
"29517.0002","-10.0000","-11.4942","-31.7200"
"29677.0000","-10.0000","-11.4942","-31.7798"
"29836.9999","-10.0000","-11.4942","-31.9437"
"29996.9997","-10.0000","-11.4942","-32.1886"
"30156.9996","-10.0000","-11.4942","-32.8662"
"30316.9994","-10.0000","-11.4942","-33.4374"
"30476.9993","-10.0000","-11.4942","-34.0152"
"30636.9991","-10.0000","-11.4942","-34.5333"
"30797.0009","-10.0000","-11.4942","-34.8590"
"30957.0007","-10.0000","-11.4942","-34.9557"
"31117.0006","-10.0000","-11.4942","-35.1858"
"31277.0004","-10.0000","-11.4942","-35.5142"
"31437.0003","-10.0000","-11.4942","-35.7649"
"31597.0001","-10.0000","-11.4942","-35.9871"
"31757.0000","-10.0000","-11.4942","-36.2258"
"31913.0001","-10.0000","-11.4942","-35.8954"
"32073.0019","-10.0000","-11.4942","-36.0641"
"32233.0017","-10.0000","-11.4942","-35.8950"
"32393.0016","-10.0000","-11.4942","-35.7358"
"32553.0014","-10.0000","-11.4942","-35.5740"
"32713.0013","-10.0000","-11.4942","-34.7940"
"32873.0011","-10.0000","-11.4942","-33.5987"
"33033.0009","-10.0000","-11.4942","-32.6276"
"33193.0008","-10.0000","-11.4942","-31.7571"
"33353.0006","-10.0000","-11.4942","-31.0317"
"33513.0005","-10.0000","-11.4942","-30.3177"
"33673.0003","-10.0000","-11.4942","-29.6291"
"33833.0002","-10.0000","-11.4942","-29.0846"
"33993.0000","-10.0000","-11.4942","-28.5311"
"34152.9999","-10.0000","-11.4942","-27.9256"
"34312.9997","-10.0000","-11.4943","-27.7648"
"34472.9996","-10.0000","-11.4942","-27.3911"
"34632.9994","-10.0000","-11.4942","-26.9453"
"34792.9993","-10.0000","-11.4942","-26.4842"
"34952.9991","-10.0000","-11.4943","-26.0529"
"35112.9990","-10.0000","-11.4942","-25.6304"
"35272.9988","-10.0000","-11.4942","-25.2004"
"35432.9987","-10.0000","-11.4942","-24.8087"
"35592.9985","-10.0000","-11.4942","-24.3734"
"35752.9984","-10.0000","-11.4942","-24.0195"
"35912.9982","-10.0000","-11.4942","-23.7286"
"36073.0019","-10.0000","-11.4942","-23.4114"
"36233.0017","-10.0000","-11.4942","-23.1291"
"36393.0016","-10.0000","-11.4942","-22.8850"
"36553.0014","-10.0000","-11.4942","-22.6473"
"36713.0013","-10.0000","-11.4942","-22.4100"
"36873.0011","-10.0000","-11.4942","-22.1552"
"37033.0009","-10.0000","-11.4942","-21.8249"
"37193.0008","-10.0000","-11.4942","-21.4720"
"37353.0006","-10.0000","-11.4942","-21.1277"
"37513.0005","-10.0000","-11.4942","-20.7967"
"37673.0003","-10.0000","-11.4942","-20.4811"
"37833.0002","-10.0000","-11.4942","-20.1927"
"37993.0000","-10.0000","-11.4942","-19.9109"
"38152.9999","-10.0000","-11.4942","-19.6274"
"38312.9997","-10.0000","-11.4942","-19.3513"
"38472.9996","-10.0000","-11.4942","-19.0314"
"38632.9994","-10.0000","-11.4943","-18.6883"
"38792.9993","-10.0000","-11.4942","-18.3278"
"38952.9991","-10.0000","-11.4942","-17.8942"
"39112.9990","-10.0000","-11.4942","-17.4456"
"39272.9988","-10.0000","-11.4942","-17.0063"
"39432.9987","-10.0000","-11.4943","-16.6452"
"39592.9985","-10.0000","-11.4942","-16.3762"
"39752.9984","-10.0000","-11.4942","-16.1107"
"39912.9982","-10.0000","-11.4942","-15.9299"
"40073.0019","-10.0000","-11.4942","-15.7433"
"40233.0017","-10.0000","-11.4942","-15.7101"
"40393.0016","-10.0000","-11.4942","-15.4925"
"40553.0014","-10.0000","-11.4942","-15.2027"
"40713.0013","-10.0000","-11.4942","-15.2598"
"40873.0011","-10.0000","-11.4942","-15.3029"
"41033.0009","-10.0000","-11.4942","-15.1371"
"41193.0008","-10.0000","-11.4942","-14.8715"
"41353.0006","-10.0000","-11.4942","-14.5881"
"41513.0005","-10.0000","-11.4942","-14.1939"
"41673.0003","-10.0000","-11.4942","-13.8783"
"41833.0002","-10.0000","-11.4942","-13.6566"
"41993.0000","-10.0000","-11.4942","-13.4261"
"42152.9999","-10.0000","-11.4942","-13.1636"
"42312.9997","-10.0000","-11.4942","-12.8392"
"42472.9996","-10.0000","-11.4942","-12.3207"
"42632.9994","-10.0000","-11.4942","-11.7389"
"42792.9993","-10.0000","-11.4942","-11.2034"
"42952.9991","-10.0000","-11.4943","-10.7634"
"43112.9990","-10.0000","-11.4943","-10.3309"
"43272.9988","-10.0000","-11.4942","-9.8444"
"43432.9987","-10.0000","-11.4943","-9.2798"
"43592.9985","-10.0000","-11.4943","-8.7841"
"43752.9984","-10.0000","-11.4943","-8.4161"
"43912.9982","-10.0000","-11.4943","-8.0186"
"44073.0019","-10.0000","-11.4943","-7.7934"
"44233.0017","-10.0000","-11.4943","-7.6104"
"44393.0016","-10.0000","-11.4943","-7.3271"
"44553.0014","-10.0000","-11.4943","-7.2237"
"44713.0013","-10.0000","-11.4943","-7.2260"
"44873.0011","-10.0000","-11.4943","-7.2550"
"45033.0009","-10.0000","-11.4943","-7.2797"
"45193.0008","-10.0000","-11.4943","-7.2953"
"45353.0006","-10.0000","-11.4942","-7.3049"
"45513.0005","-10.0000","-11.4943","-7.3114"
"45673.0003","-10.0000","-11.4942","-7.3119"
"45833.0002","-10.0000","-11.4942","-7.3089"
"45993.0000","-10.0000","-11.4942","-7.3045"
"46152.9999","-10.0000","-11.4942","-7.2993"
"46312.9997","-10.0000","-11.4942","-7.2906"
"46472.9996","-10.0000","-11.4943","-7.2800"
"46632.9994","-10.0000","-11.4942","-7.2703"
"46792.9993","-10.0000","-11.4942","-7.2580"
"46952.9991","-10.0000","-11.4942","-7.2448"
"47112.9990","-10.0000","-11.4943","-7.2313"
"47272.9988","-10.0000","-11.4943","-7.2168"
"47432.9987","-10.0000","-11.4942","-7.2017"
"47592.9985","-10.0000","-11.4943","-7.1857"
"47752.9984","-10.0000","-11.4943","-7.1695"
"47912.9982","-10.0000","-11.4943","-7.1528"
"48073.0019","-10.0000","-11.4943","-7.1359"
"48233.0017","-10.0000","-11.4942","-7.1186"
"48393.0016","-10.0000","-11.4942","-7.1009"
"48553.0014","-10.0000","-11.4942","-7.0841"
"48713.0013","-10.0000","-11.4942","-7.0654"
"48873.0011","-10.0000","-11.4942","-7.0475"
"49033.0009","-10.0000","-11.4942","-7.0290"
"49193.0008","-10.0000","-11.4942","-7.0107"
"49353.0006","-10.0000","-11.4942","-6.9924"
"49513.0005","-10.0000","-11.4942","-6.9741"
"49673.0003","-10.0000","-11.4943","-6.9554"
"49833.0002","-10.0000","-11.4942","-6.9371"
"49993.0000","-10.0000","-11.4942","-6.9185"
"50152.9999","-10.0000","-11.4942","-6.9001"
"50312.9997","-10.0000","-11.4942","-6.8820"
"50472.9996","-10.0000","-11.4942","-6.8636"
"50632.9994","-10.0000","-11.4942","-6.8456"
"50792.9993","-10.0000","-11.4942","-6.8282"
"50952.9991","-10.0000","-11.4943","-6.8104"
"51112.9990","-10.0000","-11.4942","-6.7922"
"51272.9988","-10.0000","-11.4943","-6.7745"
"51432.9987","-10.0000","-11.4942","-6.7563"
"51592.9985","-10.0000","-11.4943","-6.7388"
"51752.9984","-10.0000","-11.4943","-6.7208"
"51872.0016","-9.9940","-11.4873","-6.6926"
"52032.0015","-9.9395","-11.4248","-6.5839"
"52192.0013","-9.8869","-11.3642","-6.4875"
"52352.0012","-9.8338","-11.3033","-6.3944"
"52512.0010","-9.7806","-11.2421","-6.3051"
"52672.0009","-9.7273","-11.1808","-6.2174"
"52832.0007","-9.6740","-11.1195","-6.1313"
"52992.0006","-9.6207","-11.0583","-6.0479"
"53152.0004","-9.5674","-10.9971","-5.9662"
"53312.0003","-9.5141","-10.9357","-5.8859"
"53472.0001","-9.4607","-10.8744","-5.8067"
"53632.0000","-9.4074","-10.8131","-5.7284"
"53791.9998","-9.3541","-10.7518","-5.6518"
"53951.9997","-9.3006","-10.6903","-5.5753"
"54111.9995","-9.2473","-10.6291","-5.4994"
"54271.9994","-9.1940","-10.5678","-5.4231"
"54431.9992","-9.1406","-10.5065","-5.3473"
"54591.9991","-9.0872","-10.4451","-5.2713"
"54751.9989","-9.0340","-10.3839","-5.1953"
"54911.9987","-8.9807","-10.3227","-5.1362"
"55071.9986","-8.9274","-10.2613","-5.0575"
"55231.9984","-8.8740","-10.2000","-4.9817"
"55391.9983","-8.8207","-10.1387","-4.9069"
"55551.9981","-8.7673","-10.0774","-4.8326"
"55712.0018","-8.7139","-10.0160","-4.7579"
"55872.0016","-8.6606","-9.9547","-4.6845"
"56032.0015","-8.6073","-9.8934","-4.6124"
"56192.0013","-8.5539","-9.8320","-4.5400"
"56352.0012","-8.5004","-9.7706","-4.4684"
"56512.0010","-8.4473","-9.7095","-4.3976"
"56672.0009","-8.3939","-9.6481","-4.3273"
"56832.0007","-8.3406","-9.5869","-4.2574"
"56992.0006","-8.2873","-9.5256","-4.1887"
"57152.0004","-8.2340","-9.4644","-4.1209"
"57312.0003","-8.1805","-9.4029","-4.0534"
"57472.0001","-8.1273","-9.3417","-3.9862"
"57632.0000","-8.0739","-9.2803","-3.9199"
"57791.9998","-8.0206","-9.2191","-3.8539"
"57951.9997","-7.9672","-9.1577","-3.7887"
"58111.9995","-7.9138","-9.0963","-3.7291"
"58271.9994","-7.8605","-9.0351","-3.6647"
"58431.9992","-7.8073","-8.9739","-3.6009"
"58591.9991","-7.7539","-8.9125","-3.5364"
"58751.9989","-7.7005","-8.8512","-3.4730"
"58911.9987","-7.6474","-8.7901","-3.4100"
"59071.9986","-7.5939","-8.7287","-3.3472"
"59231.9984","-7.5406","-8.6674","-3.2845"
"59391.9983","-7.4873","-8.6061","-3.2227"
"59551.9981","-7.4339","-8.5448","-3.1615"
"59712.0018","-7.3805","-8.4834","-3.1013"
"59872.0016","-7.3273","-8.4221","-3.0407"
"60032.0015","-7.2738","-8.3607","-2.9811"
"60192.0013","-7.2206","-8.2996","-2.9217"
"60352.0012","-7.1672","-8.2382","-2.8631"
"60512.0010","-7.1139","-8.1769","-2.8044"
"60672.0009","-7.0606","-8.1157","-2.7466"
"60832.0007","-7.0075","-8.0546","-2.6901"
"60992.0006","-6.9540","-7.9931","-2.6355"
"61152.0004","-6.9007","-7.9318","-2.5819"
"61312.0003","-6.8475","-7.8707","-2.5244"
"61472.0001","-6.7940","-7.8092","-2.4680"
"61632.0000","-6.7406","-7.7478","-2.4123"
"61791.9998","-6.6874","-7.6867","-2.3585"
"61951.9997","-6.6339","-7.6252","-2.3050"
"62111.9995","-6.5805","-7.5638","-2.2525"
"62271.9994","-6.5274","-7.5027","-2.2012"
"62431.9992","-6.4739","-7.4413","-2.1498"
"62591.9991","-6.4206","-7.3800","-2.0986"
"62751.9989","-6.3674","-7.3188","-2.0495"
"62911.9987","-6.3140","-7.2575","-2.0002"
"63071.9986","-6.2607","-7.1962","-1.9519"
"63231.9984","-6.2074","-7.1350","-1.9046"
"63391.9983","-6.1538","-7.0734","-1.8572"
"63551.9981","-6.1007","-7.0123","-1.8114"
"63712.0018","-6.0473","-6.9509","-1.7662"
"63872.0016","-5.9938","-6.8894","-1.7219"
"64031.9977","-5.9406","-6.8282","-1.6781"
"64192.0013","-5.8873","-6.7670","-1.6351"
"64351.9974","-5.8338","-6.7055","-1.5917"
"64512.0010","-5.7806","-6.6444","-1.5502"
"64671.9971","-5.7274","-6.5832","-1.5095"
"64832.0007","-5.6739","-6.5217","-1.4685"
"64991.9968","-5.6207","-6.4605","-1.4280"
"65152.0004","-5.5674","-6.3993","-1.3886"
"65311.9965","-5.5139","-6.3379","-1.3493"
"65472.0001","-5.4606","-6.2766","-1.3102"
"65632.0038","-5.4073","-6.2153","-1.2732"
"65791.9998","-5.3538","-6.1538","-1.2358"
"65952.0035","-5.3006","-6.0927","-1.2000"
"66111.9995","-5.2471","-6.0312","-1.1637"
"66272.0032","-5.1940","-5.9702","-1.1272"
"66431.9992","-5.1407","-5.9088","-1.0909"
"66592.0029","-5.0874","-5.8475","-1.0544"
"66751.9989","-5.0339","-5.7861","-1.0184"
"66856.0028","-4.9993","-5.7463","-0.9947"
"67015.9988","-4.9877","-5.7330","-0.9966"
"67176.0025","-4.9890","-5.7345","-1.0032"
"67335.9985","-4.9903","-5.7359","-1.0076"
"67496.0022","-4.9911","-5.7369","-1.0126"
"67655.9982","-4.9917","-5.7376","-1.0220"
"67816.0019","-4.9921","-5.7380","-1.1687"
"67975.9979","-4.9923","-5.7382","-2.3390"
"68122.0016","-4.9924","-5.7384","-4.3752"
"68258.0032","-4.9924","-5.7384","-6.4225"
"68397.0032","-4.9925","-5.7385","-8.4638"
"68552.0020","-4.9925","-5.7385","-10.5303"
"68703.0029","-4.9925","-5.7385","-12.5970"
"68862.9990","-4.9925","-5.7385","-14.5427"
"69018.9972","-4.9925","-5.7385","-16.5431"
"69166.9998","-4.9925","-5.7385","-18.6160"
"69320.9991","-4.9925","-5.7385","-20.6776"
"69477.9968","-4.9925","-5.7385","-22.6020"
"69638.0005","-4.9925","-5.7385","-23.7631"
"69797.9965","-4.9925","-5.7385","-23.9928"
"69958.0002","-4.9925","-5.7385","-24.0326"
"70117.9962","-4.9925","-5.7385","-24.3146"
"70277.9999","-4.9925","-5.7385","-24.5449"
"70438.0035","-4.9925","-5.7385","-24.8073"
"70597.9996","-4.9925","-5.7385","-25.0572"
"70758.0032","-4.9925","-5.7385","-25.2546"
"70917.9993","-4.9925","-5.7385","-25.4987"
"71078.0029","-4.9925","-5.7385","-25.7577"
"71237.9990","-4.9925","-5.7385","-25.9668"
"71398.0026","-4.9925","-5.7385","-26.1730"
"71557.9987","-4.9925","-5.7385","-26.5012"
"71718.0023","-4.9925","-5.7385","-26.8460"
"71877.9984","-4.9925","-5.7385","-27.1140"
"72038.0020","-4.9925","-5.7385","-27.3079"
"72197.9980","-4.9925","-5.7385","-27.4677"
"72358.0017","-4.9925","-5.7385","-27.3687"
"72517.9977","-4.9925","-5.7385","-27.1730"
"72678.0014","-4.9925","-5.7385","-27.0271"
"72837.9974","-4.9925","-5.7385","-26.8997"
"72998.0011","-4.9925","-5.7385","-26.7842"
"73157.9971","-4.9925","-5.7385","-26.6847"
"73318.0008","-4.9925","-5.7385","-26.6176"
"73477.9968","-4.9925","-5.7385","-26.6490"
"73638.0005","-4.9925","-5.7385","-26.5590"
"73797.9965","-4.9925","-5.7385","-26.4764"
"73958.0002","-4.9925","-5.7385","-26.4017"
"74117.9962","-4.9925","-5.7385","-26.3306"
"74277.9999","-4.9925","-5.7385","-26.2640"
"74438.0035","-4.9925","-5.7385","-26.1970"
"74597.9996","-4.9925","-5.7385","-26.1338"
"74758.0032","-4.9925","-5.7385","-26.0478"
"74917.9993","-4.9925","-5.7385","-25.4874"
"75078.0029","-4.9925","-5.7385","-24.5547"
"75237.9990","-4.9925","-5.7385","-23.5319"
"75398.0026","-4.9925","-5.7385","-22.5473"
"75557.9987","-4.9925","-5.7385","-21.8019"
"75718.0023","-4.9925","-5.7385","-21.1305"
"75877.9984","-4.9925","-5.7385","-20.5045"
"76038.0020","-4.9925","-5.7385","-19.9273"
"76197.9980","-4.9925","-5.7385","-19.3798"
"76358.0017","-4.9925","-5.7385","-18.8308"
"76517.9977","-4.9925","-5.7385","-18.2790"
"76678.0014","-4.9925","-5.7385","-17.7507"
"76837.9974","-4.9925","-5.7385","-17.2357"
"76998.0011","-4.9925","-5.7385","-16.7598"
"77157.9971","-4.9925","-5.7385","-16.2817"
"77318.0008","-4.9925","-5.7385","-15.6569"
"77477.9968","-4.9925","-5.7385","-15.0343"
"77638.0005","-4.9925","-5.7385","-14.3903"
"77797.9965","-4.9925","-5.7385","-13.7848"
"77958.0002","-4.9925","-5.7385","-13.2298"
"78117.9962","-4.9925","-5.7385","-12.6843"
"78277.9999","-4.9925","-5.7385","-12.0955"
"78438.0035","-4.9925","-5.7385","-11.4946"
"78597.9996","-4.9925","-5.7385","-10.9269"
"78758.0032","-4.9925","-5.7385","-10.3766"
"78917.9993","-4.9925","-5.7385","-9.7709"
"79078.0029","-4.9925","-5.7385","-9.1430"
"79237.9990","-4.9925","-5.7385","-8.6092"
"79398.0026","-4.9925","-5.7385","-8.0706"
"79557.9987","-4.9925","-5.7385","-7.5239"
"79718.0023","-4.9925","-5.7385","-6.9782"
"79877.9984","-4.9925","-5.7385","-6.4939"
"80038.0020","-4.9925","-5.7385","-5.9949"
"80197.9980","-4.9925","-5.7385","-5.5402"
"80358.0017","-4.9925","-5.7385","-5.1115"
"80517.9977","-4.9925","-5.7385","-4.7361"
"80678.0014","-4.9925","-5.7385","-4.6354"
"80837.9974","-4.9925","-5.7385","-4.7003"
"80998.0011","-4.9925","-5.7385","-4.7419"
"81157.9971","-4.9925","-5.7385","-4.7521"
"81318.0008","-4.9925","-5.7385","-4.5567"
"81477.9968","-4.9925","-5.7385","-3.9363"
"81638.0005","-4.9925","-5.7385","-3.6702"
"81797.9965","-4.9925","-5.7385","-3.5110"
"81958.0002","-4.9925","-5.7385","-3.4242"
"82117.9962","-4.9925","-5.7385","-3.3716"
"82277.9999","-4.9925","-5.7385","-3.2371"
"82438.0035","-4.9925","-5.7385","-3.0516"
"82597.9996","-4.9925","-5.7385","-2.7895"
"82758.0032","-4.9925","-5.7385","-2.7693"
"82917.9993","-4.9925","-5.7385","-2.7984"
"83078.0029","-4.9925","-5.7385","-2.8186"
"83237.9990","-4.9925","-5.7385","-2.8348"
"83398.0026","-4.9925","-5.7385","-2.8483"
"83557.9987","-4.9925","-5.7385","-2.8579"
"83718.0023","-4.9925","-5.7385","-2.8658"
"83877.9984","-4.9925","-5.7385","-2.8713"
"84038.0020","-4.9925","-5.7385","-2.8760"
"84197.9980","-4.9925","-5.7385","-2.8799"
"84358.0017","-4.9925","-5.7385","-2.8809"
"84517.9977","-4.9925","-5.7385","-2.8812"
"84678.0014","-4.9925","-5.7385","-2.8815"
"84837.9974","-4.9925","-5.7385","-2.8798"
"84998.0011","-4.9925","-5.7385","-2.8782"
"85157.9971","-4.9925","-5.7385","-2.8752"
"85318.0008","-4.9925","-5.7385","-2.8711"
"85477.9968","-4.9925","-5.7385","-2.8678"
"85638.0005","-4.9925","-5.7385","-2.8618"
"85797.9965","-4.9925","-5.7385","-2.8565"
"85958.0002","-4.9925","-5.7385","-2.8520"
"86117.9962","-4.9925","-5.7385","-2.8461"
"86277.9999","-4.9925","-5.7385","-2.8412"
"86438.0035","-4.9925","-5.7385","-2.8361"
"86597.9996","-4.9925","-5.7385","-2.8280"
"86758.0032","-4.9925","-5.7385","-2.8221"
"86917.9993","-4.9925","-5.7385","-2.8158"
"87078.0029","-4.9925","-5.7385","-2.8087"
"87237.9990","-4.9925","-5.7385","-2.8027"
"87398.0026","-4.9925","-5.7385","-2.7960"
"87557.9987","-4.9925","-5.7385","-2.7889"
"87718.0023","-4.9925","-5.7385","-2.7823"
"87877.9984","-4.9925","-5.7385","-2.7746"
"88038.0020","-4.9925","-5.7385","-2.7677"
"88197.9980","-4.9925","-5.7385","-2.7618"
"88358.0017","-4.9925","-5.7385","-2.7540"
"88517.9977","-4.9925","-5.7385","-2.7475"
"88678.0014","-4.9925","-5.7385","-2.7393"
"88837.9974","-4.9925","-5.7385","-2.7320"
"88998.0011","-4.9925","-5.7385","-2.7253"
"89157.9971","-4.9925","-5.7385","-2.7168"
"89318.0008","-4.9925","-5.7385","-2.7109"
"89477.9968","-4.9925","-5.7385","-2.7044"
"89638.0005","-4.9925","-5.7385","-2.6976"
"89797.9965","-4.9925","-5.7385","-2.6903"
"89958.0002","-4.9925","-5.7385","-2.6827"
"90117.9962","-4.9925","-5.7385","-2.6757"
"90277.9999","-4.9925","-5.7385","-2.6696"
"90438.0035","-4.9925","-5.7385","-2.6618"
"90597.9996","-4.9925","-5.7385","-2.6546"
"90758.0032","-4.9925","-5.7385","-2.6482"
"90917.9993","-4.9925","-5.7385","-2.6411"
"91078.0029","-4.9925","-5.7385","-2.6338"
"91237.9990","-4.9925","-5.7385","-2.6263"
"91398.0026","-4.9925","-5.7385","-2.6190"
"91557.9987","-4.9925","-5.7385","-2.6125"
"91718.0023","-4.9925","-5.7385","-2.6049"
"91877.9984","-4.9925","-5.7385","-2.5974"
"92038.0020","-4.9925","-5.7385","-2.5915"
"92197.9980","-4.9925","-5.7385","-2.5840"
"92358.0017","-4.9925","-5.7385","-2.5773"
"92517.9977","-4.9925","-5.7385","-2.5712"
"92678.0014","-4.9925","-5.7385","-2.5639"
"92837.9974","-4.9925","-5.7385","-2.5577"
"92998.0011","-4.9925","-5.7385","-2.5505"
"93157.9971","-4.9925","-5.7385","-2.5439"
"93318.0008","-4.9925","-5.7385","-2.5370"
"93477.9968","-4.9925","-5.7385","-2.5298"
"93638.0005","-4.9925","-5.7385","-2.5234"
"93797.9965","-4.9925","-5.7385","-2.5164"
"93958.0002","-4.9925","-5.7385","-2.5093"
"94117.9962","-4.9925","-5.7385","-2.5021"
"94277.9999","-4.9925","-5.7385","-2.4961"
"94438.0035","-4.9925","-5.7385","-2.4893"
"94597.9996","-4.9925","-5.7385","-2.4826"
"94758.0032","-4.9925","-5.7385","-2.4758"
"94917.9993","-4.9925","-5.7385","-2.4692"
"95078.0029","-4.9925","-5.7385","-2.4624"
"95237.9990","-4.9925","-5.7385","-2.4564"
"95398.0026","-4.9925","-5.7385","-2.4502"
"95557.9987","-4.9925","-5.7385","-2.4437"
"95718.0023","-4.9925","-5.7385","-2.4374"
"95877.9984","-4.9925","-5.7385","-2.4315"
"96038.0020","-4.9925","-5.7385","-2.4256"
"96197.9980","-4.9925","-5.7385","-2.4191"
"96358.0017","-4.9925","-5.7385","-2.4127"
"96517.9977","-4.9925","-5.7385","-2.4070"
"96678.0014","-4.9925","-5.7385","-2.4007"
"96837.9974","-4.9925","-5.7385","-2.3950"
"96960.9985","-4.9830","-5.7276","-2.3761"
"97121.0022","-4.9292","-5.6658","-2.3083"
"97280.9982","-4.8761","-5.6047","-2.2482"
"97441.0019","-4.8230","-5.5437","-2.1925"
"97600.9979","-4.7696","-5.4823","-2.1373"
"97761.0016","-4.7163","-5.4210","-2.0824"
"97920.9976","-4.6630","-5.3598","-2.0284"
"98081.0013","-4.6096","-5.2984","-1.9747"
"98240.9973","-4.5563","-5.2371","-1.9216"
"98401.0010","-4.5030","-5.1759","-1.8700"
"98560.9970","-4.4497","-5.1146","-1.8188"
"98721.0007","-4.3964","-5.0533","-1.7689"
"98880.9967","-4.3430","-4.9920","-1.7198"
"99041.0004","-4.2898","-4.9308","-1.6719"
"99200.9964","-4.2363","-4.8693","-1.6250"
"99361.0001","-4.1830","-4.8080","-1.5803"
"99521.0037","-4.1296","-4.7466","-1.5355"
"99680.9998","-4.0763","-4.6854","-1.4921"
"99841.0034","-4.0229","-4.6240","-1.4497"
"100000.9995","-3.9695","-4.5627","-1.4086"
"100161.0031","-3.9163","-4.5015","-1.3673"
"100320.9991","-3.8629","-4.4401","-1.3268"
"100481.0028","-3.8096","-4.3789","-1.2867"
"100640.9988","-3.7563","-4.3176","-1.2472"
"100801.0025","-3.7030","-4.2563","-1.2093"
"100960.9985","-3.6495","-4.1948","-1.1718"
"101121.0022","-3.5964","-4.1337","-1.1347"
"101280.9982","-3.5429","-4.0723","-1.0972"
"101441.0019","-3.4895","-4.0109","-1.0592"
"101600.9979","-3.4362","-3.9496","-1.0221"
"101761.0016","-3.3829","-3.8884","-0.9858"
"101920.9976","-3.3295","-3.8270","-0.9495"
"102081.0013","-3.2762","-3.7658","-0.9135"
"102240.9973","-3.2228","-3.7044","-0.8787"
"102401.0010","-3.1697","-3.6433","-0.8434"
"102560.9970","-3.1164","-3.5820","-0.8088"
"102721.0007","-3.0629","-3.5206","-0.7736"
"102880.9967","-3.0096","-3.4594","-0.7391"
"103041.0004","-2.9564","-3.3981","-0.7045"
"103200.9964","-2.9029","-3.3367","-0.6700"
"103361.0001","-2.8495","-3.2753","-0.6357"
"103521.0037","-2.7964","-3.2142","-0.6021"
"103680.9998","-2.7428","-3.1526","-0.5683"
"103841.0034","-2.6895","-3.0914","-0.5354"
"104000.9995","-2.6363","-3.0302","-0.5031"
"104161.0031","-2.5830","-2.9689","-0.4705"
"104320.9991","-2.5295","-2.9075","-0.4382"
"104481.0028","-2.4764","-2.8465","-0.4059"
"104640.9988","-2.4230","-2.7851","-0.3748"
"104801.0025","-2.3697","-2.7238","-0.3430"
"104960.9985","-2.3164","-2.6625","-0.3105"
"105121.0022","-2.2629","-2.6011","-0.2776"
"105280.9982","-2.2096","-2.5398","-0.2458"
"105441.0019","-2.1564","-2.4787","-0.2133"
"105600.9979","-2.1028","-2.4170","-0.1805"
"105761.0016","-2.0496","-2.3558","-0.1487"
"105920.9976","-1.9965","-2.2948","-0.1165"
"106081.0013","-1.9429","-2.2332","-0.0847"
"106240.9973","-1.8897","-2.1720","-0.0531"
"106401.0010","-1.8364","-2.1108","-0.0220"
"106560.9970","-1.7830","-2.0494","0.0093"
"106721.0007","-1.7296","-1.9881","0.0403"
"106880.9967","-1.6764","-1.9270","0.0718"
"107041.0004","-1.6229","-1.8654","0.1028"
"107200.9964","-1.5696","-1.8042","0.1337"
"107361.0001","-1.5163","-1.7429","0.1646"
"107521.0037","-1.4629","-1.6815","0.1930"
"107680.9998","-1.4096","-1.6202","0.2236"
"107841.0034","-1.3563","-1.5589","0.2550"
"108000.9995","-1.3029","-1.4976","0.2856"
"108161.0031","-1.2497","-1.4365","0.3161"
"108320.9991","-1.1964","-1.3752","0.3467"
"108481.0028","-1.1429","-1.3137","0.3764"
"108640.9988","-1.0897","-1.2525","0.4066"
"108801.0025","-1.0364","-1.1913","0.4358"
"108960.9985","-0.9829","-1.1298","0.4657"
"109121.0022","-0.9295","-1.0684","0.4947"
"109280.9982","-0.8763","-1.0073","0.5232"
"109441.0019","-0.8228","-0.9457","0.5518"
"109600.9979","-0.7695","-0.8845","0.5808"
"109761.0016","-0.7163","-0.8233","0.6095"
"109920.9976","-0.6629","-0.7620","0.6381"
"110081.0013","-0.6096","-0.7007","0.6663"
"110240.9973","-0.5564","-0.6396","0.6946"
"110401.0010","-0.5029","-0.5781","0.7223"
"110560.9970","-0.4498","-0.5170","0.7486"
"110721.0007","-0.3964","-0.4556","0.7765"
"110880.9967","-0.3430","-0.3943","0.8050"
"111041.0004","-0.2897","-0.3330","0.8330"
"111200.9964","-0.2364","-0.2717","0.8613"
"111361.0001","-0.1829","-0.2102","0.8897"
"111521.0037","-0.1296","-0.1490","0.9173"
"111680.9998","-0.0763","-0.0877","0.9442"
"111841.0034","-0.0229","-0.0263","0.9680"
"111955.0018","0.0150","0.0172","0.9381"
"112114.9979","0.0198","0.0228","0.1305"
"112275.0015","0.0185","0.0213","-1.3682"
"112397.0032","0.0175","0.0202","-3.4405"
"112509.0027","0.0168","0.0194","-5.4929"
"112630.9967","0.0163","0.0187","-7.5799"
"112763.9999","0.0159","0.0182","-9.6312"
"112914.0015","0.0156","0.0179","-11.6882"
"113065.0024","0.0154","0.0177","-13.7243"
"113217.0029","0.0153","0.0176","-15.7430"
"113376.9989","0.0152","0.0175","-17.7192"
"113537.0026","0.0152","0.0175","-19.6382"
"113696.9986","0.0152","0.0174","-21.1726"
"113857.0023","0.0152","0.0174","-22.2398"
"114016.9983","0.0152","0.0174","-22.9396"
"114177.0020","0.0152","0.0174","-23.2637"
"114336.9980","0.0152","0.0174","-23.5201"
"114497.0016","0.0152","0.0174","-23.7249"
"114656.9977","0.0152","0.0174","-23.8444"
"114817.0013","0.0152","0.0174","-23.9480"
"114976.9974","0.0152","0.0174","-24.0455"
"115137.0010","0.0152","0.0174","-24.1812"
"115296.9971","0.0152","0.0174","-24.3657"
"115457.0007","0.0152","0.0174","-24.5544"
"115616.9968","0.0152","0.0174","-24.6862"
"115777.0004","0.0152","0.0174","-24.7602"
"115936.9965","0.0152","0.0175","-24.7396"
"116097.0001","0.0152","0.0175","-24.9375"
"116257.0038","0.0152","0.0175","-25.2390"
"116416.9998","0.0152","0.0175","-25.4032"
"116577.0035","0.0152","0.0175","-25.5077"
"116736.9995","0.0152","0.0175","-25.5269"
"116897.0032","0.0152","0.0175","-25.3935"
"117056.9992","0.0152","0.0175","-25.6067"
"117217.0029","0.0152","0.0175","-25.5308"
"117376.9989","0.0152","0.0175","-25.4211"
"117537.0026","0.0152","0.0175","-25.3086"
"117696.9986","0.0152","0.0175","-25.2100"
"117857.0023","0.0152","0.0175","-25.1244"
"118016.9983","0.0152","0.0175","-25.1188"
"118177.0020","0.0152","0.0175","-25.3760"
"118336.9980","0.0152","0.0175","-25.2778"
"118497.0016","0.0152","0.0175","-25.1992"
"118656.9977","0.0152","0.0175","-25.1245"
"118817.0013","0.0152","0.0175","-25.0558"
"118976.9974","0.0152","0.0175","-24.9911"
"119137.0010","0.0152","0.0175","-24.9304"
"119296.9971","0.0152","0.0175","-24.8727"
"119457.0007","0.0152","0.0175","-24.8185"
"119616.9968","0.0152","0.0175","-24.7669"
"119777.0004","0.0152","0.0175","-24.7175"
"119936.9965","0.0152","0.0175","-24.6700"
"120097.0001","0.0152","0.0175","-24.6224"
"120257.0038","0.0152","0.0175","-24.5707"
"120416.9998","0.0152","0.0175","-24.5171"
"120577.0035","0.0152","0.0175","-24.3212"
"120736.9995","0.0152","0.0175","-23.5914"
"120897.0032","0.0152","0.0175","-22.8746"
"121056.9992","0.0152","0.0175","-22.2355"
"121217.0029","0.0152","0.0175","-21.5816"
"121376.9989","0.0152","0.0175","-21.0095"
"121537.0026","0.0152","0.0175","-20.4863"
"121696.9986","0.0152","0.0175","-20.0132"
"121857.0023","0.0152","0.0175","-19.6154"
"122016.9983","0.0152","0.0175","-19.2069"
"122177.0020","0.0152","0.0175","-18.7227"
"122336.9980","0.0152","0.0175","-18.2386"
"122497.0016","0.0152","0.0175","-17.8091"
"122656.9977","0.0152","0.0175","-17.3308"
"122817.0013","0.0152","0.0175","-16.8298"
"122976.9974","0.0152","0.0175","-16.3652"
"123137.0010","0.0152","0.0175","-15.9424"
"123296.9971","0.0152","0.0175","-15.6266"
"123457.0007","0.0152","0.0175","-15.4654"
"123616.9968","0.0152","0.0175","-15.0822"
"123777.0004","0.0152","0.0175","-14.6062"
"123936.9965","0.0152","0.0175","-14.1036"
"124097.0001","0.0152","0.0175","-13.5926"
"124257.0038","0.0152","0.0175","-12.9702"
"124416.9998","0.0152","0.0175","-12.3802"
"124577.0035","0.0152","0.0175","-11.8518"
"124736.9995","0.0152","0.0175","-11.4145"
"124897.0032","0.0152","0.0175","-10.9303"
"125056.9992","0.0152","0.0175","-10.1713"
"125217.0029","0.0152","0.0175","-9.3886"
"125376.9989","0.0152","0.0175","-8.6511"
"125537.0026","0.0152","0.0175","-7.9528"
"125696.9986","0.0152","0.0175","-7.3394"
"125857.0023","0.0152","0.0175","-6.7186"
"126016.9983","0.0152","0.0175","-6.0940"
"126177.0020","0.0152","0.0175","-5.4960"
"126336.9980","0.0152","0.0175","-4.8608"
"126497.0016","0.0152","0.0175","-4.3166"
"126656.9977","0.0152","0.0175","-3.7128"
"126817.0013","0.0152","0.0175","-3.2729"
"126976.9974","0.0152","0.0175","-2.8963"
"127137.0010","0.0152","0.0175","-2.7258"
"127296.9971","0.0152","0.0175","-2.4133"
"127457.0007","0.0152","0.0175","-1.9814"
"127616.9968","0.0152","0.0175","-1.5075"
"127777.0004","0.0152","0.0175","-1.1336"
"127936.9965","0.0152","0.0175","-0.9042"
"128097.0001","0.0152","0.0175","-0.5672"
"128257.0038","0.0152","0.0175","-0.2836"
"128417.0074","0.0152","0.0175","-0.2672"
"128576.9958","0.0152","0.0175","-0.3128"
"128736.9995","0.0152","0.0175","-0.3502"
"128897.0032","0.0152","0.0175","-0.3767"
"129057.0068","0.0152","0.0175","-0.3993"
"129216.9952","0.0152","0.0175","-0.4201"
"129376.9989","0.0152","0.0175","-0.4392"
"129537.0026","0.0152","0.0175","-0.4653"
"129697.0062","0.0152","0.0175","-0.6353"
"129856.9946","0.0152","0.0175","-1.0595"
"130016.9983","0.0152","0.0175","-1.2605"
"130177.0020","0.0152","0.0175","-1.2396"
"130337.0056","0.0152","0.0175","-1.2302"
"130496.9940","0.0152","0.0175","-1.2248"
"130656.9977","0.0152","0.0175","-1.2210"
"130817.0013","0.0152","0.0175","-1.2179"
"130977.0050","0.0152","0.0175","-1.2145"
"131136.9934","0.0152","0.0175","-1.2111"
"131296.9971","0.0152","0.0175","-1.2094"
"131457.0007","0.0152","0.0175","-1.2067"
"131617.0044","0.0152","0.0175","-1.2041"
"131776.9928","0.0152","0.0175","-1.2005"
"131936.9965","0.0152","0.0175","-1.1974"
"132097.0001","0.0152","0.0175","-1.1943"
"132257.0038","0.0152","0.0175","-1.1914"
"132417.0074","0.0152","0.0175","-1.1881"
"132576.9958","0.0152","0.0175","-1.1845"
"132736.9995","0.0152","0.0175","-1.1809"
"132897.0032","0.0152","0.0175","-1.1780"
"133057.0068","0.0152","0.0175","-1.1745"
"133216.9952","0.0152","0.0175","-1.1713"
"133376.9989","0.0152","0.0175","-1.1675"
"133537.0026","0.0152","0.0175","-1.1638"
"133697.0062","0.0152","0.0175","-1.1604"
"133856.9946","0.0152","0.0175","-1.1569"
"134016.9983","0.0152","0.0175","-1.1535"
"134177.0020","0.0152","0.0175","-1.1501"
"134337.0056","0.0152","0.0175","-1.1462"
"134496.9940","0.0152","0.0175","-1.1427"
"134656.9977","0.0152","0.0175","-1.1394"
"134817.0013","0.0152","0.0175","-1.1356"
"134977.0050","0.0152","0.0175","-1.1321"
"135136.9934","0.0152","0.0175","-1.1283"
"135296.9971","0.0152","0.0175","-1.1252"
"135457.0007","0.0152","0.0175","-1.1219"
"135617.0044","0.0152","0.0175","-1.1181"
"135776.9928","0.0152","0.0175","-1.1144"
"135936.9965","0.0152","0.0175","-1.1112"
"136097.0001","0.0152","0.0175","-1.1080"
"136257.0038","0.0152","0.0175","-1.1046"
"136417.0074","0.0152","0.0175","-1.1004"
"136576.9958","0.0152","0.0175","-1.0971"
"136736.9995","0.0152","0.0175","-1.0939"
"136897.0032","0.0152","0.0175","-1.0901"
"137057.0068","0.0152","0.0175","-1.0869"
"137216.9952","0.0152","0.0175","-1.0836"
"137376.9989","0.0152","0.0175","-1.0802"
"137537.0026","0.0152","0.0175","-1.0768"
"137697.0062","0.0152","0.0175","-1.0736"
"137856.9946","0.0152","0.0175","-1.0703"
"138016.9983","0.0152","0.0175","-1.0673"
"138177.0020","0.0152","0.0175","-1.0639"
"138337.0056","0.0152","0.0175","-1.0603"
"138496.9940","0.0152","0.0175","-1.0575"
"138656.9977","0.0152","0.0175","-1.0544"
"138817.0013","0.0152","0.0175","-1.0512"
"138977.0050","0.0152","0.0175","-1.0475"
"139136.9934","0.0152","0.0175","-1.0445"
"139296.9971","0.0152","0.0175","-1.0418"
"139457.0007","0.0152","0.0175","-1.0385"
"139617.0044","0.0152","0.0175","-1.0352"
"139776.9928","0.0152","0.0175","-1.0322"
"139936.9965","0.0152","0.0175","-1.0288"
"140097.0001","0.0152","0.0175","-1.0253"
"140257.0038","0.0152","0.0175","-1.0226"
"140417.0074","0.0152","0.0175","-1.0196"
"140576.9958","0.0152","0.0175","-1.0164"
"140736.9995","0.0152","0.0175","-1.0134"
"140897.0032","0.0152","0.0175","-1.0108"
"141057.0068","0.0152","0.0175","-1.0074"
"141216.9952","0.0152","0.0175","-1.0040"
"141376.9989","0.0152","0.0175","-1.0012"
"141537.0026","0.0152","0.0175","-0.9983"
"141697.0062","0.0152","0.0175","-0.9943"
"141856.9946","0.0152","0.0175","-0.9914"
"141990.9973","0.0162","0.0186","-0.9884"
"142151.0010","0.0652","0.0749","-0.9422"
"142311.0046","0.1182","0.1359","-0.8967"
"142470.9930","0.1715","0.1971","-0.8535"
"142630.9967","0.2246","0.2582","-0.8119"
"142791.0004","0.2779","0.3194","-0.7716"
"142951.0040","0.3314","0.3809","-0.7317"
"143110.9924","0.3846","0.4421","-0.6930"
"143270.9961","0.4379","0.5033","-0.6542"
"143430.9998","0.4914","0.5649","-0.6161"
"143591.0034","0.5447","0.6261","-0.5788"
"143751.0071","0.5979","0.6873","-0.5430"
"143910.9955","0.6513","0.7486","-0.5071"
"144070.9991","0.7046","0.8099","-0.4722"
"144231.0028","0.7578","0.8710","-0.4380"
"144391.0065","0.8112","0.9324","-0.4045"
"144550.9949","0.8645","0.9937","-0.3701"
"144710.9985","0.9178","1.0549","-0.3355"
"144871.0022","0.9713","1.1165","-0.2998"
"145031.0059","1.0246","1.1777","-0.2657"
"145190.9943","1.0779","1.2390","-0.2308"
"145350.9979","1.1314","1.3004","-0.1963"
"145511.0016","1.1846","1.3616","-0.1623"
"145671.0052","1.2378","1.4228","-0.1288"
"145830.9937","1.2913","1.4842","-0.0953"
"145990.9973","1.3446","1.5455","-0.0616"
"146151.0010","1.3978","1.6067","-0.0284"
"146311.0046","1.4513","1.6681","0.0047"
"146470.9930","1.5046","1.7294","0.0379"
"146630.9967","1.5577","1.7905","0.0709"
"146791.0004","1.6113","1.8520","0.1033"
"146951.0040","1.6646","1.9133","0.1363"
"147110.9924","1.7179","1.9746","0.1684"
"147270.9961","1.7714","2.0361","0.2006"
"147430.9998","1.8247","2.0974","0.2328"
"147591.0034","1.8780","2.1586","0.2648"
"147751.0071","1.9314","2.2200","0.2969"
"147910.9955","1.9846","2.2812","0.3277"
"148070.9991","2.0379","2.3424","0.3591"
"148231.0028","2.0914","2.4039","0.3911"
"148391.0065","2.1445","2.4650","0.4222"
"148550.9949","2.1978","2.5262","0.4531"
"148710.9985","2.2513","2.5877","0.4838"
"148871.0022","2.3046","2.6490","0.5141"
"149031.0059","2.3579","2.7102","0.5450"
"149190.9943","2.4114","2.7717","0.5747"
"149350.9979","2.4646","2.8329","0.6052"
"149511.0016","2.5180","2.8943","0.6353"
"149671.0052","2.5712","2.9554","0.6652"
"149830.9937","2.6246","3.0168","0.6950"
"149990.9973","2.6778","3.0780","0.7243"
"150151.0010","2.7313","3.1394","0.7539"
"150311.0046","2.7844","3.2005","0.7829"
"150470.9930","2.8378","3.2619","0.8120"
"150630.9967","2.8912","3.3232","0.8419"
"150791.0004","2.9445","3.3844","0.8711"
"150951.0040","2.9979","3.4459","0.9004"
"151110.9924","3.0513","3.5072","0.9296"
"151270.9961","3.1046","3.5685","0.9588"
"151430.9998","3.1578","3.6297","0.9876"
"151591.0034","3.2113","3.6912","1.0166"
"151751.0071","3.2646","3.7524","1.0454"
"151910.9955","3.3178","3.8136","1.0736"
"152070.9991","3.3711","3.8748","1.1029"
"152231.0028","3.4245","3.9363","1.1311"
"152391.0065","3.4779","3.9976","1.1599"
"152550.9949","3.5313","4.0589","1.1876"
"152710.9985","3.5845","4.1202","1.2130"
"152871.0022","3.6380","4.1816","1.1276"
"153031.0059","3.6913","4.2428","0.5511"
"153190.9943","3.7447","4.3042","0.1611"
"153350.9979","3.7980","4.3655","-0.1432"
"153511.0016","3.8514","4.4269","-0.1125"
"153671.0052","3.9046","4.4880","-0.0458"
"153830.9937","3.9579","4.5493","0.0111"
"153990.9973","4.0113","4.6107","0.0601"
"154151.0010","4.0646","4.6720","0.1052"
"154311.0046","4.1179","4.7332","0.1493"
"154470.9930","4.1712","4.7945","0.1948"
"154630.9967","4.2246","4.8559","0.2394"
"154791.0004","4.2780","4.9172","0.2946"
"154951.0040","4.3312","4.9784","0.5121"
"155110.9924","4.3846","5.0398","0.9120"
"155270.9961","4.4381","5.1013","0.9733"
"155430.9998","4.4912","5.1624","1.0161"
"155591.0034","4.5447","5.2238","1.3098"
"155751.0071","4.5980","5.2850","1.6388"
"155910.9955","4.6513","5.3463","1.7185"
"156070.9991","4.7046","5.4076","1.7332"
"156231.0028","4.7580","5.4689","1.7537"
"156391.0065","4.8112","5.5302","1.7734"
"156550.9949","4.8647","5.5916","1.7863"
"156710.9985","4.9180","5.6529","1.8081"
"156871.0022","4.9713","5.7142","1.8314"
"157003.9978","5.0158","5.7653","1.8511"
"157145.0043","5.0278","5.7791","1.8486"
"157304.9927","5.0266","5.7777","1.8386"
"157464.9963","5.0253","5.7762","1.8303"
"157625.0000","5.0243","5.7750","1.8221"
"157785.0037","5.0236","5.7743","1.8156"
"157945.0073","5.0232","5.7738","1.8089"
"158104.9957","5.0230","5.7735","1.8030"
"158264.9994","5.0229","5.7734","1.7973"
"158425.0031","5.0228","5.7733","1.7920"
"158585.0067","5.0228","5.7733","1.7871"
"158744.9951","5.0227","5.7733","1.7823"
"158904.9988","5.0227","5.7732","1.7775"
"159065.0024","5.0227","5.7732","1.7730"
"159225.0061","5.0227","5.7732","1.7691"
"159384.9945","5.0227","5.7732","1.7650"
"159544.9982","5.0227","5.7732","1.7611"
"159705.0018","5.0227","5.7733","1.7575"
"159865.0055","5.0227","5.7733","1.7533"
"160024.9939","5.0227","5.7733","1.7496"
"160184.9976","5.0227","5.7733","1.7460"
"160345.0012","5.0227","5.7733","1.7423"
"160505.0049","5.0227","5.7733","1.7393"
"160664.9933","5.0227","5.7733","1.7358"
"160824.9969","5.0228","5.7733","1.7323"
"160985.0006","5.0228","5.7733","1.7290"
"161145.0043","5.0228","5.7733","1.7255"
"161304.9927","5.0228","5.7733","1.7220"
"161464.9963","5.0228","5.7733","1.7190"
"161625.0000","5.0228","5.7733","1.7156"
"161785.0037","5.0228","5.7733","1.7101"
"161945.0073","5.0228","5.7733","1.7044"
"162104.9957","5.0228","5.7733","1.6972"
"162264.9994","5.0228","5.7733","1.6108"
"162425.0031","5.0228","5.7733","1.0973"
"162516.0065","5.0228","5.7733","0.6814"