File: StepStrainSweepPressure2_combined.csv
1,Time,Displacement,Tensile strain (Displacement),Force
,(ms),(mm),(%),(N)
"","0.0000","-0.3623","-0.4164","0.0000"
"","200.0000","-0.3562","-0.4094","-0.0110"
"","400.0000","-0.3568","-0.4102","-0.0149"
"","600.0000","-0.3575","-0.4109","-0.0160"
"","800.0000","-0.3580","-0.4115","-0.0159"
"","1000.0000","-0.3583","-0.4118","-0.0166"
"","1200.0000","-0.3585","-0.4121","-0.0163"
"","1400.0000","-0.3586","-0.4122","-0.0163"
"","1600.0000","-0.3587","-0.4123","-0.0164"
"","1800.0000","-0.3587","-0.4123","-0.0167"
"","2000.0000","-0.3588","-0.4124","-0.0167"
"","2200.0000","-0.3588","-0.4124","-0.0167"
"","2400.0001","-0.3588","-0.4124","-0.0167"
"","2599.9999","-0.3588","-0.4124","-0.0169"
"","2800.0000","-0.3588","-0.4124","-0.0177"
"","3000.0000","-0.3588","-0.4124","-0.0169"
"","3200.0000","-0.3588","-0.4124","-0.0169"
"","3400.0001","-0.3588","-0.4124","-0.0184"
"","3599.9999","-0.3588","-0.4124","-0.0192"
"","3800.0000","-0.3588","-0.4124","-0.0182"
"","4000.0000","-0.3588","-0.4124","-0.0174"
"","4199.9998","-0.3588","-0.4124","-0.0252"
"","4400.0001","-0.3588","-0.4124","-0.0253"
"","4599.9999","-0.3588","-0.4124","-0.0254"
"","4800.0002","-0.3588","-0.4124","-0.0250"
"","5000.0000","-0.3588","-0.4124","-0.0128"
"","5199.9998","-0.3588","-0.4124","-0.0153"
"","5400.0001","-0.3588","-0.4124","-0.0169"
"","5599.9999","-0.3588","-0.4124","-0.0173"
"","5800.0002","-0.3588","-0.4124","-0.0175"
"","6000.0000","-0.3588","-0.4124","-0.0169"
"","6199.9998","-0.3588","-0.4124","-0.0173"
"","6400.0001","-0.3588","-0.4124","-0.0181"
"","6599.9999","-0.3588","-0.4124","-0.0178"
"","6800.0002","-0.3588","-0.4124","-0.0179"
"","7000.0000","-0.3588","-0.4124","-0.0179"
"","7199.9998","-0.3588","-0.4124","-0.0190"
"","7400.0001","-0.3588","-0.4124","-0.0254"
"","7599.9999","-0.3588","-0.4124","-0.0265"
"","7800.0002","-0.3588","-0.4124","-0.0344"
"","8000.0000","-0.3588","-0.4124","-0.0350"
"","8199.9998","-0.3588","-0.4124","-0.0352"
"","8399.9996","-0.3588","-0.4124","-0.0345"
"","8600.0004","-0.3588","-0.4124","-0.0335"
"","8800.0002","-0.3588","-0.4124","-0.0328"
"","9000.0000","-0.3588","-0.4124","-0.0327"
"","9199.9998","-0.3588","-0.4124","-0.0330"
"","9399.9996","-0.3588","-0.4124","-0.0326"
"","9600.0004","-0.3588","-0.4124","-0.0308"
"","9800.0002","-0.3588","-0.4124","-0.0301"
"","9998.9996","-0.3588","-0.4124","-0.0293"
"","10178.9999","-0.4602","-0.5290","-0.1076"
"","10378.9997","-0.6259","-0.7195","-0.2172"
"","10579.0005","-0.7925","-0.9109","-0.3237"
"","10779.0003","-0.9595","-1.1029","-0.4277"
"","10979.0001","-1.1258","-1.2941","-0.5303"
"","11178.9999","-1.2923","-1.4854","-0.6313"
"","11378.9997","-1.4590","-1.6770","-0.7329"
"","11579.0005","-1.6258","-1.8687","-0.8328"
"","11779.0003","-1.7924","-2.0602","-0.9345"
"","11979.0001","-1.9589","-2.2517","-1.0368"
"","12178.9999","-2.1257","-2.4433","-1.1416"
"","12378.9997","-2.2925","-2.6351","-1.2483"
"","12579.0005","-2.4591","-2.8266","-1.3564"
"","12779.0003","-2.6258","-3.0181","-1.4660"
"","12979.0001","-2.7925","-3.2098","-1.5780"
"","13178.9999","-2.9593","-3.4015","-1.6946"
"","13378.9997","-3.1258","-3.5929","-1.8147"
"","13579.0005","-3.2924","-3.7844","-1.9409"
"","13779.0003","-3.4592","-3.9761","-2.0725"
"","13979.0001","-3.6259","-4.1678","-2.2066"
"","14178.9999","-3.7925","-4.3592","-2.3433"
"","14378.9997","-3.9591","-4.5506","-2.4809"
"","14579.0005","-4.1258","-4.7423","-2.6192"
"","14779.0003","-4.2925","-4.9339","-2.7608"
"","14979.0001","-4.4589","-5.1252","-2.9017"
"","15178.9999","-4.6257","-5.3169","-3.0437"
"","15378.9997","-4.7925","-5.5086","-3.1855"
"","15579.0005","-4.9590","-5.7000","-3.3275"
"","15779.0003","-5.1257","-5.8916","-3.4698"
"","15979.0001","-5.2924","-6.0832","-3.6154"
"","16179.0009","-5.4593","-6.2750","-3.7610"
"","16378.9997","-5.6258","-6.4664","-3.9071"
"","16579.0005","-5.7924","-6.6579","-4.0534"
"","16778.9993","-5.9591","-6.8495","-4.2011"
"","16979.0001","-6.1259","-7.0413","-4.3489"
"","17179.0009","-6.2924","-7.2327","-4.4977"
"","17378.9997","-6.4590","-7.4241","-4.6470"
"","17579.0005","-6.6258","-7.6158","-4.7973"
"","17778.9993","-6.7925","-7.8075","-4.9484"
"","17979.0001","-6.9589","-7.9988","-5.0998"
"","18179.0009","-7.1255","-8.1903","-5.2525"
"","18378.9997","-7.2925","-8.3821","-5.4072"
"","18579.0005","-7.4592","-8.5738","-5.5631"
"","18778.9993","-7.6257","-8.7651","-5.7187"
"","18979.0001","-7.7923","-8.9567","-5.8766"
"","19179.0009","-7.9592","-9.1485","-6.0364"
"","19378.9997","-8.1259","-9.3402","-6.1973"
"","19579.0005","-8.2925","-9.5316","-6.3582"
"","19778.9993","-8.4591","-9.7231","-6.5218"
"","19979.0001","-8.6260","-9.9150","-6.6875"
"","20179.0009","-8.7926","-10.1065","-6.8536"
"","20378.9997","-8.9592","-10.2979","-7.0216"
"","20579.0005","-9.1258","-10.4895","-7.1924"
"","20778.9993","-9.2926","-10.6811","-7.3651"
"","20979.0001","-9.4592","-10.8726","-7.5404"
"","21179.0009","-9.6257","-11.0640","-7.7194"
"","21378.9997","-9.7923","-11.2556","-7.9032"
"","21579.0005","-9.9590","-11.4472","-8.0911"
"","21731.0009","-10.0119","-11.5079","-8.0920"
"","21930.9998","-10.0058","-11.5009","-8.0184"
"","22131.0005","-10.0023","-11.4968","-7.9588"
"","22330.9994","-10.0008","-11.4952","-7.9065"
"","22531.0001","-10.0003","-11.4945","-7.8592"
"","22731.0009","-10.0000","-11.4943","-7.8157"
"","22930.9998","-10.0000","-11.4942","-7.7738"
"","23131.0005","-9.9999","-11.4942","-7.7346"
"","23330.9994","-9.9999","-11.4942","-7.6979"
"","23531.0001","-9.9999","-11.4942","-7.6620"
"","23731.0009","-9.9999","-11.4942","-7.6278"
"","23930.9998","-9.9999","-11.4942","-7.5947"
"","24131.0005","-10.0000","-11.4942","-7.5651"
"","24330.9994","-10.0000","-11.4942","-7.5355"
"","24531.0001","-10.0000","-11.4942","-7.5116"
"","24731.0009","-10.0000","-11.4942","-7.5065"
"","24930.9998","-10.0000","-11.4942","-7.6668"
"","25131.0005","-10.0000","-11.4942","-8.8083"
"","25330.9994","-10.0000","-11.4942","-10.3231"
"","25531.0001","-10.0000","-11.4942","-11.6686"
"","25731.0009","-10.0000","-11.4942","-12.7284"
"","25930.9998","-10.0000","-11.4942","-13.8664"
"","26131.0005","-10.0000","-11.4942","-15.1588"
"","26330.9994","-10.0000","-11.4942","-16.5653"
"","26531.0001","-10.0000","-11.4942","-17.9101"
"","26731.0009","-10.0000","-11.4942","-19.0841"
"","26930.9998","-10.0000","-11.4942","-20.1628"
"","27131.0005","-10.0000","-11.4942","-21.1568"
"","27330.9994","-10.0000","-11.4942","-22.2585"
"","27531.0001","-10.0000","-11.4942","-23.2918"
"","27731.0009","-10.0000","-11.4942","-24.0970"
"","27930.9998","-10.0000","-11.4942","-24.8129"
"","28131.0005","-10.0000","-11.4942","-25.5315"
"","28330.9994","-10.0000","-11.4942","-26.4875"
"","28531.0001","-10.0000","-11.4942","-27.6837"
"","28731.0009","-10.0000","-11.4942","-28.8436"
"","28930.9998","-10.0000","-11.4942","-29.8493"
"","29131.0005","-10.0000","-11.4942","-30.8729"
"","29330.9994","-10.0000","-11.4942","-31.8988"
"","29441.0000","-10.0000","-11.4942","-29.8761"
"","29500.9995","-10.0000","-11.4942","-27.1580"
"","29687.9997","-10.0000","-11.4942","-25.8478"
"","29888.0005","-10.0000","-11.4942","-26.0021"
"","30087.9993","-10.0000","-11.4942","-26.2392"
"","30288.0001","-10.0000","-11.4942","-26.5515"
"","30488.0009","-10.0000","-11.4942","-26.7875"
"","30687.9997","-10.0000","-11.4942","-27.0793"
"","30888.0005","-10.0000","-11.4942","-27.4020"
"","31087.9993","-10.0000","-11.4942","-27.6402"
"","31288.0001","-10.0000","-11.4942","-27.7708"
"","31488.0009","-10.0000","-11.4942","-27.9373"
"","31687.9997","-10.0000","-11.4942","-28.2791"
"","31888.0005","-10.0000","-11.4942","-28.5124"
"","32088.0013","-10.0000","-11.4942","-28.6829"
"","32287.9982","-10.0000","-11.4942","-28.8165"
"","32487.9990","-10.0000","-11.4942","-28.9166"
"","32687.9997","-10.0000","-11.4942","-29.0506"
"","32888.0005","-10.0000","-11.4942","-29.2814"
"","33088.0013","-10.0000","-11.4942","-29.5125"
"","33287.9982","-10.0000","-11.4942","-29.7732"
"","33487.9990","-10.0000","-11.4942","-29.9944"
"","33687.9997","-10.0000","-11.4942","-30.1213"
"","33888.0005","-10.0000","-11.4942","-30.2295"
"","34088.0013","-10.0000","-11.4942","-30.4090"
"","34287.9982","-10.0000","-11.4942","-30.7071"
"","34487.9990","-10.0000","-11.4942","-30.9838"
"","34687.9997","-10.0000","-11.4942","-31.2148"
"","34888.0005","-10.0000","-11.4942","-31.7655"
"","35088.0013","-10.0000","-11.4942","-32.4460"
"","35287.9982","-10.0000","-11.4942","-32.9337"
"","35487.9990","-10.0000","-11.4942","-33.3079"
"","35687.9997","-10.0000","-11.4942","-33.8543"
"","35888.0005","-10.0000","-11.4942","-34.3636"
"","36088.0013","-10.0000","-11.4942","-34.5779"
"","36287.9982","-10.0000","-11.4942","-34.9097"
"","36487.9990","-10.0000","-11.4942","-35.1706"
"","36687.9997","-10.0000","-11.4942","-35.5402"
"","36888.0005","-10.0000","-11.4942","-35.8831"
"","37088.0013","-10.0000","-11.4942","-36.1878"
"","37273.9983","-10.0000","-11.4942","-35.3755"
"","37473.9990","-10.0000","-11.4942","-35.6651"
"","37673.9998","-10.0000","-11.4942","-35.6693"
"","37874.0005","-10.0000","-11.4942","-35.6717"
"","38074.0013","-10.0000","-11.4942","-35.5582"
"","38273.9983","-10.0000","-11.4942","-35.4336"
"","38473.9990","-10.0000","-11.4942","-35.3160"
"","38673.9998","-10.0000","-11.4942","-35.1994"
"","38874.0005","-10.0000","-11.4942","-34.7041"
"","39074.0013","-10.0000","-11.4943","-33.0419"
"","39273.9983","-10.0000","-11.4943","-31.0896"
"","39473.9990","-10.0000","-11.4943","-29.7539"
"","39673.9998","-10.0000","-11.4943","-28.8933"
"","39874.0005","-10.0000","-11.4943","-28.0320"
"","40074.0013","-10.0000","-11.4943","-27.4955"
"","40273.9983","-10.0000","-11.4943","-27.2428"
"","40473.9990","-10.0000","-11.4943","-26.5449"
"","40673.9998","-10.0000","-11.4943","-25.5450"
"","40874.0005","-10.0000","-11.4943","-24.6163"
"","41074.0013","-10.0000","-11.4943","-23.8025"
"","41273.9983","-10.0000","-11.4943","-23.1063"
"","41473.9990","-10.0000","-11.4943","-22.4850"
"","41673.9998","-10.0000","-11.4943","-21.9022"
"","41874.0005","-10.0000","-11.4943","-21.4299"
"","42074.0013","-10.0000","-11.4943","-20.9182"
"","42273.9983","-10.0000","-11.4943","-20.3561"
"","42473.9990","-10.0000","-11.4943","-19.8457"
"","42673.9998","-10.0000","-11.4943","-19.4101"
"","42874.0005","-10.0000","-11.4943","-18.9369"
"","43074.0013","-10.0000","-11.4943","-18.4392"
"","43273.9983","-10.0000","-11.4942","-17.8847"
"","43473.9990","-10.0000","-11.4943","-17.3180"
"","43673.9998","-10.0000","-11.4943","-16.7854"
"","43874.0005","-10.0000","-11.4943","-16.2744"
"","44074.0013","-10.0000","-11.4943","-15.8006"
"","44273.9983","-10.0000","-11.4943","-15.3197"
"","44473.9990","-10.0000","-11.4943","-14.9700"
"","44673.9998","-10.0000","-11.4943","-14.6227"
"","44874.0005","-10.0000","-11.4943","-14.3865"
"","45074.0013","-10.0000","-11.4943","-14.1526"
"","45273.9983","-10.0000","-11.4943","-13.9937"
"","45473.9990","-10.0000","-11.4943","-13.7348"
"","45673.9998","-10.0000","-11.4943","-13.6674"
"","45874.0005","-10.0000","-11.4943","-13.5373"
"","46074.0013","-10.0000","-11.4943","-13.2375"
"","46273.9983","-10.0000","-11.4943","-12.6413"
"","46473.9990","-10.0000","-11.4943","-12.0933"
"","46673.9998","-10.0000","-11.4943","-11.4553"
"","46874.0005","-10.0000","-11.4943","-10.7155"
"","47074.0013","-10.0000","-11.4943","-9.9769"
"","47273.9983","-10.0000","-11.4943","-9.0842"
"","47473.9990","-10.0000","-11.4943","-8.2552"
"","47673.9998","-10.0000","-11.4943","-7.5812"
"","47874.0005","-10.0000","-11.4943","-7.0138"
"","48074.0013","-10.0000","-11.4943","-6.4463"
"","48273.9983","-10.0000","-11.4943","-6.4738"
"","48473.9990","-10.0000","-11.4943","-6.5417"
"","48673.9998","-10.0000","-11.4943","-6.5882"
"","48874.0005","-10.0000","-11.4943","-6.6188"
"","49074.0013","-10.0000","-11.4943","-6.6393"
"","49273.9983","-10.0000","-11.4943","-6.6492"
"","49473.9990","-10.0000","-11.4943","-6.6504"
"","49673.9998","-10.0000","-11.4943","-6.6447"
"","49874.0005","-10.0000","-11.4943","-6.6247"
"","50074.0013","-10.0000","-11.4943","-5.6896"
"","50273.9983","-10.0000","-11.4943","-4.5879"
"","50473.9990","-10.0000","-11.4943","-4.0505"
"","50673.9998","-10.0000","-11.4943","-3.5122"
"","50874.0005","-10.0000","-11.4943","-2.9980"
"","51074.0013","-10.0000","-11.4943","-2.8520"
"","51273.9983","-10.0000","-11.4943","-2.9250"
"","51473.9990","-10.0000","-11.4943","-2.9831"
"","51651.0010","-10.0000","-11.4943","-3.0182"
"","51833.0002","-9.9527","-11.4399","-2.9681"
"","52033.0009","-9.8869","-11.3642","-2.9029"
"","52233.0017","-9.8204","-11.2878","-2.8347"
"","52432.9987","-9.7539","-11.2114","-2.7668"
"","52632.9994","-9.6872","-11.1347","-2.7003"
"","52833.0002","-9.6208","-11.0583","-2.6362"
"","53033.0009","-9.5540","-10.9816","-2.5713"
"","53233.0017","-9.4875","-10.9051","-2.5132"
"","53432.9987","-9.4208","-10.8285","-2.4562"
"","53632.9994","-9.3541","-10.7518","-2.3997"
"","53833.0002","-9.2874","-10.6751","-2.3428"
"","54033.0009","-9.2205","-10.5983","-2.2831"
"","54233.0017","-9.1538","-10.5216","-2.2232"
"","54432.9987","-9.0873","-10.4451","-2.1624"
"","54632.9994","-9.0206","-10.3685","-2.1024"
"","54833.0002","-8.9541","-10.2920","-2.0397"
"","55033.0009","-8.8872","-10.2152","-1.9777"
"","55233.0017","-8.8208","-10.1388","-1.9150"
"","55432.9987","-8.7541","-10.0621","-1.8545"
"","55632.9994","-8.6873","-9.9854","-1.7937"
"","55833.0002","-8.6208","-9.9089","-1.7346"
"","56033.0009","-8.5538","-9.8320","-1.6747"
"","56233.0017","-8.4873","-9.7555","-1.6161"
"","56432.9987","-8.4204","-9.6787","-1.5582"
"","56632.9994","-8.3540","-9.6023","-1.4993"
"","56833.0002","-8.2873","-9.5257","-1.4401"
"","57033.0009","-8.2207","-9.4491","-1.3827"
"","57233.0017","-8.1540","-9.3725","-1.3266"
"","57432.9987","-8.0874","-9.2958","-1.2708"
"","57632.9994","-8.0206","-9.2191","-1.2160"
"","57833.0002","-7.9540","-9.1425","-1.1623"
"","58033.0009","-7.8873","-9.0658","-1.1098"
"","58233.0017","-7.8207","-8.9894","-1.0576"
"","58432.9987","-7.7539","-8.9125","-1.0055"
"","58632.9994","-7.6873","-8.8360","-0.9541"
"","58833.0002","-7.6207","-8.7594","-0.9047"
"","59033.0009","-7.5540","-8.6828","-0.8551"
"","59233.0017","-7.4874","-8.6062","-0.8071"
"","59432.9987","-7.4206","-8.5294","-0.7589"
"","59632.9994","-7.3540","-8.4529","-0.7123"
"","59833.0002","-7.2873","-8.3762","-0.6658"
"","60033.0009","-7.2206","-8.2996","-0.6201"
"","60233.0017","-7.1539","-8.2229","-0.5740"
"","60432.9987","-7.0874","-8.1464","-0.5284"
"","60632.9994","-7.0207","-8.0698","-0.4837"
"","60833.0002","-6.9540","-7.9931","-0.4404"
"","61033.0009","-6.8872","-7.9164","-0.3971"
"","61233.0017","-6.8208","-7.8400","-0.3555"
"","61432.9987","-6.7539","-7.7632","-0.3150"
"","61632.9994","-6.6874","-7.6867","-0.2742"
"","61833.0002","-6.6205","-7.6098","-0.2328"
"","62033.0009","-6.5540","-7.5333","-0.1917"
"","62233.0017","-6.4873","-7.4567","-0.1507"
"","62432.9987","-6.4206","-7.3801","-0.1100"
"","62632.9994","-6.3540","-7.3035","-0.0699"
"","62833.0002","-6.2873","-7.2267","-0.0299"
"","63033.0009","-6.2207","-7.1503","0.0097"
"","63233.0017","-6.1539","-7.0734","0.0495"
"","63432.9987","-6.0873","-6.9969","0.0885"
"","63632.9994","-6.0206","-6.9202","0.1272"
"","63833.0002","-5.9540","-6.8437","0.1655"
"","64032.9971","-5.8873","-6.7671","0.2037"
"","64233.0017","-5.8207","-6.6904","0.2414"
"","64432.9987","-5.7540","-6.6137","0.2781"
"","64633.0032","-5.6874","-6.5372","0.3156"
"","64833.0002","-5.6207","-6.4605","0.3528"
"","65032.9971","-5.5541","-6.3841","0.3893"
"","65233.0017","-5.4872","-6.3072","0.4258"
"","65432.9987","-5.4206","-6.2306","0.4612"
"","65633.0032","-5.3538","-6.1538","0.4963"
"","65833.0002","-5.2873","-6.0773","0.5317"
"","66032.9971","-5.2207","-6.0008","0.5669"
"","66233.0017","-5.1540","-5.9241","0.6027"
"","66432.9987","-5.0874","-5.8475","0.6372"
"","66633.0032","-5.0206","-5.7708","0.6713"
"","66777.0004","-4.9869","-5.7321","0.6821"
"","66976.9974","-4.9887","-5.7342","0.6681"
"","67177.0020","-4.9903","-5.7360","0.6581"
"","67376.9989","-4.9913","-5.7372","0.6491"
"","67577.0035","-4.9919","-5.7379","0.6411"
"","67777.0004","-4.9922","-5.7382","0.6339"
"","67976.9974","-4.9924","-5.7384","0.6271"
"","68177.0020","-4.9925","-5.7385","0.6203"
"","68376.9989","-4.9925","-5.7385","0.6077"
"","68577.0035","-4.9925","-5.7385","0.5835"
"","68777.0004","-4.9925","-5.7385","0.2534"
"","68976.9974","-4.9925","-5.7385","-0.2483"
"","69177.0020","-4.9925","-5.7385","-0.5945"
"","69376.9989","-4.9925","-5.7385","-0.7124"
"","69577.0035","-4.9925","-5.7385","-0.7146"
"","69777.0004","-4.9925","-5.7385","-0.7082"
"","69976.9974","-4.9925","-5.7385","-0.6978"
"","70177.0020","-4.9925","-5.7385","-0.6920"
"","70376.9989","-4.9925","-5.7385","-0.6872"
"","70577.0035","-4.9925","-5.7385","-0.6940"
"","70777.0004","-4.9925","-5.7385","-0.9463"
"","70976.9974","-4.9925","-5.7385","-1.2036"
"","71177.0020","-4.9925","-5.7385","-1.1716"
"","71376.9989","-4.9925","-5.7385","-1.1509"
"","71577.0035","-4.9925","-5.7385","-1.1365"
"","71777.0004","-4.9925","-5.7385","-1.1254"
"","71976.9974","-4.9925","-5.7385","-1.1158"
"","72177.0020","-4.9925","-5.7385","-1.1075"
"","72376.9989","-4.9925","-5.7385","-1.1009"
"","72577.0035","-4.9925","-5.7385","-1.0944"
"","72777.0004","-4.9925","-5.7385","-1.0891"
"","72976.9974","-4.9925","-5.7385","-1.0842"
"","73177.0020","-4.9925","-5.7385","-1.0793"
"","73376.9989","-4.9925","-5.7385","-1.1066"
"","73577.0035","-4.9925","-5.7385","-2.6894"
"","73762.0010","-4.9925","-5.7385","-5.1934"
"","73933.9981","-4.9925","-5.7385","-7.7635"
"","74134.0027","-4.9925","-5.7385","-10.1162"
"","74333.9996","-4.9925","-5.7385","-11.9292"
"","74533.9966","-4.9925","-5.7385","-13.6789"
"","74734.0012","-4.9925","-5.7385","-15.4631"
"","74933.9981","-4.9925","-5.7385","-16.9986"
"","75134.0027","-4.9925","-5.7385","-18.5186"
"","75333.9996","-4.9925","-5.7385","-19.8847"
"","75533.9966","-4.9925","-5.7385","-20.9796"
"","75734.0012","-4.9925","-5.7385","-22.0445"
"","75933.9981","-4.9925","-5.7385","-22.9287"
"","76134.0027","-4.9925","-5.7385","-23.3329"
"","76333.9996","-4.9925","-5.7385","-23.6969"
"","76533.9966","-4.9925","-5.7385","-24.3140"
"","76734.0012","-4.9925","-5.7385","-25.1339"
"","76933.9981","-4.9925","-5.7385","-26.0110"
"","77134.0027","-4.9925","-5.7385","-26.7095"
"","77333.9996","-4.9925","-5.7385","-27.0858"
"","77533.9966","-4.9925","-5.7385","-27.5362"
"","77734.0012","-4.9925","-5.7385","-28.0495"
"","77933.9981","-4.9925","-5.7385","-28.2711"
"","78134.0027","-4.9925","-5.7385","-28.4117"
"","78333.9996","-4.9925","-5.7385","-28.5879"
"","78533.9966","-4.9925","-5.7385","-28.7467"
"","78734.0012","-4.9925","-5.7385","-28.8647"
"","78933.9981","-4.9925","-5.7385","-28.7496"
"","79134.0027","-4.9925","-5.7385","-28.9684"
"","79333.9996","-4.9925","-5.7385","-29.7983"
"","79533.9966","-4.9925","-5.7385","-30.1692"
"","79734.0012","-4.9925","-5.7385","-30.1426"
"","79933.9981","-4.9925","-5.7385","-29.7708"
"","80134.0027","-4.9925","-5.7385","-29.6410"
"","80333.9996","-4.9925","-5.7385","-30.0745"
"","80533.9966","-4.9925","-5.7385","-30.2220"
"","80734.0012","-4.9925","-5.7385","-29.9633"
"","80933.9981","-4.9925","-5.7385","-29.6954"
"","81134.0027","-4.9925","-5.7385","-29.4789"
"","81333.9996","-4.9925","-5.7385","-29.2798"
"","81533.9966","-4.9925","-5.7385","-28.9906"
"","81734.0012","-4.9925","-5.7385","-28.3191"
"","81933.9981","-4.9925","-5.7385","-27.5309"
"","82134.0027","-4.9925","-5.7385","-26.8822"
"","82333.9996","-4.9925","-5.7385","-26.2150"
"","82533.9966","-4.9925","-5.7385","-25.5820"
"","82734.0012","-4.9925","-5.7385","-25.3165"
"","82933.9981","-4.9925","-5.7385","-25.1157"
"","83134.0027","-4.9925","-5.7385","-24.5374"
"","83333.9996","-4.9925","-5.7385","-23.9102"
"","83533.9966","-4.9925","-5.7385","-23.5567"
"","83734.0012","-4.9925","-5.7385","-23.2496"
"","83933.9981","-4.9925","-5.7385","-23.0158"
"","84134.0027","-4.9925","-5.7385","-22.7720"
"","84333.9996","-4.9925","-5.7385","-22.5477"
"","84533.9966","-4.9925","-5.7385","-22.5462"
"","84734.0012","-4.9925","-5.7385","-22.3954"
"","84933.9981","-4.9925","-5.7385","-21.7993"
"","85134.0027","-4.9925","-5.7385","-21.5746"
"","85333.9996","-4.9925","-5.7385","-21.6018"
"","85533.9966","-4.9925","-5.7385","-21.6152"
"","85734.0012","-4.9925","-5.7385","-21.2163"
"","85933.9981","-4.9925","-5.7385","-20.8018"
"","86134.0027","-4.9925","-5.7385","-20.8094"
"","86333.9996","-4.9925","-5.7385","-20.6351"
"","86533.9966","-4.9925","-5.7385","-20.2087"
"","86734.0012","-4.9925","-5.7385","-19.9731"
"","86933.9981","-4.9925","-5.7385","-19.7677"
"","87134.0027","-4.9925","-5.7385","-19.4406"
"","87333.9996","-4.9925","-5.7385","-19.3836"
"","87533.9966","-4.9925","-5.7385","-19.3955"
"","87734.0012","-4.9925","-5.7385","-18.9278"
"","87933.9981","-4.9925","-5.7385","-18.4731"
"","88134.0027","-4.9925","-5.7385","-18.1455"
"","88333.9996","-4.9925","-5.7385","-17.8020"
"","88533.9966","-4.9925","-5.7385","-17.4631"
"","88734.0012","-4.9925","-5.7385","-17.1062"
"","88933.9981","-4.9925","-5.7385","-16.7262"
"","89134.0027","-4.9925","-5.7385","-16.1639"
"","89333.9996","-4.9925","-5.7385","-15.6510"
"","89533.9966","-4.9925","-5.7385","-15.1128"
"","89734.0012","-4.9925","-5.7385","-14.3438"
"","89933.9981","-4.9925","-5.7385","-13.5606"
"","90134.0027","-4.9925","-5.7385","-12.8528"
"","90333.9996","-4.9925","-5.7385","-12.2957"
"","90533.9966","-4.9925","-5.7385","-12.1280"
"","90734.0012","-4.9925","-5.7385","-11.2194"
"","90933.9981","-4.9925","-5.7385","-9.9405"
"","91134.0027","-4.9925","-5.7385","-9.1113"
"","91333.9996","-4.9925","-5.7385","-8.6072"
"","91533.9966","-4.9925","-5.7385","-7.9534"
"","91734.0012","-4.9925","-5.7385","-6.8045"
"","91933.9981","-4.9925","-5.7385","-5.6384"
"","92134.0027","-4.9925","-5.7385","-4.8655"
"","92333.9996","-4.9925","-5.7385","-4.1604"
"","92533.9966","-4.9925","-5.7385","-3.3523"
"","92734.0012","-4.9925","-5.7385","-2.5165"
"","92933.9981","-4.9925","-5.7385","-1.9488"
"","93134.0027","-4.9925","-5.7385","-1.5451"
"","93333.9996","-4.9925","-5.7385","-1.2214"
"","93533.9966","-4.9925","-5.7385","-1.1573"
"","93734.0012","-4.9925","-5.7385","-1.2276"
"","93933.9981","-4.9925","-5.7385","-1.2781"
"","94134.0027","-4.9925","-5.7385","-1.3174"
"","94333.9996","-4.9925","-5.7385","-1.3487"
"","94533.9966","-4.9925","-5.7385","-1.3750"
"","94734.0012","-4.9925","-5.7385","-1.3952"
"","94933.9981","-4.9925","-5.7385","-1.4129"
"","95134.0027","-4.9925","-5.7385","-1.4271"
"","95333.9996","-4.9925","-5.7385","-1.4388"
"","95533.9966","-4.9925","-5.7385","-1.4489"
"","95734.0012","-4.9925","-5.7385","-1.4564"
"","95933.9981","-4.9925","-5.7385","-1.4627"
"","96134.0027","-4.9925","-5.7385","-1.4681"
"","96333.9996","-4.9925","-5.7385","-1.4721"
"","96533.9966","-4.9925","-5.7385","-1.4748"
"","96696.9986","-4.9925","-5.7385","-1.4766"
"","96886.0016","-4.9558","-5.6964","-1.4391"
"","97085.9985","-4.8894","-5.6199","-1.3788"
"","97286.0031","-4.8230","-5.5436","-1.3210"
"","97486.0001","-4.7563","-5.4670","-1.2659"
"","97685.9970","-4.6895","-5.3902","-1.2125"
"","97886.0016","-4.6228","-5.3135","-1.1614"
"","98085.9985","-4.5563","-5.2371","-1.1115"
"","98286.0031","-4.4896","-5.1605","-1.0618"
"","98486.0001","-4.4231","-5.0841","-1.0139"
"","98685.9970","-4.3562","-5.0072","-0.9666"
"","98886.0016","-4.2899","-4.9309","-0.9208"
"","99085.9985","-4.2230","-4.8540","-0.8750"
"","99286.0031","-4.1563","-4.7773","-0.8307"
"","99486.0001","-4.0896","-4.7007","-0.7851"
"","99685.9970","-4.0229","-4.6240","-0.7404"
"","99886.0016","-3.9563","-4.5475","-0.6965"
"","100085.9985","-3.8895","-4.4707","-0.6525"
"","100286.0031","-3.8229","-4.3942","-0.6099"
"","100486.0001","-3.7563","-4.3176","-0.5678"
"","100685.9970","-3.6897","-4.2411","-0.5268"
"","100886.0016","-3.6231","-4.1645","-0.4858"
"","101085.9985","-3.5563","-4.0877","-0.4439"
"","101286.0031","-3.4895","-4.0109","-0.4037"
"","101486.0001","-3.4229","-3.9344","-0.3627"
"","101685.9970","-3.3562","-3.8577","-0.3229"
"","101886.0016","-3.2897","-3.7812","-0.2820"
"","102085.9985","-3.2228","-3.7044","-0.2412"
"","102286.0031","-3.1564","-3.6281","-0.2003"
"","102486.0001","-3.0897","-3.5513","-0.1587"
"","102685.9970","-3.0230","-3.4748","-0.1184"
"","102886.0016","-2.9564","-3.3981","-0.0777"
"","103085.9985","-2.8897","-3.3215","-0.0383"
"","103286.0031","-2.8230","-3.2448","0.0013"
"","103486.0001","-2.7562","-3.1681","0.0411"
"","103685.9970","-2.6895","-3.0914","0.0807"
"","103886.0016","-2.6229","-3.0149","0.1197"
"","104085.9985","-2.5563","-2.9383","0.1582"
"","104286.0031","-2.4897","-2.8617","0.1971"
"","104486.0001","-2.4230","-2.7851","0.2352"
"","104685.9970","-2.3563","-2.7083","0.2738"
"","104886.0016","-2.2896","-2.6317","0.3118"
"","105085.9985","-2.2230","-2.5551","0.3493"
"","105286.0031","-2.1564","-2.4786","0.3866"
"","105486.0001","-2.0895","-2.4017","0.4239"
"","105685.9970","-2.0230","-2.3253","0.4611"
"","105886.0016","-1.9563","-2.2486","0.4974"
"","106085.9985","-1.8896","-2.1720","0.5329"
"","106286.0031","-1.8230","-2.0954","0.5700"
"","106486.0001","-1.7564","-2.0188","0.6050"
"","106685.9970","-1.6897","-1.9422","0.6410"
"","106886.0016","-1.6229","-1.8654","0.6764"
"","107085.9985","-1.5562","-1.7888","0.7101"
"","107286.0031","-1.4896","-1.7122","0.7457"
"","107486.0001","-1.4229","-1.6356","0.7812"
"","107685.9970","-1.3563","-1.5590","0.8168"
"","107886.0016","-1.2896","-1.4823","0.8521"
"","108085.9985","-1.2230","-1.4057","0.8871"
"","108286.0031","-1.1564","-1.3292","0.9221"
"","108486.0001","-1.0897","-1.2525","0.9569"
"","108685.9970","-1.0231","-1.1760","0.9907"
"","108886.0016","-0.9562","-1.0990","1.0258"
"","109085.9985","-0.8897","-1.0227","1.0601"
"","109286.0031","-0.8228","-0.9458","1.0942"
"","109486.0001","-0.7562","-0.8693","1.1281"
"","109685.9970","-0.6896","-0.7926","1.1613"
"","109886.0016","-0.6230","-0.7160","1.1953"
"","110085.9985","-0.5564","-0.6396","1.2281"
"","110286.0031","-0.4896","-0.5628","1.2612"
"","110486.0001","-0.4230","-0.4862","1.2937"
"","110685.9970","-0.3564","-0.4096","1.3261"
"","110886.0016","-0.2897","-0.3330","1.3581"
"","111085.9985","-0.2230","-0.2563","1.3890"
"","111286.0031","-0.1562","-0.1796","1.4209"
"","111486.0001","-0.0895","-0.1029","1.4527"
"","111685.9970","-0.0229","-0.0263","1.4871"
"","111839.9963","0.0208","0.0240","1.5064"
"","112040.0009","0.0191","0.0220","1.4962"
"","112239.9979","0.0176","0.0202","1.4879"
"","112440.0024","0.0164","0.0189","1.4808"
"","112639.9994","0.0158","0.0182","1.4730"
"","112839.9963","0.0155","0.0178","1.4668"
"","113040.0009","0.0153","0.0176","1.4676"
"","113239.9979","0.0152","0.0175","1.6541"
"","113440.0024","0.0152","0.0175","2.2005"
"","113639.9994","0.0152","0.0174","2.4124"
"","113839.9963","0.0152","0.0174","2.7437"
"","114040.0009","0.0152","0.0174","2.7824"
"","114239.9979","0.0152","0.0174","2.7477"
"","114440.0024","0.0152","0.0174","2.7235"
"","114639.9994","0.0152","0.0174","2.7011"
"","114839.9963","0.0152","0.0174","2.6553"
"","115040.0009","0.0152","0.0174","2.2706"
"","115239.9979","0.0152","0.0175","1.4648"
"","115440.0024","0.0152","0.0175","0.7472"
"","115639.9994","0.0152","0.0175","0.4148"
"","115839.9963","0.0152","0.0175","-0.1483"
"","116040.0009","0.0152","0.0175","-0.5009"
"","116239.9979","0.0152","0.0175","-0.4606"
"","116440.0024","0.0152","0.0175","-0.4274"
"","116639.9994","0.0152","0.0175","-0.4032"
"","116839.9963","0.0152","0.0175","-0.3838"
"","117040.0009","0.0152","0.0175","-0.3689"
"","117239.9979","0.0152","0.0175","-0.3551"
"","117440.0024","0.0152","0.0175","-0.3437"
"","117639.9994","0.0152","0.0175","-0.3336"
"","117839.9963","0.0152","0.0175","-0.3248"
"","118040.0009","0.0152","0.0175","-0.3169"
"","118239.9979","0.0152","0.0175","-0.3097"
"","118440.0024","0.0152","0.0175","-0.3041"
"","118639.9994","0.0152","0.0175","-0.2994"
"","118839.9963","0.0152","0.0175","-0.2938"
"","119040.0009","0.0152","0.0175","-0.2900"
"","119239.9979","0.0152","0.0175","-0.2854"
"","119440.0024","0.0152","0.0175","-0.2814"
"","119639.9994","0.0152","0.0175","-0.2789"
"","119839.9963","0.0152","0.0175","-0.2808"
"","120040.0009","0.0152","0.0175","-1.0470"
"","120234.0012","0.0152","0.0175","-3.2805"
"","120421.9971","0.0152","0.0175","-5.8433"
"","120622.0016","0.0152","0.0175","-8.3299"
"","120821.9986","0.0152","0.0175","-10.6903"
"","121022.0032","0.0152","0.0175","-12.8500"
"","121222.0001","0.0152","0.0175","-14.4812"
"","121421.9971","0.0152","0.0175","-15.8658"
"","121622.0016","0.0152","0.0175","-17.2521"
"","121821.9986","0.0152","0.0175","-18.6842"
"","122022.0032","0.0152","0.0175","-20.0986"
"","122222.0001","0.0152","0.0175","-21.3057"
"","122421.9971","0.0152","0.0175","-22.0304"
"","122622.0016","0.0152","0.0175","-22.5556"
"","122821.9986","0.0152","0.0175","-22.9775"
"","123022.0032","0.0152","0.0175","-23.4763"
"","123222.0001","0.0152","0.0175","-23.9129"
"","123421.9971","0.0152","0.0175","-24.0982"
"","123622.0016","0.0152","0.0175","-24.3393"
"","123821.9986","0.0152","0.0175","-24.6667"
"","124022.0032","0.0152","0.0175","-25.0011"
"","124222.0001","0.0152","0.0175","-25.2940"
"","124421.9971","0.0152","0.0175","-25.5802"
"","124622.0016","0.0152","0.0175","-25.9795"
"","124821.9986","0.0152","0.0175","-26.4280"
"","125022.0032","0.0152","0.0175","-26.6768"
"","125222.0001","0.0152","0.0175","-26.8833"
"","125421.9971","0.0152","0.0175","-27.1241"
"","125622.0016","0.0152","0.0175","-27.3359"
"","125821.9986","0.0152","0.0175","-27.5747"
"","126022.0032","0.0152","0.0175","-27.5329"
"","126222.0001","0.0152","0.0175","-26.7538"
"","126421.9971","0.0152","0.0175","-25.4622"
"","126622.0016","0.0152","0.0175","-24.2744"
"","126821.9986","0.0152","0.0175","-23.2132"
"","127022.0032","0.0152","0.0175","-22.3659"
"","127222.0001","0.0152","0.0175","-21.7139"
"","127421.9971","0.0152","0.0175","-21.0834"
"","127622.0016","0.0152","0.0175","-20.4074"
"","127821.9986","0.0152","0.0175","-19.7934"
"","128022.0032","0.0152","0.0175","-19.2075"
"","128222.0001","0.0152","0.0175","-18.5546"
"","128421.9971","0.0152","0.0175","-17.8138"
"","128621.9940","0.0152","0.0175","-16.9877"
"","128822.0062","0.0152","0.0175","-16.2840"
"","129022.0032","0.0152","0.0175","-15.5540"
"","129222.0001","0.0152","0.0175","-14.7995"
"","129421.9971","0.0152","0.0175","-13.9309"
"","129621.9940","0.0152","0.0175","-13.0556"
"","129822.0062","0.0152","0.0175","-12.2843"
"","130022.0032","0.0152","0.0175","-11.7898"
"","130222.0001","0.0152","0.0175","-11.0837"
"","130421.9971","0.0152","0.0175","-10.4559"
"","130621.9940","0.0152","0.0175","-9.7614"
"","130822.0062","0.0152","0.0175","-9.4855"
"","131022.0032","0.0152","0.0175","-9.5655"
"","131222.0001","0.0152","0.0175","-9.5865"
"","131421.9971","0.0152","0.0175","-9.5290"
"","131621.9940","0.0152","0.0175","-7.8012"
"","131822.0062","0.0152","0.0175","-5.6721"
"","132022.0032","0.0152","0.0175","-3.6123"
"","132222.0001","0.0152","0.0175","-2.2073"
"","132421.9971","0.0152","0.0175","-2.1800"
"","132621.9940","0.0152","0.0175","-2.2918"
"","132822.0062","0.0152","0.0175","-2.3877"
"","133022.0032","0.0152","0.0175","-2.4578"
"","133222.0001","0.0152","0.0175","-2.5124"
"","133421.9971","0.0152","0.0175","-2.5573"
"","133621.9940","0.0152","0.0175","-2.5965"
"","133822.0062","0.0152","0.0175","-2.6279"
"","134022.0032","0.0152","0.0175","-2.6419"
"","134222.0001","0.0152","0.0175","-2.6559"
"","134421.9971","0.0152","0.0175","-2.6679"
"","134621.9940","0.0152","0.0175","-2.6614"
"","134822.0062","0.0152","0.0175","-2.6438"
"","135022.0032","0.0152","0.0175","-2.3980"
"","135222.0001","0.0152","0.0175","-1.4582"
"","135421.9971","0.0152","0.0175","-1.0511"
"","135621.9940","0.0152","0.0175","-0.8216"
"","135822.0062","0.0152","0.0175","-0.8429"
"","136022.0032","0.0152","0.0175","-0.8701"
"","136222.0001","0.0152","0.0175","-0.8873"
"","136421.9971","0.0152","0.0175","-0.9007"
"","136621.9940","0.0152","0.0175","-0.9123"
"","136822.0062","0.0152","0.0175","-0.9220"
"","137022.0032","0.0152","0.0175","-0.9314"
"","137222.0001","0.0152","0.0175","-0.9434"
"","137421.9971","0.0152","0.0175","-1.4662"
"","137570.0073","0.0152","0.0175","-3.9813"
"","137667.9993","0.0152","0.0175","-6.6335"
"","137757.9956","0.0152","0.0175","-9.2447"
"","137848.0072","0.0152","0.0175","-11.9770"
"","137938.0035","0.0152","0.0175","-14.5867"
"","138027.9999","0.0152","0.0175","-17.2170"
"","138119.0033","0.0152","0.0175","-19.8879"
"","138227.0050","0.0152","0.0175","-22.5157"
"","138397.0032","0.0152","0.0175","-24.8198"
"","138597.0001","0.0152","0.0175","-26.0410"
"","138796.9971","0.0152","0.0175","-27.4940"
"","138996.9940","0.0152","0.0175","-28.5580"
"","139197.0062","0.0152","0.0175","-29.1819"
"","139397.0032","0.0152","0.0175","-28.7809"
"","139597.0001","0.0152","0.0175","-28.3724"
"","139796.9971","0.0152","0.0175","-28.0904"
"","139996.9940","0.0152","0.0175","-27.7231"
"","140197.0062","0.0152","0.0175","-26.9869"
"","140397.0032","0.0152","0.0175","-26.1251"
"","140597.0001","0.0152","0.0175","-25.3728"
"","140796.9971","0.0152","0.0175","-24.7287"
"","140996.9940","0.0152","0.0175","-23.8870"
"","141197.0062","0.0152","0.0175","-22.9458"
"","141397.0032","0.0152","0.0175","-22.0024"
"","141597.0001","0.0152","0.0175","-20.9808"
"","141779.0070","0.0152","0.0175","-19.9844"
"","141942.0013","0.0452","0.0520","-19.0337"
"","142141.9983","0.1115","0.1282","-17.9107"
"","142341.9952","0.1781","0.2047","-16.6598"
"","142542.0074","0.2446","0.2811","-14.9084"
"","142742.0044","0.3115","0.3580","-12.9125"
"","142942.0013","0.3779","0.4344","-10.9719"
"","143141.9983","0.4447","0.5112","-9.2083"
"","143341.9952","0.5114","0.5878","-7.8893"
"","143542.0074","0.5780","0.6643","-6.5960"
"","143742.0044","0.6447","0.7410","-5.3816"
"","143942.0013","0.7114","0.8177","-4.4642"
"","144141.9983","0.7779","0.8941","-4.1381"
"","144341.9952","0.8445","0.9707","-3.9193"
"","144542.0074","0.9112","1.0473","-3.4867"
"","144742.0044","0.9780","1.1242","-2.7327"
"","144942.0013","1.0448","1.2009","-2.2761"
"","145141.9983","1.1113","1.2774","-1.8588"
"","145341.9952","1.1780","1.3540","-1.3326"
"","145542.0074","1.2446","1.4306","-1.2124"
"","145742.0044","1.3114","1.5073","-1.1339"
"","145942.0013","1.3779","1.5838","-0.9138"
"","146141.9983","1.4447","1.6606","-0.6372"
"","146341.9952","1.5112","1.7371","-0.6086"
"","146542.0074","1.5779","1.8137","-0.5989"
"","146742.0044","1.6445","1.8903","-0.5793"
"","146942.0013","1.7113","1.9670","-0.5550"
"","147141.9983","1.7780","2.0437","-0.5261"
"","147341.9952","1.8448","2.1204","-0.4952"
"","147542.0074","1.9113","2.1969","-0.4626"
"","147742.0044","1.9780","2.2735","-0.4293"
"","147942.0013","2.0445","2.3500","-0.3948"
"","148141.9983","2.1114","2.4268","-0.3585"
"","148341.9952","2.1780","2.5034","-0.3198"
"","148542.0074","2.2447","2.5801","-0.2817"
"","148742.0044","2.3114","2.6567","-0.2430"
"","148942.0013","2.3780","2.7333","-0.2030"
"","149141.9983","2.4447","2.8100","-0.1642"
"","149341.9952","2.5113","2.8866","-0.1241"
"","149542.0074","2.5780","2.9632","-0.0854"
"","149742.0044","2.6446","3.0398","-0.0449"
"","149942.0013","2.7112","3.1164","-0.0043"
"","150141.9983","2.7778","3.1929","0.0349"
"","150341.9952","2.8445","3.2696","0.0760"
"","150542.0074","2.9113","3.3463","0.1165"
"","150742.0044","2.9781","3.4231","0.1573"
"","150942.0013","3.0447","3.4996","0.1975"
"","151141.9983","3.1114","3.5763","0.2378"
"","151341.9952","3.1778","3.6527","0.2762"
"","151542.0074","3.2447","3.7295","0.3140"
"","151742.0044","3.3113","3.8060","0.3506"
"","151942.0013","3.3779","3.8826","0.3884"
"","152141.9983","3.4446","3.9593","0.4248"
"","152341.9952","3.5113","4.0360","0.4598"
"","152542.0074","3.5781","4.1127","0.4512"
"","152742.0044","3.6447","4.1893","0.0841"
"","152942.0013","3.7114","4.2660","0.0845"
"","153141.9983","3.7781","4.3426","0.1387"
"","153341.9952","3.8447","4.4192","0.1928"
"","153542.0074","3.9112","4.4957","0.2418"
"","153742.0044","3.9778","4.5722","0.2883"
"","153942.0013","4.0447","4.6490","0.3346"
"","154141.9983","4.1113","4.7257","0.3795"
"","154341.9952","4.1779","4.8022","0.4235"
"","154542.0074","4.2446","4.8789","0.4662"
"","154742.0044","4.3112","4.9554","0.5082"
"","154942.0013","4.3781","5.0323","0.5496"
"","155141.9983","4.4447","5.1088","0.5896"
"","155341.9952","4.5113","5.1854","0.6295"
"","155542.0074","4.5779","5.2620","0.6695"
"","155742.0044","4.6445","5.3385","0.7093"
"","155942.0013","4.7113","5.4153","0.7470"
"","156141.9983","4.7779","5.4918","0.7874"
"","156341.9952","4.8447","5.5686","0.8261"
"","156542.0074","4.9113","5.6451","0.8652"
"","156742.0044","4.9781","5.7219","0.9029"
"","156895.9961","5.0273","5.7785","0.9295"
"","157095.9930","5.0271","5.7783","0.9234"
"","157296.0052","5.0255","5.7764","0.9180"
"","157496.0022","5.0242","5.7750","0.9148"
"","157695.9991","5.0235","5.7741","0.9121"
"","157895.9961","5.0231","5.7737","0.9083"
"","158095.9930","5.0229","5.7735","0.9037"
"","158296.0052","5.0228","5.7734","0.8902"
"","158496.0022","5.0228","5.7733","0.2916"
"","158695.9991","5.0228","5.7733","-0.0533"
"","158895.9961","5.0228","5.7733","-0.0065"
"","159095.9930","5.0228","5.7733","0.0195"
"","159296.0052","5.0228","5.7733","0.0350"
"","159496.0022","5.0228","5.7733","0.0476"
"","159695.9991","5.0228","5.7733","0.0535"
"","159895.9961","5.0228","5.7733","0.0578"
"","160095.9930","5.0228","5.7733","0.0636"
"","160296.0052","5.0228","5.7733","0.0685"
"","160496.0022","5.0228","5.7733","0.0694"
"","160695.9991","5.0228","5.7733","0.0700"
"","160895.9961","5.0228","5.7733","0.0680"
"","161095.9930","5.0228","5.7733","0.0432"
"","161285.0037","5.0228","5.7733","-1.8454"
"","161444.0002","5.0228","5.7733","-4.4118"
"","161585.0067","5.0228","5.7733","-7.0322"
"","161725.0061","5.0228","5.7733","-9.6101"
"","161873.0011","5.0228","5.7733","-12.1734"
"","162022.9950","5.0228","5.7733","-14.7471"
"","162175.0031","5.0228","5.7733","-17.3171"
"","162365.9973","5.0228","5.7733","-19.7867"
"","162565.9943","5.0228","5.7733","-22.1100"
"","162766.0065","5.0228","5.7733","-24.0308"
"","162966.0034","5.0228","5.7733","-25.4021"
"","163166.0004","5.0228","5.7733","-26.2017"
"","163365.9973","5.0228","5.7733","-26.6303"
"","163565.9943","5.0228","5.7733","-26.4454"
"","163766.0065","5.0228","5.7733","-26.0443"
"","163966.0034","5.0228","5.7733","-25.7790"
"","164166.0004","5.0228","5.7733","-25.5842"
"","164365.9973","5.0228","5.7733","-25.3372"
"","164565.9943","5.0228","5.7733","-24.5532"
"","164766.0065","5.0228","5.7733","-23.7371"
"","164966.0034","5.0228","5.7733","-23.0780"
"","165166.0004","5.0228","5.7733","-22.5128"
"","165365.9973","5.0228","5.7733","-22.0133"
"","165565.9943","5.0228","5.7733","-21.3506"
"","165766.0065","5.0228","5.7733","-20.6258"
"","165966.0034","5.0228","5.7733","-19.9746"
"","166166.0004","5.0228","5.7733","-19.3295"
"","166365.9973","5.0228","5.7733","-18.5411"
"","166565.9943","5.0228","5.7733","-17.6476"
"","166766.0065","5.0228","5.7733","-16.7045"
"","166966.0034","5.0228","5.7733","-15.7456"
"","167166.0004","5.0228","5.7733","-14.8176"
"","167365.9973","5.0228","5.7733","-13.9758"
"","167565.9943","5.0228","5.7733","-13.2938"
"","167766.0065","5.0228","5.7733","-12.7337"
"","167966.0034","5.0228","5.7733","-12.3139"
"","168166.0004","5.0228","5.7733","-11.8209"
"","168365.9973","5.0228","5.7733","-11.2619"
"","168565.9943","5.0228","5.7733","-10.7449"
"","168766.0065","5.0228","5.7733","-10.1157"
"","168966.0034","5.0228","5.7733","-9.4028"
"","169166.0004","5.0228","5.7733","-8.8949"
"","169365.9973","5.0228","5.7733","-8.6029"
"","169565.9943","5.0228","5.7733","-8.2523"
"","169766.0065","5.0228","5.7733","-7.7053"
"","169966.0034","5.0228","5.7733","-7.0132"
"","170166.0004","5.0228","5.7733","-6.3383"
"","170365.9973","5.0228","5.7733","-5.9967"
"","170565.9943","5.0228","5.7733","-5.6056"
[...]
"","118422.9965","0.0152","0.0174","-17.9148"
"","118589.9963","0.0152","0.0174","-20.4878"
"","118776.0010","0.0152","0.0174","-22.9303"
"","118975.9979","0.0152","0.0174","-24.4287"
"","119176.0025","0.0152","0.0174","-25.1655"
"","119375.9995","0.0152","0.0174","-25.9681"
"","119575.9964","0.0152","0.0174","-26.7752"
"","119776.0010","0.0152","0.0174","-27.6000"
"","119975.9979","0.0152","0.0174","-28.2635"
"","120176.0025","0.0152","0.0174","-28.7591"
"","120375.9995","0.0152","0.0174","-29.2659"
"","120575.9964","0.0152","0.0174","-29.6572"
"","120776.0010","0.0152","0.0174","-29.6033"
"","120975.9979","0.0152","0.0174","-29.2286"
"","121176.0025","0.0152","0.0174","-28.9604"
"","121375.9995","0.0152","0.0174","-28.7433"
"","121575.9964","0.0152","0.0174","-28.5590"
"","121776.0010","0.0152","0.0174","-28.3983"
"","121975.9979","0.0152","0.0174","-28.2558"
"","122176.0025","0.0152","0.0174","-28.1263"
"","122375.9995","0.0152","0.0174","-28.0086"
"","122575.9964","0.0152","0.0174","-27.8971"
"","122776.0010","0.0152","0.0174","-27.5243"
"","122975.9979","0.0152","0.0174","-26.6639"
"","123176.0025","0.0152","0.0174","-25.7430"
"","123375.9995","0.0152","0.0174","-24.9437"
"","123575.9964","0.0152","0.0174","-24.0817"
"","123776.0010","0.0152","0.0174","-23.1370"
"","123975.9979","0.0152","0.0174","-22.1139"
"","124176.0025","0.0152","0.0174","-21.0760"
"","124375.9995","0.0152","0.0174","-20.1243"
"","124575.9964","0.0152","0.0174","-19.1760"
"","124776.0010","0.0152","0.0174","-18.2076"
"","124975.9979","0.0152","0.0174","-17.2094"
"","125176.0025","0.0152","0.0174","-15.9995"
"","125375.9995","0.0152","0.0174","-14.7249"
"","125575.9964","0.0152","0.0174","-13.3194"
"","125776.0010","0.0152","0.0174","-11.9641"
"","125975.9979","0.0152","0.0174","-10.5684"
"","126176.0025","0.0152","0.0174","-9.1176"
"","126375.9995","0.0152","0.0174","-7.6931"
"","126575.9964","0.0152","0.0174","-6.5249"
"","126776.0010","0.0152","0.0174","-5.3394"
"","126975.9979","0.0152","0.0174","-4.6663"
"","127176.0025","0.0152","0.0174","-4.0914"
"","127375.9995","0.0152","0.0174","-3.5829"
"","127575.9964","0.0152","0.0174","-3.3540"
"","127776.0010","0.0152","0.0174","-2.9834"
"","127975.9979","0.0152","0.0174","-3.0430"
"","128175.9949","0.0152","0.0174","-3.1241"
"","128376.0071","0.0152","0.0174","-3.1884"
"","128576.0040","0.0152","0.0174","-3.2359"
"","128776.0010","0.0152","0.0174","-3.2689"
"","128975.9979","0.0152","0.0174","-2.3172"
"","129175.9949","0.0152","0.0174","-1.5400"
"","129376.0071","0.0152","0.0174","-1.1220"
"","129576.0040","0.0152","0.0174","-1.0462"
"","129776.0010","0.0152","0.0174","-0.7484"
"","129975.9979","0.0152","0.0174","-0.5801"
"","130175.9949","0.0152","0.0174","-0.6241"
"","130376.0071","0.0152","0.0174","-0.6548"
"","130576.0040","0.0152","0.0174","-0.6781"
"","130776.0010","0.0152","0.0174","-0.6968"
"","130975.9979","0.0152","0.0174","-0.7135"
"","131175.9949","0.0152","0.0174","-0.6942"
"","131376.0071","0.0152","0.0174","-0.4958"
"","131576.0040","0.0152","0.0174","-0.1912"
"","131776.0010","0.0152","0.0174","-0.0548"
"","131975.9979","0.0152","0.0174","-0.0115"
"","132175.9949","0.0152","0.0174","0.0030"
"","132376.0071","0.0152","0.0174","0.0087"
"","132576.0040","0.0152","0.0174","0.0120"
"","132776.0010","0.0152","0.0174","0.0134"
"","132975.9979","0.0152","0.0174","0.0148"
"","133175.9949","0.0152","0.0174","0.0156"
"","133376.0071","0.0152","0.0174","0.0165"
"","133576.0040","0.0152","0.0174","0.0171"
"","133776.0010","0.0152","0.0174","0.0171"
"","133975.9979","0.0152","0.0174","0.0176"
"","134175.9949","0.0152","0.0174","0.0170"
"","134376.0071","0.0152","0.0174","0.0172"
"","134576.0040","0.0152","0.0174","0.0156"
"","134776.0010","0.0152","0.0174","0.0132"
"","134975.9979","0.0152","0.0174","0.0089"
"","135175.9949","0.0152","0.0174","0.0067"
"","135376.0071","0.0152","0.0174","0.0051"
"","135576.0040","0.0152","0.0174","0.0012"
"","135776.0010","0.0152","0.0174","-0.0003"
"","135975.9979","0.0152","0.0174","-0.0034"
"","136175.9949","0.0152","0.0174","-0.0059"
"","136376.0071","0.0152","0.0174","-0.0067"
"","136576.0040","0.0152","0.0174","-0.0073"
"","136776.0010","0.0152","0.0174","-0.0089"
"","136975.9979","0.0152","0.0174","-0.0098"
"","137175.9949","0.0152","0.0174","-0.0101"
"","137376.0071","0.0152","0.0174","-0.0107"
"","137576.0040","0.0152","0.0174","-0.0108"
"","137776.0010","0.0152","0.0174","-0.0116"
"","137975.9979","0.0152","0.0174","-0.0120"
"","138175.9949","0.0152","0.0174","-0.0124"
"","138376.0071","0.0152","0.0174","-0.0126"
"","138576.0040","0.0152","0.0174","-0.0129"
"","138776.0010","0.0152","0.0174","-0.0137"
"","138975.9979","0.0152","0.0174","-0.0145"
"","139175.9949","0.0152","0.0174","-0.0149"
"","139376.0071","0.0152","0.0174","-0.0145"
"","139576.0040","0.0152","0.0174","-0.0151"
"","139776.0010","0.0152","0.0174","-0.0157"
"","139975.9979","0.0152","0.0174","-0.0160"
"","140175.9949","0.0152","0.0174","-0.0161"
"","140376.0071","0.0152","0.0174","-0.0162"
"","140576.0040","0.0152","0.0174","-0.0165"
"","140776.0010","0.0152","0.0174","-0.0165"
"","140975.9979","0.0152","0.0174","-0.0170"
"","141175.9949","0.0152","0.0174","-0.0169"
"","141376.0071","0.0152","0.0174","-0.0172"
"","141576.0040","0.0152","0.0174","-0.0176"
"","141776.0010","0.0152","0.0174","-0.0173"
"","141938.9954","0.0152","0.0174","-0.0173"
"","142136.9934","0.0585","0.0672","0.0168"
"","142337.0056","0.1249","0.1435","0.0624"
"","142537.0026","0.1913","0.2198","0.1049"
"","142736.9995","0.2579","0.2964","0.1463"
"","142936.9965","0.3247","0.3732","0.1867"
"","143136.9934","0.3913","0.4498","0.2261"
"","143337.0056","0.4580","0.5264","0.2651"
"","143537.0026","0.5247","0.6031","0.3038"
"","143736.9995","0.5911","0.6795","0.3424"
"","143936.9965","0.6580","0.7563","0.3805"
"","144136.9934","0.7246","0.8328","0.4186"
"","144337.0056","0.7912","0.9094","0.4555"
"","144537.0026","0.8579","0.9861","0.4930"
"","144736.9995","0.9245","1.0626","0.5287"
"","144936.9965","0.9913","1.1394","0.5650"
"","145136.9934","1.0580","1.2161","0.6012"
"","145337.0056","1.1247","1.2928","0.6371"
"","145537.0026","1.1912","1.3692","0.6734"
"","145736.9995","1.2579","1.4459","0.7082"
"","145936.9965","1.3245","1.5224","0.7432"
"","146136.9934","1.3911","1.5990","0.7777"
"","146337.0056","1.4579","1.6758","0.8131"
"","146537.0026","1.5246","1.7524","0.8477"
"","146736.9995","1.5912","1.8289","0.8761"
"","146936.9965","1.6580","1.9057","0.8936"
"","147136.9934","1.7245","1.9822","0.9066"
"","147337.0056","1.7914","2.0591","0.9078"
"","147537.0026","1.8579","2.1355","0.7424"
"","147736.9995","1.9247","2.2123","0.2663"
"","147936.9965","1.9912","2.2888","-0.2364"
"","148136.9934","2.0578","2.3653","-0.5756"
"","148337.0056","2.1245","2.4420","-0.6587"
"","148537.0026","2.1911","2.5186","-0.6007"
"","148736.9995","2.2580","2.5954","-0.5376"
"","148936.9965","2.3247","2.6721","-0.4796"
"","149136.9934","2.3914","2.7487","-0.4244"
"","149337.0056","2.4580","2.8252","-0.3744"
"","149537.0026","2.5246","2.9019","-0.3261"
"","149736.9995","2.5913","2.9785","-0.2761"
"","149936.9965","2.6579","3.0551","-0.2275"
"","150136.9934","2.7245","3.1316","-0.1801"
"","150337.0056","2.7911","3.2082","-0.1334"
"","150537.0026","2.8577","3.2847","-0.0876"
"","150736.9995","2.9246","3.3616","-0.0425"
"","150936.9965","2.9913","3.4382","0.0020"
"","151136.9934","3.0580","3.5150","0.0440"
"","151337.0056","3.1248","3.5917","0.0716"
"","151537.0026","3.1913","3.6682","0.0839"
"","151736.9995","3.2579","3.7447","0.1207"
"","151936.9965","3.3245","3.8213","0.1632"
"","152136.9934","3.3912","3.8979","0.2049"
"","152337.0056","3.4579","3.9746","0.2465"
"","152537.0026","3.5245","4.0512","0.2867"
"","152736.9995","3.5912","4.1278","0.3270"
"","152936.9965","3.6580","4.2045","0.3671"
"","153136.9934","3.7247","4.2813","0.4067"
"","153337.0056","3.7915","4.3580","0.4437"
"","153537.0026","3.8580","4.4345","0.4770"
"","153736.9995","3.9246","4.5111","0.5009"
"","153936.9965","3.9910","4.5874","0.4378"
"","154136.9934","4.0580","4.6643","0.1100"
"","154337.0056","4.1244","4.7407","0.1025"
"","154537.0026","4.1912","4.8175","0.1522"
"","154736.9995","4.2578","4.8941","0.2036"
"","154936.9965","4.3245","4.9707","0.2523"
"","155136.9934","4.3913","5.0474","0.2991"
"","155337.0056","4.4580","5.1241","0.3441"
"","155537.0026","4.5247","5.2008","0.3883"
"","155736.9995","4.5913","5.2774","0.4303"
"","155936.9965","4.6579","5.3539","0.4719"
"","156136.9934","4.7245","5.4304","0.5125"
"","156337.0056","4.7912","5.5071","0.5528"
"","156537.0026","4.8579","5.5838","0.5921"
"","156736.9995","4.9246","5.6605","0.6310"
"","156936.9965","4.9913","5.7371","0.6704"
"","157091.0034","5.0285","5.7799","0.6884"
"","157291.0004","5.0267","5.7778","0.6830"
"","157490.9973","5.0251","5.7760","0.6799"
"","157690.9943","5.0240","5.7747","0.6776"
"","157891.0065","5.0233","5.7739","0.6760"
"","158091.0034","5.0230","5.7736","0.6756"
"","158291.0004","5.0228","5.7734","0.6739"
"","158490.9973","5.0228","5.7733","0.6722"
"","158690.9943","5.0227","5.7732","0.6715"
"","158891.0065","5.0227","5.7732","0.6706"
"","159091.0034","5.0227","5.7732","0.6699"
"","159291.0004","5.0227","5.7732","0.6638"
"","159490.9973","5.0227","5.7732","0.1054"
"","159690.9943","5.0227","5.7732","-1.0239"
"","159891.0065","5.0227","5.7732","-2.5897"
"","160078.0029","5.0227","5.7732","-5.1008"
"","160270.0043","5.0227","5.7732","-7.6526"
"","160436.9965","5.0227","5.7733","-10.2275"
"","160606.9946","5.0227","5.7733","-12.7902"
"","160796.9971","5.0227","5.7733","-15.3394"
"","160996.9940","5.0227","5.7733","-17.6579"
"","161197.0062","5.0227","5.7733","-19.3296"
"","161397.0032","5.0227","5.7733","-20.6524"
"","161597.0001","5.0227","5.7733","-21.9377"
"","161796.9971","5.0227","5.7733","-22.9006"
"","161996.9940","5.0227","5.7733","-23.5061"
"","162197.0062","5.0227","5.7733","-24.1470"
"","162397.0032","5.0227","5.7733","-24.8446"
"","162597.0001","5.0227","5.7733","-25.4937"
"","162796.9971","5.0227","5.7733","-26.0031"
"","162996.9940","5.0227","5.7733","-26.4705"
"","163197.0062","5.0227","5.7733","-26.9687"
"","163397.0032","5.0227","5.7733","-27.4611"
"","163597.0001","5.0227","5.7733","-27.9569"
"","163796.9971","5.0227","5.7733","-28.4155"
"","163996.9940","5.0227","5.7733","-28.8519"
"","164197.0062","5.0227","5.7733","-29.2971"
"","164397.0032","5.0227","5.7733","-29.3245"
"","164597.0001","5.0227","5.7733","-29.1302"
"","164796.9971","5.0227","5.7733","-28.8610"
"","164996.9940","5.0227","5.7733","-28.6436"
"","165197.0062","5.0227","5.7733","-28.4613"
"","165397.0032","5.0227","5.7733","-28.2999"
"","165597.0001","5.0227","5.7733","-28.1552"
"","165796.9971","5.0227","5.7733","-28.0256"
"","165996.9940","5.0227","5.7733","-27.8128"
"","166197.0062","5.0227","5.7733","-27.2294"
"","166397.0032","5.0227","5.7733","-26.5362"
"","166597.0001","5.0227","5.7733","-25.9680"
"","166796.9971","5.0227","5.7733","-25.4888"
"","166996.9940","5.0227","5.7733","-24.9742"
"","167197.0062","5.0227","5.7733","-24.4074"
"","167397.0032","5.0227","5.7733","-23.8760"
"","167597.0001","5.0227","5.7733","-23.4168"
"","167796.9971","5.0227","5.7733","-22.9505"
"","167996.9940","5.0227","5.7733","-22.4324"
"","168197.0062","5.0227","5.7733","-21.9615"
"","168397.0032","5.0227","5.7733","-21.5384"
"","168597.0001","5.0227","5.7733","-21.1742"
"","168796.9971","5.0227","5.7733","-20.7763"
"","168996.9940","5.0227","5.7733","-20.4114"
"","169197.0062","5.0227","5.7733","-20.0885"
"","169397.0032","5.0227","5.7733","-19.7419"
"","169597.0001","5.0227","5.7733","-19.4091"
"","169796.9971","5.0227","5.7733","-19.0832"
"","169996.9940","5.0227","5.7733","-18.7487"
"","170197.0062","5.0227","5.7733","-18.3501"
"","170397.0032","5.0227","5.7733","-17.8986"
"","170597.0001","5.0227","5.7733","-17.4465"
"","170796.9971","5.0227","5.7733","-17.0085"
"","170996.9940","5.0227","5.7733","-16.6007"
"","171197.0062","5.0227","5.7733","-16.1500"
"","171397.0032","5.0227","5.7733","-15.7354"
"","171597.0001","5.0227","5.7733","-15.2358"
"","171796.9971","5.0227","5.7733","-14.7165"
"","171996.9940","5.0227","5.7733","-14.2771"
"","172197.0062","5.0227","5.7733","-13.3607"
"","172397.0032","5.0227","5.7733","-12.3689"
"","172597.0001","5.0227","5.7733","-11.7776"
"","172796.9971","5.0227","5.7733","-11.2828"
"","172996.9940","5.0227","5.7733","-10.3430"
"","173197.0062","5.0227","5.7733","-9.1426"
"","173397.0032","5.0227","5.7733","-8.2025"
"","173597.0001","5.0227","5.7733","-7.4777"
"","173796.9971","5.0227","5.7733","-7.0451"
"","173996.9940","5.0227","5.7733","-6.6049"
"","174197.0062","5.0227","5.7733","-6.1203"
"","174397.0032","5.0227","5.7733","-6.0938"
"","174597.0001","5.0227","5.7733","-5.7994"
"","174796.9971","5.0227","5.7733","-5.4575"
"","174996.9940","5.0227","5.7733","-5.1438"
"","175197.0062","5.0227","5.7733","-4.4215"
"","175397.0032","5.0227","5.7733","-3.8773"
"","175597.0001","5.0227","5.7733","-3.4588"
"","175796.9971","5.0227","5.7733","-2.9230"
"","175996.9940","5.0227","5.7733","-2.6552"
"","176197.0062","5.0227","5.7733","-2.5676"
"","176397.0032","5.0227","5.7733","-2.2682"
"","176597.0001","5.0227","5.7733","-2.0406"
"","176796.9971","5.0227","5.7733","-1.6456"
"","176996.9940","5.0227","5.7733","-1.4236"
"","177197.0062","5.0227","5.7733","-1.2216"
"","177397.0032","5.0227","5.7733","-0.8991"
"","177597.0001","5.0227","5.7733","-0.5654"
"","177796.9971","5.0227","5.7733","-0.3672"
"","177996.9940","5.0227","5.7733","-0.2330"
"","178197.0062","5.0227","5.7733","-0.1860"
"","178397.0032","5.0227","5.7733","-0.0718"
"","178597.0001","5.0227","5.7733","0.0833"
"","178796.9971","5.0227","5.7733","0.0976"
"","178996.9940","5.0227","5.7733","0.0928"
"","179197.0062","5.0227","5.7733","0.1686"
"","179397.0032","5.0227","5.7733","0.1569"
"","179597.0001","5.0227","5.7733","0.1398"
"","179796.9971","5.0227","5.7733","0.1281"
"","179996.9940","5.0227","5.7733","0.1192"
"","180197.0062","5.0227","5.7733","0.1113"
"","180397.0032","5.0227","5.7733","0.1046"
"","180597.0001","5.0227","5.7733","0.0992"
"","180796.9971","5.0227","5.7733","0.0951"
"","180996.9940","5.0227","5.7733","0.0910"
"","181197.0062","5.0227","5.7733","0.0883"
"","181397.0032","5.0227","5.7733","0.0857"
"","181597.0001","5.0227","5.7733","0.0839"
"","181796.9971","5.0227","5.7733","0.0822"
"","181996.9940","5.0227","5.7733","0.0813"
"","182197.0062","5.0227","5.7733","0.0812"
"","182397.0032","5.0227","5.7733","0.0788"
"","182597.0001","5.0227","5.7733","0.0776"
"","182796.9971","5.0227","5.7733","0.0781"
"","182996.9940","5.0227","5.7733","0.0780"
"","183197.0062","5.0228","5.7733","0.0776"
"","183397.0032","5.0227","5.7733","0.0781"
"","183597.0001","5.0227","5.7733","0.0785"
"","183796.9971","5.0228","5.7733","0.0808"
"","183996.9940","5.0227","5.7733","0.0897"
"","184197.0062","5.0227","5.7733","0.1020"
"","184397.0032","5.0227","5.7733","0.2935"
"","184597.0001","5.0227","5.7733","0.5258"
"","184796.9971","5.0227","5.7733","0.5127"
"","184996.9940","5.0227","5.7733","0.4973"
"","185197.0062","5.0227","5.7733","0.4761"
"","185397.0032","5.0227","5.7733","0.4313"
"","185597.0001","5.0227","5.7733","0.3617"
"","185796.9971","5.0227","5.7733","0.3030"
"","185996.9940","5.0227","5.7733","0.2897"
"","186197.0062","5.0227","5.7733","0.2868"
"","186397.0032","5.0227","5.7733","0.2888"
"","186597.0001","5.0227","5.7733","0.2910"
"","186796.9971","5.0227","5.7733","0.2924"
"","186996.9940","5.0227","5.7733","0.2935"
"","187154.9988","5.0457","5.7996","0.3124"
"","187354.9957","5.1123","5.8762","0.3617"
"","187554.9927","5.1789","5.9527","0.4088"
"","187755.0049","5.2454","6.0292","0.4536"
"","187955.0018","5.3119","6.1056","0.4970"
"","188154.9988","5.3786","6.1822","0.5396"
"","188354.9957","5.4451","6.2588","0.5801"
"","188554.9927","5.5120","6.3357","0.6213"
"","188755.0049","5.5786","6.4122","0.6611"
"","188955.0018","5.6454","6.4890","0.6997"
"","189154.9988","5.7120","6.5655","0.7383"
"","189354.9957","5.7786","6.6421","0.7768"
"","189554.9927","5.8453","6.7187","0.8152"
"","189755.0049","5.9120","6.7954","0.8532"
"","189955.0018","5.9786","6.8719","0.8906"
"","190154.9988","6.0452","6.9486","0.9281"
"","190354.9957","6.1119","7.0251","0.9656"
"","190554.9927","6.1785","7.1017","1.0026"
"","190755.0049","6.2453","7.1785","1.0401"
"","190955.0018","6.3121","7.2553","1.0763"
"","191154.9988","6.3787","7.3319","1.1118"
"","191354.9957","6.4453","7.4084","1.1477"
"","191554.9927","6.5120","7.4851","1.1838"
"","191755.0049","6.5785","7.5615","1.2193"
"","191955.0018","6.6454","7.6384","1.2549"
"","192154.9988","6.7118","7.7147","1.2885"
"","192354.9957","6.7786","7.7915","1.3237"
"","192554.9927","6.8453","7.8681","1.3594"
"","192755.0049","6.9119","7.9447","1.3946"
"","192955.0018","6.9787","8.0215","1.4301"
"","193154.9988","7.0453","8.0981","1.4640"
"","193354.9957","7.1120","8.1748","1.4986"
"","193554.9927","7.1787","8.2514","1.5339"
"","193755.0049","7.2453","8.3279","1.5691"
"","193955.0018","7.3119","8.4044","1.6037"
"","194154.9988","7.3785","8.4810","1.6385"
"","194354.9957","7.4453","8.5579","1.6734"
"","194554.9927","7.5120","8.6345","1.7080"
"","194755.0049","7.5786","8.7111","1.7425"
"","194955.0018","7.6453","8.7877","1.7769"
"","195154.9988","7.7119","8.8643","1.8111"
"","195354.9957","7.7787","8.9411","1.8452"
"","195554.9927","7.8452","9.0175","1.8791"
"","195755.0049","7.9120","9.0943","1.9128"
"","195955.0018","7.9786","9.1708","1.9464"
"","196154.9988","8.0452","9.2474","1.9800"
"","196354.9957","8.1119","9.3241","2.0136"
"","196554.9927","8.1786","9.4007","2.0461"
"","196755.0049","8.2454","9.4774","2.0738"
"","196955.0018","8.3121","9.5541","2.1074"
"","197154.9988","8.3786","9.6306","2.1405"
"","197354.9957","8.4452","9.7071","2.1729"
"","197554.9927","8.5119","9.7838","2.2057"
"","197755.0049","8.5786","9.8605","2.2382"
"","197955.0018","8.6454","9.9372","2.2688"
"","198154.9988","8.7120","10.0138","2.2994"
"","198354.9957","8.7786","10.0903","2.3317"
"","198554.9927","8.8452","10.1669","2.3636"
"","198755.0049","8.9121","10.2437","2.3926"
"","198955.0018","8.9786","10.3202","2.2918"
"","199154.9988","9.0454","10.3970","1.8364"
"","199354.9957","9.1119","10.4734","1.8216"
"","199554.9927","9.1785","10.5500","1.8693"
"","199755.0049","9.2452","10.6267","1.9150"
"","199955.0018","9.3118","10.7032","1.9578"
"","200154.9988","9.3787","10.7802","1.9932"
"","200354.9957","9.4454","10.8568","1.9376"
"","200554.9927","9.5120","10.9334","1.9076"
"","200755.0049","9.5786","11.0099","1.9542"
"","200955.0018","9.6453","11.0865","1.9972"
"","201154.9988","9.7120","11.1632","2.0382"
"","201354.9957","9.7786","11.2398","2.0770"
"","201554.9927","9.8452","11.3163","2.1150"
"","201755.0049","9.9119","11.3930","2.1528"
"","201955.0018","9.9785","11.4695","2.1892"
"","202110.0006","10.0302","11.5289","2.2168"
"","202309.9976","10.0349","11.5344","2.2134"
"","202509.9945","10.0332","11.5324","2.2088"
"","202710.0067","10.0319","11.5309","2.2039"
"","202910.0037","10.0311","11.5300","2.2001"
"","203110.0006","10.0307","11.5296","2.1964"
"","203309.9976","10.0305","11.5294","2.1930"
"","203509.9945","10.0305","11.5293","2.1901"
"","203710.0067","10.0304","11.5292","2.1872"
"","203910.0037","10.0304","11.5292","2.1842"
"","204110.0006","10.0304","11.5292","2.1830"
"","204309.9976","10.0304","11.5292","2.1793"
"","204509.9945","10.0304","11.5292","1.9757"
"","204710.0067","10.0304","11.5292","1.4540"
"","204910.0037","10.0304","11.5292","1.4881"
"","205110.0006","10.0304","11.5292","1.5107"
"","205309.9976","10.0304","11.5292","1.5224"
"","205509.9945","10.0304","11.5292","1.5304"
"","205710.0067","10.0304","11.5292","1.5353"
"","205910.0037","10.0304","11.5292","1.5392"
"","206110.0006","10.0304","11.5292","1.5392"
"","206309.9976","10.0304","11.5292","1.5403"
"","206509.9945","10.0304","11.5292","1.5421"
"","206710.0067","10.0304","11.5292","1.0407"
"","206735.9924","10.0304","11.5292","0.8583"