File: data/single_circular_test/StepStrainSweepPressure2_3.csv
Time,Displacement,Tensile strain (Displacement),Force
(ms),(mm),(%),(N)
"0.0000","-0.2224","-0.2556","0.0003"
"180.0000","-0.2168","-0.2492","0.0011"
"360.0000","-0.2174","-0.2499","-0.0004"
"540.0000","-0.2180","-0.2505","-0.0002"
"720.0000","-0.2184","-0.2511","-0.0013"
"900.0000","-0.2188","-0.2514","-0.0018"
"1080.0000","-0.2190","-0.2517","-0.0023"
"1260.0000","-0.2191","-0.2519","-0.0028"
"1440.0001","-0.2192","-0.2520","-0.0030"
"1620.0000","-0.2193","-0.2520","-0.0035"
"1800.0000","-0.2193","-0.2521","-0.0038"
"1980.0000","-0.2193","-0.2521","-0.0038"
"2160.0001","-0.2194","-0.2521","-0.0040"
"2339.9999","-0.2194","-0.2521","-0.0039"
"2520.0000","-0.2194","-0.2521","-0.0037"
"2700.0000","-0.2194","-0.2522","-0.0041"
"2880.0001","-0.2194","-0.2522","-0.0038"
"3059.9999","-0.2194","-0.2522","-0.0039"
"3240.0000","-0.2194","-0.2522","-0.0038"
"3420.0001","-0.2194","-0.2522","-0.0039"
"3599.9999","-0.2194","-0.2521","-0.0042"
"3780.0000","-0.2194","-0.2521","-0.0039"
"3960.0000","-0.2194","-0.2521","-0.0035"
"4139.9999","-0.2194","-0.2521","-0.0037"
"4320.0002","-0.2194","-0.2521","-0.0034"
"4500.0000","-0.2194","-0.2521","-0.0033"
"4679.9998","-0.2194","-0.2521","-0.0034"
"4860.0001","-0.2194","-0.2521","-0.0036"
"5040.0000","-0.2194","-0.2521","-0.0029"
"5219.9998","-0.2194","-0.2521","-0.0031"
"5400.0001","-0.2194","-0.2521","-0.0032"
"5579.9999","-0.2194","-0.2521","-0.0030"
"5760.0002","-0.2194","-0.2521","-0.0030"
"5940.0001","-0.2194","-0.2521","-0.0027"
"6119.9999","-0.2194","-0.2521","-0.0030"
"6300.0002","-0.2194","-0.2521","-0.0029"
"6480.0000","-0.2194","-0.2521","-0.0023"
"6659.9998","-0.2194","-0.2521","-0.0021"
"6840.0002","-0.2194","-0.2521","-0.0022"
"7020.0000","-0.2194","-0.2521","-0.0024"
"7199.9998","-0.2194","-0.2521","-0.0019"
"7380.0001","-0.2194","-0.2521","-0.0019"
"7559.9999","-0.2194","-0.2521","-0.0019"
"7739.9998","-0.2194","-0.2521","-0.0016"
"7920.0001","-0.2194","-0.2521","-0.0017"
"8100.0004","-0.2194","-0.2521","-0.0014"
"8279.9997","-0.2194","-0.2521","-0.0009"
"8460.0000","-0.2194","-0.2521","-0.0012"
"8640.0003","-0.2194","-0.2521","-0.0006"
"8819.9997","-0.2194","-0.2521","-0.0007"
"9000.0000","-0.2194","-0.2521","-0.0005"
"9180.0003","-0.2194","-0.2521","-0.0005"
"9359.9997","-0.2194","-0.2521","-0.0003"
"9540.0000","-0.2194","-0.2521","-0.0002"
"9720.0003","-0.2194","-0.2521","0.0001"
"9899.9996","-0.2194","-0.2521","-0.0001"
"10052.0000","-0.2239","-0.2573","-0.0062"
"10232.0004","-0.3704","-0.4258","-0.1126"
"10411.9997","-0.5199","-0.5976","-0.2125"
"10592.0000","-0.6696","-0.7696","-0.3100"
"10772.0003","-0.8196","-0.9420","-0.4055"
"10951.9997","-0.9696","-1.1145","-0.4998"
"11132.0000","-1.1196","-1.2869","-0.5932"
"11312.0003","-1.2695","-1.4592","-0.6862"
"11491.9996","-1.4195","-1.6316","-0.7779"
"11671.9999","-1.5696","-1.8042","-0.8694"
"11852.0002","-1.7195","-1.9765","-0.9614"
"12031.9996","-1.8695","-2.1489","-1.0500"
"12211.9999","-2.0195","-2.3212","-1.1428"
"12392.0002","-2.1697","-2.4939","-1.2369"
"12571.9995","-2.3197","-2.6663","-1.3339"
"12751.9999","-2.4696","-2.8386","-1.4321"
"12932.0002","-2.6195","-3.0109","-1.5337"
"13112.0005","-2.7695","-3.1833","-1.6377"
"13291.9998","-2.9195","-3.3558","-1.7434"
"13472.0001","-3.0694","-3.5280","-1.8530"
"13652.0004","-3.2193","-3.7004","-1.9658"
"13831.9998","-3.3696","-3.8731","-2.0834"
"14012.0001","-3.5197","-4.0456","-2.2029"
"14192.0004","-3.6696","-4.2179","-2.3245"
"14371.9997","-3.8195","-4.3902","-2.4473"
"14552.0000","-3.9695","-4.5626","-2.5720"
"14732.0004","-4.1196","-4.7352","-2.6990"
"14911.9997","-4.2697","-4.9077","-2.8266"
"15092.0000","-4.4195","-5.0799","-2.9532"
"15272.0003","-4.5695","-5.2523","-3.0809"
"15451.9997","-4.7196","-5.4248","-3.2062"
"15632.0000","-4.8695","-5.5972","-3.3289"
"15812.0003","-5.0195","-5.7695","-3.4436"
"15991.9996","-5.1694","-5.9419","-3.5566"
"16172.0009","-5.3196","-6.1145","-3.6577"
"16351.9993","-5.4696","-6.2869","-3.7291"
"16531.9996","-5.6196","-6.4593","-3.2843"
"16711.9999","-5.7694","-6.6315","-2.7876"
"16892.0002","-5.9194","-6.8039","-2.4658"
"17072.0005","-6.0695","-6.9765","-2.1001"
"17252.0008","-6.2196","-7.1490","-1.8161"
"17431.9992","-6.3696","-7.3214","-1.7369"
"17611.9995","-6.5196","-7.4938","-1.7352"
"17791.9998","-6.6697","-7.6663","-1.7857"
"17972.0001","-6.8196","-7.8387","-1.9211"
"18152.0004","-6.9694","-8.0108","-2.0592"
"18332.0007","-7.1193","-8.1831","-2.1989"
"18511.9991","-7.2695","-8.3557","-2.3414"
"18691.9994","-7.4197","-8.5284","-2.4843"
"18871.9997","-7.5696","-8.7007","-2.6274"
"19052.0000","-7.7194","-8.8728","-2.7720"
"19232.0004","-7.8694","-9.0453","-2.9163"
"19412.0007","-8.0196","-9.2179","-3.0634"
"19591.9991","-8.1696","-9.3903","-3.2134"
"19771.9994","-8.3195","-9.5627","-3.3658"
"19951.9997","-8.4696","-9.7352","-3.5155"
"20132.0000","-8.6198","-9.9078","-3.6673"
"20312.0003","-8.7697","-10.0801","-3.8159"
"20492.0006","-8.9195","-10.2523","-3.9347"
"20672.0009","-9.0694","-10.4246","-4.0318"
"20851.9993","-9.2195","-10.5971","-4.1477"
"21031.9996","-9.3696","-10.7697","-4.2764"
"21211.9999","-9.5196","-10.9421","-4.4089"
"21392.0002","-9.6695","-11.1143","-4.4826"
"21572.0005","-9.8195","-11.2868","-4.0217"
"21752.0008","-9.9695","-11.4592","-3.5811"
"21891.0007","-10.0119","-11.5080","-3.2272"
"22070.9991","-10.0063","-11.5015","-2.8791"
"22250.9995","-10.0028","-11.4974","-2.5833"
"22430.9998","-10.0011","-11.4955","-2.4408"
"22611.0001","-10.0004","-11.4947","-2.4286"
"22791.0004","-10.0001","-11.4944","-2.4282"
"22971.0007","-10.0000","-11.4943","-2.4221"
"23150.9991","-10.0000","-11.4942","-2.4174"
"23330.9994","-9.9999","-11.4942","-2.4183"
"23510.9997","-9.9999","-11.4942","-2.4177"
"23691.0000","-9.9999","-11.4942","-2.4168"
"23871.0003","-9.9999","-11.4942","-2.4164"
"24051.0006","-9.9999","-11.4942","-2.4215"
"24231.0009","-10.0000","-11.4942","-2.4305"
"24410.9993","-10.0000","-11.4942","-2.4364"
"24590.9996","-10.0000","-11.4942","-2.4402"
"24770.9999","-10.0000","-11.4942","-2.4424"
"24951.0002","-10.0000","-11.4942","-2.4449"
"25131.0005","-10.0000","-11.4942","-2.4446"
"25311.0008","-10.0000","-11.4942","-2.4478"
"25490.9992","-10.0000","-11.4942","-2.5024"
"25670.9995","-10.0000","-11.4942","-2.7314"
"25850.9998","-10.0000","-11.4942","-3.0097"
"26031.0001","-10.0000","-11.4942","-3.9482"
"26211.0004","-10.0000","-11.4942","-5.3487"
"26391.0007","-10.0000","-11.4942","-6.7649"
"26570.9991","-10.0000","-11.4942","-8.0723"
"26750.9995","-10.0000","-11.4942","-9.3078"
"26930.9998","-10.0000","-11.4942","-10.8235"
"27111.0001","-10.0000","-11.4942","-12.5356"
"27291.0004","-10.0000","-11.4942","-14.3005"
"27471.0007","-10.0000","-11.4942","-16.0291"
"27650.9991","-10.0000","-11.4942","-17.8416"
"27830.9994","-10.0000","-11.4942","-19.5327"
"28010.9997","-10.0000","-11.4942","-20.9684"
"28191.0000","-10.0000","-11.4942","-22.4926"
"28371.0003","-10.0000","-11.4942","-23.8778"
"28551.0006","-10.0000","-11.4942","-25.2051"
"28731.0009","-10.0000","-11.4942","-26.5755"
"28910.9993","-10.0000","-11.4942","-27.8623"
"29090.9996","-10.0000","-11.4942","-28.9607"
"29270.9999","-10.0000","-11.4942","-29.9806"
"29451.0002","-10.0000","-11.4942","-31.1450"
"29631.0005","-10.0000","-11.4942","-31.6288"
"29694.9997","-10.0000","-11.4942","-29.1641"
"29813.9992","-10.0000","-11.4942","-26.9799"
"29993.9995","-10.0000","-11.4942","-26.1561"
"30173.9998","-10.0000","-11.4942","-26.1934"
"30354.0001","-10.0000","-11.4942","-26.3116"
"30534.0004","-10.0000","-11.4942","-26.4251"
"30714.0007","-10.0000","-11.4942","-26.7257"
"30893.9991","-10.0000","-11.4942","-27.1247"
"31073.9994","-10.0000","-11.4942","-27.3961"
"31253.9997","-10.0000","-11.4942","-27.5492"
"31434.0000","-10.0000","-11.4942","-27.6959"
"31614.0003","-10.0000","-11.4942","-27.9511"
"31794.0006","-10.0000","-11.4942","-28.2500"
"31974.0009","-10.0000","-11.4942","-28.5499"
"32153.9993","-10.0000","-11.4942","-28.9067"
"32333.9996","-10.0000","-11.4942","-29.2600"
"32513.9999","-10.0000","-11.4942","-29.5748"
"32694.0002","-10.0000","-11.4942","-29.8299"
"32874.0005","-10.0000","-11.4942","-30.0421"
"33054.0009","-10.0000","-11.4942","-30.2390"
"33234.0012","-10.0000","-11.4942","-30.3656"
"33414.0015","-10.0000","-11.4942","-30.4006"
"33594.0018","-10.0000","-11.4942","-30.5287"
"33773.9983","-10.0000","-11.4942","-30.6352"
"33953.9986","-10.0000","-11.4942","-30.7824"
"34133.9989","-10.0000","-11.4942","-30.9640"
"34313.9992","-10.0000","-11.4942","-31.0827"
"34493.9995","-10.0000","-11.4942","-31.0858"
"34673.9998","-10.0000","-11.4942","-31.1889"
"34854.0001","-10.0000","-11.4942","-31.4852"
"35034.0004","-10.0000","-11.4942","-31.7793"
"35214.0007","-10.0000","-11.4942","-32.1580"
"35394.0010","-10.0000","-11.4942","-32.5031"
"35574.0013","-10.0000","-11.4942","-32.9065"
"35754.0016","-10.0000","-11.4942","-33.1513"
"35933.9981","-10.0000","-11.4942","-33.4893"
"36113.9984","-10.0000","-11.4942","-33.5476"
"36293.9987","-10.0000","-11.4942","-33.0994"
"36473.9990","-10.0000","-11.4942","-32.1517"
"36653.9993","-10.0000","-11.4942","-31.4504"
"36833.9996","-10.0000","-11.4942","-30.9165"
"37013.9999","-10.0000","-11.4942","-30.6240"
"37194.0002","-10.0000","-11.4942","-30.4583"
"37374.0005","-10.0000","-11.4942","-30.2002"
"37554.0009","-10.0000","-11.4942","-29.5168"
"37734.0012","-10.0000","-11.4942","-28.6978"
"37914.0015","-10.0000","-11.4942","-28.0444"
"38094.0018","-10.0000","-11.4942","-27.4910"
"38273.9983","-10.0000","-11.4943","-26.9353"
"38453.9986","-10.0000","-11.4942","-26.4832"
"38633.9989","-10.0000","-11.4942","-26.1285"
"38813.9992","-10.0000","-11.4942","-25.9345"
"38993.9995","-10.0000","-11.4942","-25.7365"
"39173.9998","-10.0000","-11.4942","-25.5773"
"39354.0001","-10.0000","-11.4942","-25.4165"
"39534.0004","-10.0000","-11.4942","-25.2591"
"39714.0007","-10.0000","-11.4942","-24.9930"
"39894.0010","-10.0000","-11.4942","-24.6781"
"40074.0013","-10.0000","-11.4942","-24.3546"
"40254.0016","-10.0000","-11.4942","-24.0650"
"40433.9981","-10.0000","-11.4942","-23.8214"
"40613.9984","-10.0000","-11.4942","-23.6290"
"40793.9987","-10.0000","-11.4942","-23.5186"
"40973.9990","-10.0000","-11.4942","-23.3926"
"41153.9993","-10.0000","-11.4942","-23.1981"
"41333.9996","-10.0000","-11.4942","-22.9273"
"41513.9999","-10.0000","-11.4942","-22.5677"
"41694.0002","-10.0000","-11.4942","-22.1812"
"41874.0005","-10.0000","-11.4942","-21.8853"
"42054.0009","-10.0000","-11.4942","-21.6194"
"42234.0012","-10.0000","-11.4942","-21.2859"
"42414.0015","-10.0000","-11.4942","-20.7765"
"42594.0018","-10.0000","-11.4942","-20.3737"
"42773.9983","-10.0000","-11.4942","-19.9812"
"42953.9986","-10.0000","-11.4942","-19.3847"
"43133.9989","-10.0000","-11.4943","-18.6571"
"43313.9992","-10.0000","-11.4942","-17.8265"
"43493.9995","-10.0000","-11.4942","-16.7410"
"43673.9998","-10.0000","-11.4943","-15.5053"
"43854.0001","-10.0000","-11.4943","-14.4343"
"44034.0004","-10.0000","-11.4943","-13.6142"
"44214.0007","-10.0000","-11.4943","-12.8630"
"44394.0010","-10.0000","-11.4943","-12.1424"
"44574.0013","-10.0000","-11.4943","-11.4335"
"44754.0016","-10.0000","-11.4943","-10.6727"
"44933.9981","-10.0000","-11.4943","-9.8975"
"45113.9984","-10.0000","-11.4943","-9.1474"
"45293.9987","-10.0000","-11.4943","-8.4320"
"45473.9990","-10.0000","-11.4943","-7.8124"
"45653.9993","-10.0000","-11.4943","-7.2576"
"45833.9996","-10.0000","-11.4943","-6.7676"
"46013.9999","-10.0000","-11.4943","-6.3380"
"46194.0002","-10.0000","-11.4943","-5.9218"
"46374.0005","-10.0000","-11.4943","-5.5554"
"46554.0009","-10.0000","-11.4943","-5.1711"
"46734.0012","-10.0000","-11.4943","-4.8199"
"46914.0015","-10.0000","-11.4943","-4.4798"
"47094.0018","-10.0000","-11.4943","-4.2818"
"47273.9983","-10.0000","-11.4943","-4.0864"
"47453.9986","-10.0000","-11.4943","-3.8255"
"47633.9989","-10.0000","-11.4943","-3.5687"
"47813.9992","-10.0000","-11.4943","-3.2889"
"47993.9995","-10.0000","-11.4943","-2.9799"
"48173.9998","-10.0000","-11.4943","-2.7379"
"48354.0001","-10.0000","-11.4943","-2.5818"
"48534.0004","-10.0000","-11.4942","-2.5032"
"48714.0007","-10.0000","-11.4943","-2.5109"
"48894.0010","-10.0000","-11.4943","-2.5343"
"49074.0013","-10.0000","-11.4943","-2.5450"
"49254.0016","-10.0000","-11.4943","-2.5324"
"49433.9981","-10.0000","-11.4943","-2.4258"
"49613.9984","-10.0000","-11.4943","-1.9370"
"49793.9987","-10.0000","-11.4943","-1.6678"
"49973.9990","-10.0000","-11.4943","-1.6792"
"50153.9993","-10.0000","-11.4943","-1.7402"
"50333.9996","-10.0000","-11.4943","-1.7903"
"50513.9999","-10.0000","-11.4943","-1.8324"
"50694.0002","-10.0000","-11.4943","-1.9012"
"50874.0005","-10.0000","-11.4943","-1.9891"
"51054.0009","-10.0000","-11.4943","-2.2888"
"51234.0012","-10.0000","-11.4943","-2.5044"
"51414.0015","-10.0000","-11.4943","-2.4974"
"51594.0018","-10.0000","-11.4943","-2.4867"
"51773.9983","-10.0000","-11.4943","-2.4808"
"51916.0004","-9.9805","-11.4719","-2.4403"
"52096.0007","-9.9199","-11.4022","-2.3518"
"52276.0010","-9.8604","-11.3338","-2.2707"
"52456.0013","-9.8004","-11.2648","-2.1923"
"52636.0016","-9.7406","-11.1960","-2.1171"
"52816.0019","-9.6806","-11.1272","-2.0437"
"52995.9984","-9.6207","-11.0583","-1.9727"
"53175.9987","-9.5606","-10.9892","-1.9022"
"53355.9990","-9.5007","-10.9204","-1.8357"
"53535.9993","-9.4408","-10.8515","-1.7726"
"53715.9996","-9.3806","-10.7823","-1.7085"
"53895.9999","-9.3205","-10.7132","-1.6499"
"54076.0002","-9.2606","-10.6443","-1.5934"
"54256.0005","-9.2006","-10.5754","-1.5404"
"54436.0008","-9.1406","-10.5065","-1.4893"
"54616.0011","-9.0806","-10.4374","-1.4409"
"54796.0014","-9.0205","-10.3684","-1.3931"
"54976.0017","-8.9607","-10.2997","-1.3446"
"55155.9982","-8.9007","-10.2307","-1.2959"
"55335.9985","-8.8407","-10.1618","-1.2461"
"55515.9988","-8.7807","-10.0927","-1.1986"
"55695.9991","-8.7205","-10.0236","-1.1505"
"55875.9995","-8.6606","-9.9547","-1.1017"
"56055.9998","-8.6007","-9.8858","-1.0538"
"56236.0001","-8.5406","-9.8168","-1.0057"
"56416.0004","-8.4806","-9.7478","-0.9584"
"56596.0007","-8.4204","-9.6786","-0.9110"
"56776.0010","-8.3607","-9.6100","-0.8649"
"56956.0013","-8.3008","-9.5411","-0.8197"
"57136.0016","-8.2406","-9.4720","-0.7747"
"57316.0019","-8.1805","-9.4029","-0.7300"
"57495.9984","-8.1206","-9.3341","-0.6865"
"57675.9987","-8.0607","-9.2651","-0.6454"
"57855.9990","-8.0007","-9.1963","-0.6044"
"58035.9993","-7.9405","-9.1270","-0.5621"
"58215.9996","-7.8805","-9.0581","-0.5210"
"58395.9999","-7.8207","-8.9893","-0.5071"
"58576.0002","-7.7606","-8.9203","-0.9715"
"58756.0005","-7.7005","-8.8512","-1.4808"
"58936.0008","-7.6407","-8.7824","-1.8330"
"59116.0011","-7.5807","-8.7135","-1.9021"
"59296.0014","-7.5208","-8.6445","-1.8169"
"59476.0017","-7.4607","-8.5755","-1.7354"
"59655.9982","-7.4006","-8.5064","-1.6610"
"59835.9985","-7.3406","-8.4374","-1.5920"
"60015.9988","-7.2806","-8.3685","-1.5252"
"60195.9991","-7.2206","-8.2996","-1.4625"
"60375.9995","-7.1606","-8.2305","-1.4021"
"60555.9998","-7.1005","-8.1615","-1.3441"
"60736.0001","-7.0407","-8.0927","-1.2880"
"60916.0004","-6.9807","-8.0238","-1.2333"
"61096.0007","-6.9207","-7.9549","-1.1812"
"61276.0010","-6.8607","-7.8858","-1.1294"
"61456.0013","-6.8006","-7.8167","-1.0794"
"61636.0016","-6.7406","-7.7478","-1.0308"
"61816.0019","-6.6807","-7.6789","-0.9833"
"61995.9984","-6.6205","-7.6098","-0.9363"
"62175.9987","-6.5605","-7.5408","-0.8905"
"62355.9990","-6.5006","-7.4719","-0.8454"
"62535.9993","-6.4407","-7.4031","-0.8021"
"62715.9996","-6.3807","-7.3342","-0.7588"
"62895.9999","-6.3206","-7.2650","-0.7161"
"63076.0002","-6.2606","-7.1961","-0.6750"
"63256.0005","-6.2008","-7.1273","-0.6345"
"63436.0008","-6.1406","-7.0581","-0.5938"
"63616.0011","-6.0806","-6.9891","-0.5542"
"63796.0014","-6.0206","-6.9202","-0.5266"
"63976.0017","-5.9606","-6.8512","-0.8567"
"64155.9982","-5.9007","-6.7824","-1.0399"
"64335.9985","-5.8405","-6.7132","-1.1067"
"64515.9988","-5.7806","-6.6444","-1.0828"
"64695.9991","-5.7207","-6.5755","-1.0370"
"64875.9995","-5.6606","-6.5065","-0.9853"
"65055.9998","-5.6007","-6.4376","-0.9337"
"65236.0001","-5.5407","-6.3686","-0.8852"
"65416.0004","-5.4806","-6.2995","-0.8380"
"65596.0007","-5.4206","-6.2306","-0.7919"
"65776.0010","-5.3606","-6.1616","-0.7473"
"65956.0013","-5.3006","-6.0927","-0.7042"
"66136.0016","-5.2406","-6.0237","-0.6615"
"66316.0019","-5.1805","-5.9546","-0.6204"
"66496.0022","-5.1206","-5.8857","-0.5801"
"66676.0025","-5.0608","-5.8170","-0.5418"
"66856.0028","-5.0006","-5.7478","-0.5055"
"66980.0034","-4.9874","-5.7327","-0.5095"
"67160.0037","-4.9888","-5.7343","-0.5499"
"67339.9963","-4.9902","-5.7359","-0.7852"
"67519.9966","-4.9912","-5.7370","-0.8511"
"67699.9969","-4.9918","-5.7377","-0.8808"
"67879.9973","-4.9921","-5.7381","-0.9241"
"68059.9976","-4.9923","-5.7383","-0.9788"
"68239.9979","-4.9924","-5.7384","-1.0159"
"68419.9982","-4.9925","-5.7385","-1.0381"
"68599.9985","-4.9925","-5.7385","-1.0484"
"68779.9988","-4.9925","-5.7385","-1.0415"
"68959.9991","-4.9925","-5.7385","-1.0333"
"69139.9994","-4.9925","-5.7385","-1.0294"
"69319.9997","-4.9925","-5.7385","-1.0353"
"69500.0000","-4.9925","-5.7385","-1.0526"
"69680.0003","-4.9925","-5.7385","-1.0535"
"69860.0006","-4.9925","-5.7385","-1.0533"
"70040.0009","-4.9925","-5.7385","-1.0571"
"70220.0012","-4.9925","-5.7385","-1.1438"
"70400.0015","-4.9925","-5.7385","-1.9022"
"70580.0018","-4.9925","-5.7385","-3.2928"
"70760.0021","-4.9925","-5.7385","-5.2880"
"70920.9976","-4.9925","-5.7385","-7.6058"
"71065.0024","-4.9925","-5.7385","-9.9419"
"71216.0034","-4.9925","-5.7385","-12.2514"
"71391.9983","-4.9925","-5.7385","-14.5298"
"71571.9986","-4.9925","-5.7385","-16.7473"
"71751.9989","-4.9925","-5.7385","-18.8648"
"71931.9992","-4.9925","-5.7385","-20.7682"
"72111.9995","-4.9925","-5.7385","-22.4260"
"72291.9998","-4.9925","-5.7385","-23.4150"
"72472.0001","-4.9925","-5.7385","-23.6727"
"72652.0004","-4.9925","-5.7385","-23.7708"
"72832.0007","-4.9925","-5.7385","-23.9307"
"73012.0010","-4.9925","-5.7385","-24.2417"
"73192.0013","-4.9925","-5.7385","-24.5897"
"73372.0016","-4.9925","-5.7385","-24.7928"
"73552.0020","-4.9925","-5.7385","-25.1062"
"73732.0023","-4.9925","-5.7385","-25.5567"
"73912.0026","-4.9925","-5.7385","-25.9261"
"74092.0029","-4.9925","-5.7385","-26.1581"
"74272.0032","-4.9925","-5.7385","-26.4726"
"74452.0035","-4.9925","-5.7385","-26.8450"
"74632.0038","-4.9925","-5.7385","-27.3795"
"74811.9965","-4.9925","-5.7385","-27.8561"
"74991.9968","-4.9925","-5.7385","-28.3214"
"75171.9971","-4.9925","-5.7385","-28.6222"
"75351.9974","-4.9925","-5.7385","-28.8219"
"75531.9977","-4.9925","-5.7385","-29.0918"
"75711.9980","-4.9925","-5.7385","-29.3675"
"75891.9983","-4.9925","-5.7385","-29.6769"
"76071.9986","-4.9925","-5.7385","-29.9502"
"76251.9989","-4.9925","-5.7385","-30.2147"
"76431.9992","-4.9925","-5.7385","-30.3695"
"76611.9995","-4.9925","-5.7385","-30.4042"
"76791.9998","-4.9925","-5.7385","-30.4742"
"76972.0001","-4.9925","-5.7385","-30.4852"
"77152.0004","-4.9925","-5.7385","-30.4601"
"77332.0007","-4.9925","-5.7385","-30.2302"
"77512.0010","-4.9925","-5.7385","-29.9818"
"77692.0013","-4.9925","-5.7385","-29.7746"
"77872.0016","-4.9925","-5.7385","-29.5958"
"78052.0020","-4.9925","-5.7385","-29.4364"
"78232.0023","-4.9925","-5.7385","-29.2913"
"78412.0026","-4.9925","-5.7385","-29.1582"
"78592.0029","-4.9925","-5.7385","-29.0351"
"78772.0032","-4.9925","-5.7385","-28.9222"
"78952.0035","-4.9925","-5.7385","-28.8130"
"79132.0038","-4.9925","-5.7385","-28.7107"
"79311.9965","-4.9925","-5.7385","-28.6047"
"79491.9968","-4.9925","-5.7385","-28.2417"
"79671.9971","-4.9925","-5.7385","-27.7510"
"79851.9974","-4.9925","-5.7385","-27.3350"
"80031.9977","-4.9925","-5.7385","-27.0132"
"80211.9980","-4.9925","-5.7385","-26.7258"
"80391.9983","-4.9925","-5.7385","-26.4800"
"80571.9986","-4.9925","-5.7385","-26.3445"
"80751.9989","-4.9925","-5.7385","-26.2680"
"80931.9992","-4.9925","-5.7385","-26.0633"
"81111.9995","-4.9925","-5.7385","-25.7125"
"81291.9998","-4.9925","-5.7385","-25.4572"
"81472.0001","-4.9925","-5.7385","-25.3292"
"81652.0004","-4.9925","-5.7385","-25.3051"
"81832.0007","-4.9925","-5.7385","-25.2066"
"82012.0010","-4.9925","-5.7385","-24.7811"
"82192.0013","-4.9925","-5.7385","-24.5081"
"82372.0016","-4.9925","-5.7385","-24.3009"
"82552.0020","-4.9925","-5.7385","-24.0395"
"82732.0023","-4.9925","-5.7385","-23.7591"
"82912.0026","-4.9925","-5.7385","-23.5533"
"83092.0029","-4.9925","-5.7385","-23.3290"
"83272.0032","-4.9925","-5.7385","-23.0320"
"83452.0035","-4.9925","-5.7385","-22.7247"
"83632.0038","-4.9925","-5.7385","-22.4896"
"83811.9965","-4.9925","-5.7385","-22.3027"
"83991.9968","-4.9925","-5.7385","-22.0565"
"84171.9971","-4.9925","-5.7385","-21.7249"
"84351.9974","-4.9925","-5.7385","-21.3930"
"84531.9977","-4.9925","-5.7385","-20.9963"
"84711.9980","-4.9925","-5.7385","-20.5570"
"84891.9983","-4.9925","-5.7385","-20.1294"
"85071.9986","-4.9925","-5.7385","-19.7150"
"85251.9989","-4.9925","-5.7385","-19.2931"
"85431.9992","-4.9925","-5.7385","-18.7875"
"85611.9995","-4.9925","-5.7385","-18.2014"
"85791.9998","-4.9925","-5.7385","-17.6919"
"85972.0001","-4.9925","-5.7385","-17.2881"
"86152.0004","-4.9925","-5.7385","-16.9617"
"86332.0007","-4.9925","-5.7385","-16.5759"
"86512.0010","-4.9925","-5.7385","-16.1134"
"86692.0013","-4.9925","-5.7385","-15.6159"
"86872.0016","-4.9925","-5.7385","-15.1580"
"87052.0020","-4.9925","-5.7385","-14.6841"
"87232.0023","-4.9925","-5.7385","-14.2299"
"87412.0026","-4.9925","-5.7385","-13.7520"
"87592.0029","-4.9925","-5.7385","-13.3424"
"87772.0032","-4.9925","-5.7385","-12.8921"
"87952.0035","-4.9925","-5.7385","-12.5398"
"88132.0038","-4.9925","-5.7385","-12.1023"
"88311.9965","-4.9925","-5.7385","-11.4397"
"88491.9968","-4.9925","-5.7385","-10.5398"
"88671.9971","-4.9925","-5.7385","-9.5604"
"88851.9974","-4.9925","-5.7385","-8.4081"
"89031.9977","-4.9925","-5.7385","-7.4059"
"89211.9980","-4.9925","-5.7385","-6.6815"
"89391.9983","-4.9925","-5.7385","-6.0371"
"89571.9986","-4.9925","-5.7385","-5.2478"
"89751.9989","-4.9925","-5.7385","-4.4572"
"89931.9992","-4.9925","-5.7385","-3.7398"
"90111.9995","-4.9925","-5.7385","-3.2228"
"90291.9998","-4.9925","-5.7385","-2.7954"
"90472.0001","-4.9925","-5.7385","-2.5003"
"90652.0004","-4.9925","-5.7385","-2.1238"
"90832.0007","-4.9925","-5.7385","-1.8532"
"91012.0010","-4.9925","-5.7385","-1.8610"
"91192.0013","-4.9925","-5.7385","-1.7709"
"91372.0016","-4.9925","-5.7385","-1.6027"
"91552.0020","-4.9925","-5.7385","-1.3288"
"91732.0023","-4.9925","-5.7385","-1.2154"
"91912.0026","-4.9925","-5.7385","-1.2622"
"92092.0029","-4.9925","-5.7385","-1.2968"
"92272.0032","-4.9925","-5.7385","-1.3243"
"92452.0035","-4.9925","-5.7385","-1.3451"
"92632.0038","-4.9925","-5.7385","-1.3622"
"92811.9965","-4.9925","-5.7385","-1.3772"
"92991.9968","-4.9925","-5.7385","-1.3893"
"93171.9971","-4.9925","-5.7385","-1.3996"
"93351.9974","-4.9925","-5.7385","-1.4083"
"93531.9977","-4.9925","-5.7385","-1.4155"
"93711.9980","-4.9925","-5.7385","-1.4213"
"93891.9983","-4.9925","-5.7385","-1.4263"
"94071.9986","-4.9925","-5.7385","-1.4298"
"94251.9989","-4.9925","-5.7385","-1.4334"
"94431.9992","-4.9925","-5.7385","-1.4360"
"94611.9995","-4.9925","-5.7385","-1.4378"
"94791.9998","-4.9925","-5.7385","-1.4393"
"94972.0001","-4.9925","-5.7385","-1.4403"
"95152.0004","-4.9925","-5.7385","-1.4406"
"95332.0007","-4.9925","-5.7385","-1.4411"
"95512.0010","-4.9925","-5.7385","-1.4405"
"95692.0013","-4.9925","-5.7385","-1.4406"
"95872.0016","-4.9925","-5.7385","-1.4397"
"96052.0020","-4.9925","-5.7385","-1.4384"
"96232.0023","-4.9925","-5.7385","-1.4373"
"96412.0026","-4.9925","-5.7385","-1.4360"
"96592.0029","-4.9925","-5.7385","-1.4349"
"96772.0032","-4.9925","-5.7385","-1.4326"
"96904.9988","-4.9924","-5.7384","-1.4315"
"97084.9991","-4.9424","-5.6809","-1.3792"
"97264.9994","-4.8827","-5.6123","-1.3232"
"97444.9997","-4.8230","-5.5437","-1.2713"
"97625.0000","-4.7629","-5.4747","-1.2212"
"97805.0003","-4.7028","-5.4055","-1.1726"
"97985.0006","-4.6429","-5.3366","-1.1269"
"98165.0009","-4.5830","-5.2678","-1.0816"
"98345.0012","-4.5229","-5.1988","-1.0375"
"98525.0015","-4.4629","-5.1298","-0.9952"
"98705.0018","-4.4030","-5.0610","-0.9541"
"98885.0021","-4.3431","-4.9920","-0.9124"
"99065.0024","-4.2832","-4.9232","-0.8716"
"99245.0027","-4.2230","-4.8540","-0.8313"
"99425.0031","-4.1629","-4.7849","-0.7909"
"99605.0034","-4.1030","-4.7161","-0.7508"
"99785.0037","-4.0430","-4.6471","-0.7112"
"99964.9963","-3.9829","-4.5781","-0.6724"
"100144.9966","-3.9230","-4.5092","-0.6336"
"100324.9969","-3.8629","-4.4401","-0.5958"
"100504.9973","-3.8030","-4.3712","-0.5587"
"100684.9976","-3.7430","-4.3023","-0.5213"
"100864.9979","-3.6832","-4.2335","-0.4861"
"101044.9982","-3.6231","-4.1645","-0.4490"
"101224.9985","-3.5629","-4.0952","-0.4124"
"101404.9988","-3.5030","-4.0264","-0.3766"
"101584.9991","-3.4429","-3.9574","-0.3393"
"101764.9994","-3.3829","-3.8884","-0.3021"
"101944.9997","-3.3229","-3.8194","-0.2649"
"102125.0000","-3.2629","-3.7505","-0.2278"
"102305.0003","-3.2030","-3.6816","-0.1911"
"102485.0006","-3.1431","-3.6128","-0.1550"
"102665.0009","-3.0831","-3.5437","-0.1189"
"102845.0012","-3.0230","-3.4748","-0.0825"
"103025.0015","-2.9631","-3.4059","-0.0472"
"103205.0018","-2.9030","-3.3368","-0.0114"
"103385.0021","-2.8429","-3.2677","0.0240"
"103565.0024","-2.7830","-3.1988","0.0591"
"103745.0027","-2.7229","-3.1298","0.0947"
"103925.0031","-2.6630","-3.0609","0.1295"
"104105.0034","-2.6029","-2.9918","0.1640"
"104285.0037","-2.5429","-2.9229","0.1981"
"104464.9963","-2.4831","-2.8541","0.2327"
"104644.9966","-2.4231","-2.7851","0.2667"
"104824.9969","-2.3630","-2.7161","0.3007"
"105004.9973","-2.3030","-2.6471","0.3346"
"105184.9976","-2.2430","-2.5782","0.3677"
"105364.9979","-2.1829","-2.5091","0.4017"
"105544.9982","-2.1228","-2.4401","0.4346"
"105724.9985","-2.0630","-2.3712","0.4674"
"105904.9988","-2.0031","-2.3024","0.4992"
"106084.9991","-1.9429","-2.2333","0.5317"
"106264.9994","-1.8830","-2.1643","0.5643"
"106444.9997","-1.8231","-2.0955","0.5962"
"106625.0000","-1.7630","-2.0265","0.6281"
"106805.0003","-1.7030","-1.9575","0.6601"
"106985.0006","-1.6430","-1.8885","0.6919"
"107165.0009","-1.5830","-1.8195","0.7224"
"107345.0012","-1.5230","-1.7506","0.7535"
"107525.0015","-1.4629","-1.6815","0.7853"
"107705.0018","-1.4030","-1.6126","0.8170"
"107885.0021","-1.3431","-1.5437","0.8481"
"108065.0024","-1.2829","-1.4746","0.8791"
"108245.0027","-1.2230","-1.4057","0.9104"
"108425.0031","-1.1631","-1.3369","0.9414"
"108605.0034","-1.1031","-1.2679","0.9720"
"108785.0037","-1.0431","-1.1990","1.0021"
"108964.9963","-0.9829","-1.1298","1.0306"
"109144.9966","-0.9230","-1.0609","1.0576"
"109324.9969","-0.8630","-0.9920","1.0836"
"109504.9973","-0.8028","-0.9228","1.1057"
"109684.9976","-0.7429","-0.8539","1.0332"
"109864.9979","-0.6830","-0.7851","0.4677"
"110044.9982","-0.6230","-0.7161","0.0489"
"110224.9985","-0.5631","-0.6472","-0.0907"
"110404.9988","-0.5030","-0.5781","-0.0614"
"110584.9991","-0.4431","-0.5093","-0.0088"
"110764.9994","-0.3832","-0.4404","0.0430"
"110944.9997","-0.3230","-0.3712","0.0925"
"111125.0000","-0.2629","-0.3022","0.1387"
"111305.0003","-0.2030","-0.2333","0.1830"
"111485.0006","-0.1430","-0.1643","0.2255"
"111665.0009","-0.0830","-0.0954","0.2674"
"111845.0012","-0.0230","-0.0264","0.3079"
"111978.9963","0.0194","0.0223","0.3342"
"112158.9966","0.0195","0.0224","0.3304"
"112338.9969","0.0180","0.0207","0.3277"
"112518.9972","0.0168","0.0193","0.3244"
"112698.9975","0.0160","0.0184","0.3227"
"112878.9978","0.0156","0.0179","0.3213"
"113058.9981","0.0154","0.0177","0.3201"
"113238.9984","0.0152","0.0175","0.3200"
"113418.9987","0.0152","0.0175","0.3197"
"113598.9990","0.0152","0.0174","0.3186"
"113778.9993","0.0151","0.0174","0.3176"
"113958.9996","0.0151","0.0174","0.3174"
"114138.9999","0.0151","0.0174","0.3154"
"114319.0002","0.0151","0.0174","0.3116"
"114499.0005","0.0151","0.0174","0.2974"
"114679.0009","0.0151","0.0174","0.0518"
"114859.0012","0.0151","0.0174","0.0308"
"115039.0015","0.0151","0.0174","0.0358"
"115219.0018","0.0151","0.0174","0.0405"
"115399.0021","0.0152","0.0174","0.0439"
"115579.0024","0.0152","0.0174","0.0466"
"115759.0027","0.0152","0.0174","0.0491"
"115939.0030","0.0152","0.0174","0.0503"
"116119.0033","0.0152","0.0174","0.0517"
"116299.0036","0.0152","0.0174","0.0521"
"116478.9963","0.0152","0.0174","0.0523"
"116658.9966","0.0152","0.0174","0.0511"
"116838.9969","0.0152","0.0174","0.0470"
"117018.9972","0.0152","0.0174","0.0284"
"117198.9975","0.0152","0.0174","-0.4302"
"117378.9978","0.0152","0.0174","-1.4915"
"117557.9987","0.0152","0.0174","-3.5499"
"117713.9969","0.0152","0.0174","-5.8698"
"117847.0001","0.0152","0.0174","-8.1798"
"117978.9963","0.0152","0.0174","-10.4916"
"118113.9984","0.0152","0.0174","-12.7736"
"118250.9995","0.0152","0.0174","-15.0662"
"118391.9983","0.0152","0.0174","-17.3969"
"118539.0015","0.0152","0.0174","-19.7251"
"118695.9991","0.0152","0.0174","-22.0090"
"118875.9995","0.0152","0.0174","-23.7888"
"119055.9998","0.0152","0.0174","-24.7879"
"119236.0001","0.0152","0.0174","-25.4086"
"119416.0004","0.0152","0.0174","-26.1125"
"119596.0007","0.0152","0.0174","-26.8708"
"119776.0010","0.0152","0.0174","-27.6000"
"119956.0013","0.0152","0.0174","-28.1988"
"120136.0016","0.0152","0.0174","-28.6833"
"120316.0019","0.0152","0.0174","-29.0905"
"120496.0022","0.0152","0.0174","-29.5370"
"120676.0025","0.0152","0.0174","-29.7491"
"120856.0028","0.0152","0.0174","-29.4320"
"121036.0031","0.0152","0.0174","-29.1414"
"121216.0034","0.0152","0.0174","-28.9144"
"121396.0037","0.0152","0.0174","-28.7237"
"121575.9964","0.0152","0.0174","-28.5590"
"121755.9967","0.0152","0.0174","-28.4130"
"121935.9970","0.0152","0.0174","-28.2827"
"122115.9973","0.0152","0.0174","-28.1634"
"122295.9976","0.0152","0.0174","-28.0543"
"122475.9979","0.0152","0.0174","-27.9528"
"122655.9982","0.0152","0.0174","-27.8292"
"122835.9985","0.0152","0.0174","-27.3068"
"123015.9988","0.0152","0.0174","-26.4710"
"123195.9991","0.0152","0.0174","-25.6612"
"123375.9995","0.0152","0.0174","-24.9437"
"123555.9998","0.0152","0.0174","-24.1716"
"123736.0001","0.0152","0.0174","-23.3330"
"123916.0004","0.0152","0.0174","-22.4240"
"124096.0007","0.0152","0.0174","-21.4906"
"124276.0010","0.0152","0.0174","-20.5890"
"124456.0013","0.0152","0.0174","-19.7366"
"124636.0016","0.0152","0.0174","-18.8847"
"124816.0019","0.0152","0.0174","-18.0309"
"124996.0022","0.0152","0.0174","-17.0926"
"125176.0025","0.0152","0.0174","-15.9995"
"125356.0028","0.0152","0.0174","-14.8589"
"125536.0031","0.0152","0.0174","-13.6007"
"125716.0034","0.0152","0.0174","-12.3719"
"125896.0037","0.0152","0.0174","-11.1494"
"126075.9964","0.0152","0.0174","-9.8006"
"126255.9967","0.0152","0.0174","-8.5316"
"126435.9970","0.0152","0.0174","-7.3477"
"126615.9973","0.0152","0.0174","-6.2609"
"126795.9976","0.0152","0.0174","-5.2359"
"126975.9979","0.0152","0.0174","-4.6663"
"127155.9982","0.0152","0.0174","-4.1861"
"127335.9985","0.0152","0.0174","-3.6327"
"127515.9988","0.0152","0.0174","-3.4215"
"127695.9991","0.0152","0.0174","-3.0940"
"127875.9995","0.0152","0.0174","-2.9978"
"128055.9998","0.0152","0.0174","-3.0779"
"128235.9924","0.0152","0.0174","-3.1459"
"128416.0004","0.0152","0.0174","-3.1990"
"128595.9930","0.0152","0.0174","-3.2398"
"128776.0010","0.0152","0.0174","-3.2689"
"128955.9937","0.0152","0.0174","-2.4606"
"129136.0016","0.0152","0.0174","-1.6088"
"129315.9943","0.0152","0.0174","-1.2383"
"129496.0022","0.0152","0.0174","-1.0322"
"129675.9949","0.0152","0.0174","-0.9555"
"129856.0028","0.0152","0.0174","-0.6204"
"130035.9955","0.0152","0.0174","-0.5944"
"130216.0034","0.0152","0.0174","-0.6314"
"130395.9961","0.0152","0.0174","-0.6575"
"130576.0040","0.0152","0.0174","-0.6781"
"130755.9967","0.0152","0.0174","-0.6953"
"130936.0046","0.0152","0.0174","-0.7100"
"131115.9973","0.0152","0.0174","-0.7128"
"131296.0052","0.0152","0.0174","-0.6180"
"131475.9979","0.0152","0.0174","-0.3262"
"131656.0059","0.0152","0.0174","-0.1182"
"131835.9985","0.0152","0.0174","-0.0365"
"132016.0065","0.0152","0.0174","-0.0074"
"132195.9991","0.0152","0.0174","0.0036"
"132376.0071","0.0152","0.0174","0.0087"
"132555.9998","0.0152","0.0174","0.0117"
"132735.9924","0.0152","0.0174","0.0132"
"132916.0004","0.0152","0.0174","0.0145"
"133095.9930","0.0152","0.0174","0.0154"
"133276.0010","0.0152","0.0174","0.0160"
"133455.9937","0.0152","0.0174","0.0168"
"133636.0016","0.0152","0.0174","0.0175"
"133815.9943","0.0152","0.0174","0.0173"
"133996.0022","0.0152","0.0174","0.0178"
"134175.9949","0.0152","0.0174","0.0170"
"134356.0028","0.0152","0.0174","0.0172"
"134535.9955","0.0152","0.0174","0.0159"
"134716.0034","0.0152","0.0174","0.0138"
"134895.9961","0.0152","0.0174","0.0121"
"135076.0040","0.0152","0.0174","0.0081"
"135255.9967","0.0152","0.0174","0.0065"
"135436.0046","0.0152","0.0174","0.0039"
"135615.9973","0.0152","0.0174","0.0011"
"135796.0052","0.0152","0.0174","-0.0009"
"135975.9979","0.0152","0.0174","-0.0034"
"136156.0059","0.0152","0.0174","-0.0057"
"136335.9985","0.0152","0.0174","-0.0063"
"136516.0065","0.0152","0.0174","-0.0067"
"136695.9991","0.0152","0.0174","-0.0077"
"136876.0071","0.0152","0.0174","-0.0092"
"137055.9998","0.0152","0.0174","-0.0101"
"137235.9924","0.0152","0.0174","-0.0102"
"137416.0004","0.0152","0.0174","-0.0108"
"137595.9930","0.0152","0.0174","-0.0109"
"137776.0010","0.0152","0.0174","-0.0116"
"137955.9937","0.0152","0.0174","-0.0121"
"138136.0016","0.0152","0.0174","-0.0121"
"138315.9943","0.0152","0.0174","-0.0126"
"138496.0022","0.0152","0.0174","-0.0130"
"138675.9949","0.0152","0.0174","-0.0132"
"138856.0028","0.0152","0.0174","-0.0140"
"139035.9955","0.0152","0.0174","-0.0148"
"139216.0034","0.0152","0.0174","-0.0149"
"139395.9961","0.0152","0.0174","-0.0147"
"139576.0040","0.0152","0.0174","-0.0151"
"139755.9967","0.0152","0.0174","-0.0153"
"139936.0046","0.0152","0.0174","-0.0158"
"140115.9973","0.0152","0.0174","-0.0161"
"140296.0052","0.0152","0.0174","-0.0163"
"140475.9979","0.0152","0.0174","-0.0166"
"140656.0059","0.0152","0.0174","-0.0167"
"140835.9985","0.0152","0.0174","-0.0170"
"141016.0065","0.0152","0.0174","-0.0164"
"141195.9991","0.0152","0.0174","-0.0167"
"141376.0071","0.0152","0.0174","-0.0172"
"141555.9998","0.0152","0.0174","-0.0166"
"141735.9924","0.0152","0.0174","-0.0168"
"141916.0004","0.0152","0.0174","-0.0170"
"142057.0068","0.0314","0.0361","-0.0031"
"142236.9995","0.0916","0.1053","0.0400"
"142417.0074","0.1515","0.1741","0.0800"
"142597.0001","0.2112","0.2428","0.1182"
"142776.9928","0.2712","0.3117","0.1545"
"142957.0007","0.3314","0.3809","0.1909"
"143136.9934","0.3913","0.4498","0.2261"
"143317.0013","0.4513","0.5188","0.2615"
"143496.9940","0.5113","0.5877","0.2961"
"143677.0020","0.5712","0.6566","0.3305"
"143856.9946","0.6313","0.7256","0.3655"
"144037.0026","0.6913","0.7946","0.4000"
"144216.9952","0.7511","0.8634","0.4332"
"144397.0032","0.8112","0.9324","0.4670"
"144576.9958","0.8712","1.0014","0.4998"
"144757.0038","0.9311","1.0703","0.5324"
"144936.9965","0.9913","1.1394","0.5650"
"145117.0044","1.0514","1.2085","0.5976"
"145296.9971","1.1113","1.2774","0.6297"
"145477.0050","1.1712","1.3462","0.6620"
"145656.9977","1.2312","1.4152","0.6940"
"145837.0056","1.2913","1.4843","0.7257"
"146016.9983","1.3513","1.5532","0.7572"
"146197.0062","1.4111","1.6220","0.7885"
"146376.9989","1.4712","1.6910","0.8200"
"146557.0068","1.5312","1.7600","0.8510"
"146736.9995","1.5912","1.8289","0.8761"
"146917.0074","1.6512","1.8979","0.8919"
"147097.0001","1.7112","1.9668","0.9049"
"147276.9928","1.7714","2.0361","0.9094"
"147457.0007","1.8313","2.1049","0.8641"
"147636.9934","1.8913","2.1739","0.5194"
"147817.0013","1.9514","2.2430","0.0578"
"147996.9940","2.0113","2.3119","-0.3633"
"148177.0020","2.0712","2.3807","-0.6127"
"148356.9946","2.1311","2.4496","-0.6547"
"148537.0026","2.1911","2.5186","-0.6007"
"148716.9952","2.2513","2.5877","-0.5438"
"148897.0032","2.3113","2.6567","-0.4906"
"149076.9958","2.3712","2.7255","-0.4407"
"149257.0038","2.4314","2.7947","-0.3942"
"149436.9965","2.4913","2.8636","-0.3499"
"149617.0044","2.5512","2.9324","-0.3062"
"149796.9971","2.6113","3.0015","-0.2608"
"149977.0050","2.6712","3.0704","-0.2176"
"150156.9977","2.7313","3.1394","-0.1752"
"150337.0056","2.7911","3.2082","-0.1334"
"150516.9983","2.8510","3.2771","-0.0924"
"150697.0062","2.9113","3.3463","-0.0509"
"150876.9989","2.9714","3.4153","-0.0113"
"151057.0068","3.0313","3.4843","0.0275"
"151236.9995","3.0912","3.5531","0.0604"
"151417.0074","3.1513","3.6222","0.0746"
"151597.0001","3.2113","3.6911","0.0930"
"151776.9928","3.2713","3.7601","0.1291"
"151957.0007","3.3312","3.8289","0.1674"
"152136.9934","3.3912","3.8979","0.2049"
"152317.0013","3.4512","3.9669","0.2422"
"152496.9940","3.5112","4.0359","0.2789"
"152677.0020","3.5714","4.1050","0.3152"
"152856.9946","3.6313","4.1739","0.3509"
"153037.0026","3.6913","4.2428","0.3869"
"153216.9952","3.7513","4.3118","0.4218"
"153397.0032","3.8112","4.3807","0.4544"
"153576.9958","3.8714","4.4499","0.4827"
"153757.0038","3.9313","4.5187","0.5022"
"153936.9965","3.9910","4.5874","0.4378"
"154117.0044","4.0513","4.6567","0.1253"
"154296.9971","4.1113","4.7256","0.0958"
"154477.0050","4.1712","4.7944","0.1371"
"154656.9977","4.2312","4.8634","0.1830"
"154837.0056","4.2912","4.9325","0.2282"
"155016.9983","4.3513","5.0015","0.2714"
"155197.0062","4.4113","5.0704","0.3126"
"155376.9989","4.4711","5.1392","0.3531"
"155557.0068","4.5313","5.2084","0.3921"
"155736.9995","4.5913","5.2774","0.4303"
"155917.0074","4.6512","5.3462","0.4674"
"156097.0001","4.7112","5.4152","0.5044"
"156276.9928","4.7711","5.4840","0.5407"
"156457.0007","4.8312","5.5531","0.5763"
"156636.9934","4.8913","5.6222","0.6118"
"156817.0013","4.9513","5.6911","0.6467"
"156996.9940","5.0114","5.7602","0.6815"
"157130.9967","5.0279","5.7792","0.6868"
"157311.0046","5.0266","5.7776","0.6828"
"157490.9973","5.0251","5.7760","0.6799"
"157671.0052","5.0241","5.7748","0.6777"
"157850.9979","5.0234","5.7741","0.6762"
"158031.0059","5.0231","5.7736","0.6759"
"158210.9985","5.0229","5.7734","0.6746"
"158391.0065","5.0228","5.7733","0.6732"
"158570.9991","5.0227","5.7733","0.6720"
"158751.0071","5.0227","5.7732","0.6714"
"158930.9998","5.0227","5.7732","0.6704"
"159110.9924","5.0227","5.7732","0.6694"
"159291.0004","5.0227","5.7732","0.6638"
"159470.9930","5.0227","5.7732","0.1977"
"159651.0010","5.0227","5.7732","-0.7753"
"159830.9937","5.0227","5.7732","-2.0220"
"160003.9978","5.0227","5.7732","-4.0855"
"160177.9938","5.0227","5.7732","-6.3740"
"160335.9985","5.0227","5.7732","-8.6873"
"160492.0044","5.0227","5.7733","-10.9976"
"160643.0054","5.0227","5.7733","-13.3109"
"160817.0013","5.0227","5.7733","-15.5710"
"160996.9940","5.0227","5.7733","-17.6579"
"161177.0020","5.0227","5.7733","-19.1757"
"161356.9946","5.0227","5.7733","-20.4145"
"161537.0026","5.0227","5.7733","-21.5416"
"161716.9952","5.0227","5.7733","-22.5882"
"161897.0032","5.0227","5.7733","-23.2151"
"162076.9958","5.0227","5.7733","-23.7377"
"162257.0038","5.0227","5.7733","-24.3548"
"162436.9965","5.0227","5.7733","-24.9814"
"162617.0044","5.0227","5.7733","-25.5526"
"162796.9971","5.0227","5.7733","-26.0031"
"162977.0050","5.0227","5.7733","-26.4224"
"163156.9977","5.0227","5.7733","-26.8654"
"163337.0056","5.0227","5.7733","-27.3121"
"163516.9983","5.0227","5.7733","-27.7617"
"163697.0062","5.0227","5.7733","-28.1935"
"163876.9989","5.0227","5.7733","-28.5818"
"164057.0068","5.0227","5.7733","-29.0053"
"164236.9995","5.0227","5.7733","-29.3338"
"164417.0074","5.0227","5.7733","-29.3102"
"164597.0001","5.0227","5.7733","-29.1302"
"164776.9928","5.0227","5.7733","-28.8854"
"164957.0007","5.0227","5.7733","-28.6835"
"165136.9934","5.0227","5.7733","-28.5132"
"165317.0013","5.0227","5.7733","-28.3628"
"165496.9940","5.0227","5.7733","-28.2254"
"165677.0020","5.0227","5.7733","-28.1015"
"165856.9946","5.0227","5.7733","-27.9865"
"166037.0026","5.0227","5.7733","-27.7169"
"166216.9952","5.0227","5.7733","-27.1591"
"166397.0032","5.0227","5.7733","-26.5362"
"166576.9958","5.0227","5.7733","-26.0185"
"166757.0038","5.0227","5.7733","-25.5826"
"166936.9965","5.0227","5.7733","-25.1398"
"167117.0044","5.0227","5.7733","-24.6356"
"167296.9971","5.0227","5.7733","-24.1321"
"167477.0050","5.0227","5.7733","-23.6873"
"167656.9977","5.0227","5.7733","-23.2851"
"167837.0056","5.0227","5.7733","-22.8521"
"168016.9983","5.0227","5.7733","-22.3809"
"168197.0062","5.0227","5.7733","-21.9615"
"168376.9989","5.0227","5.7733","-21.5813"
"168557.0068","5.0227","5.7733","-21.2408"
"168736.9995","5.0227","5.7733","-20.9053"
"168917.0074","5.0227","5.7733","-20.5456"
"169097.0001","5.0227","5.7733","-20.2528"
"169276.9928","5.0227","5.7733","-19.9446"
"169457.0007","5.0227","5.7733","-19.6478"
"169636.9934","5.0227","5.7733","-19.3372"
"169817.0013","5.0227","5.7733","-19.0507"
"169996.9940","5.0227","5.7733","-18.7487"
"170177.0020","5.0227","5.7733","-18.3922"
"170356.9946","5.0227","5.7733","-17.9875"
"170537.0026","5.0227","5.7733","-17.5870"
"170716.9952","5.0227","5.7733","-17.1763"
"170897.0032","5.0227","5.7733","-16.8022"
"171076.9958","5.0227","5.7733","-16.4295"
"171257.0038","5.0227","5.7733","-16.0171"
"171436.9965","5.0227","5.7733","-15.6464"
"171617.0044","5.0227","5.7733","-15.1812"
"171796.9971","5.0227","5.7733","-14.7165"
"171977.0050","5.0227","5.7733","-14.3244"
"172156.9977","5.0227","5.7733","-13.5984"
"172337.0056","5.0227","5.7733","-12.6331"
"172516.9983","5.0227","5.7733","-11.9762"
"172697.0062","5.0227","5.7733","-11.5500"
"172876.9989","5.0227","5.7733","-10.9868"
"173057.0068","5.0227","5.7733","-9.9904"
"173236.9995","5.0227","5.7733","-8.9281"
"173417.0074","5.0227","5.7733","-8.1186"
"173597.0001","5.0227","5.7733","-7.4777"
"173776.9928","5.0227","5.7733","-7.0925"
"173957.0007","5.0227","5.7733","-6.6919"
"174136.9934","5.0227","5.7733","-6.2594"
"174317.0013","5.0227","5.7733","-6.0690"
"174496.9940","5.0227","5.7733","-6.0517"
"174677.0020","5.0227","5.7733","-5.6460"
"174856.9946","5.0227","5.7733","-5.3428"
"175037.0026","5.0227","5.7733","-5.0476"
"175216.9952","5.0227","5.7733","-4.3513"
"175397.0032","5.0227","5.7733","-3.8773"
"175576.9958","5.0227","5.7733","-3.5180"
"175757.0038","5.0227","5.7733","-3.0304"
"175936.9965","5.0227","5.7733","-2.6903"
"176117.0044","5.0227","5.7733","-2.6309"
"176296.9971","5.0227","5.7733","-2.4156"
"176477.0050","5.0227","5.7733","-2.1641"
"176656.9977","5.0227","5.7733","-1.9524"
"176837.0056","5.0227","5.7733","-1.5735"
"177016.9983","5.0227","5.7733","-1.4147"
"177197.0062","5.0227","5.7733","-1.2216"
"177376.9989","5.0227","5.7733","-0.9372"
"177557.0068","5.0227","5.7733","-0.6137"
"177736.9995","5.0227","5.7733","-0.4156"
"177917.0074","5.0227","5.7733","-0.2922"
"178097.0001","5.0227","5.7733","-0.1906"
"178276.9928","5.0227","5.7733","-0.1707"
"178457.0007","5.0227","5.7733","-0.0106"
"178636.9934","5.0227","5.7733","0.0911"
"178817.0013","5.0227","5.7733","0.0969"
"178996.9940","5.0227","5.7733","0.0928"
"179177.0020","5.0227","5.7733","0.1625"
"179356.9946","5.0227","5.7733","0.1616"
"179537.0026","5.0227","5.7733","0.1442"
"179716.9952","5.0227","5.7733","0.1334"
"179897.0032","5.0227","5.7733","0.1237"
"180076.9958","5.0227","5.7733","0.1158"
"180257.0038","5.0227","5.7733","0.1093"
"180436.9965","5.0227","5.7733","0.1035"
"180617.0044","5.0227","5.7733","0.0986"
"180796.9971","5.0227","5.7733","0.0951"
"180977.0050","5.0227","5.7733","0.0912"
"181156.9977","5.0227","5.7733","0.0888"
"181337.0056","5.0227","5.7733","0.0862"
"181516.9983","5.0227","5.7733","0.0846"
"181697.0062","5.0227","5.7733","0.0833"
"181876.9989","5.0227","5.7733","0.0822"
"182057.0068","5.0227","5.7733","0.0813"
"182236.9995","5.0227","5.7733","0.0806"
"182417.0074","5.0227","5.7733","0.0789"
"182597.0001","5.0227","5.7733","0.0776"
"182776.9928","5.0227","5.7733","0.0782"
"182957.0007","5.0227","5.7733","0.0777"
"183136.9934","5.0227","5.7733","0.0780"
"183317.0013","5.0227","5.7733","0.0779"
"183496.9940","5.0227","5.7733","0.0788"
"183677.0020","5.0227","5.7733","0.0789"
"183856.9946","5.0227","5.7733","0.0834"
"184037.0026","5.0227","5.7733","0.0918"
"184216.9952","5.0228","5.7733","0.1037"
"184397.0032","5.0227","5.7733","0.2935"
"184576.9958","5.0227","5.7733","0.5213"
"184757.0038","5.0227","5.7733","0.5160"
"184936.9965","5.0228","5.7733","0.5024"
"185117.0044","5.0227","5.7733","0.4860"
"185296.9971","5.0227","5.7733","0.4613"
"185477.0050","5.0227","5.7733","0.3960"
"185656.9977","5.0227","5.7733","0.3433"
"185837.0056","5.0227","5.7733","0.2993"
"186016.9983","5.0227","5.7733","0.2885"
"186197.0062","5.0227","5.7733","0.2868"
"186376.9989","5.0227","5.7733","0.2887"
"186557.0068","5.0228","5.7733","0.2906"
"186736.9995","5.0227","5.7733","0.2922"
"186917.0074","5.0227","5.7733","0.2931"
"187054.9927","5.0228","5.7734","0.2942"
"187235.0006","5.0724","5.8304","0.3328"
"187414.9933","5.1321","5.8990","0.3759"
"187595.0012","5.1922","5.9680","0.4175"
"187774.9939","5.2520","6.0368","0.4581"
"187955.0018","5.3119","6.1056","0.4970"
"188134.9945","5.3718","6.1745","0.5354"
"188315.0024","5.4319","6.2435","0.5721"
"188494.9951","5.4921","6.3127","0.6089"
"188675.0031","5.5520","6.3816","0.6452"
"188854.9957","5.6118","6.4504","0.6803"
"189035.0037","5.6721","6.5197","0.7155"
"189214.9963","5.7321","6.5886","0.7500"
"189395.0043","5.7919","6.6574","0.7842"
"189574.9969","5.8518","6.7263","0.8190"
"189755.0049","5.9120","6.7954","0.8532"
"189934.9976","5.9720","6.8643","0.8872"
"190115.0055","6.0319","6.9332","0.9207"
"190294.9982","6.0918","7.0021","0.9539"
"190475.0061","6.1520","7.0712","0.9877"
"190654.9988","6.2121","7.1403","1.0213"
"190835.0067","6.2721","7.2093","1.0545"
"191014.9994","6.3320","7.2782","1.0868"
"191195.0073","6.3919","7.3470","1.1193"
"191375.0000","6.4520","7.4161","1.1516"
"191554.9927","6.5120","7.4851","1.1838"
"191735.0006","6.5720","7.5540","1.2157"
"191914.9933","6.6320","7.6230","1.2478"
"192095.0012","6.6919","7.6918","1.2786"
"192274.9939","6.7519","7.7608","1.3101"
"192455.0018","6.8121","7.8300","1.3414"
"192634.9945","6.8720","7.8989","1.3738"
"192815.0024","6.9319","7.9677","1.4052"
"192994.9951","6.9920","8.0367","1.4369"
"193175.0031","7.0520","8.1057","1.4671"
"193354.9957","7.1120","8.1748","1.4986"
"193535.0037","7.1719","8.2436","1.5306"
"193714.9963","7.2318","8.3125","1.5624"
"193895.0043","7.2920","8.3816","1.5936"
"194074.9969","7.3519","8.4504","1.6253"
"194255.0049","7.4119","8.5195","1.6561"
"194434.9976","7.4719","8.5884","1.6874"
"194615.0055","7.5319","8.6574","1.7186"
"194794.9982","7.5921","8.7266","1.7496"
"194975.0061","7.6520","8.7954","1.7804"
"195154.9988","7.7119","8.8643","1.8111"
"195335.0067","7.7720","8.9334","1.8419"
"195514.9994","7.8320","9.0023","1.8721"
"195695.0073","7.8919","9.0711","1.9027"
"195875.0000","7.9519","9.1401","1.9327"
"196054.9927","8.0119","9.2090","1.9630"
"196235.0006","8.0720","9.2781","1.9932"
"196414.9933","8.1321","9.3472","2.0236"
"196595.0012","8.1920","9.4161","2.0526"
"196774.9939","8.2520","9.4851","2.0771"
"196955.0018","8.3121","9.5541","2.1074"
"197134.9945","8.3719","9.6229","2.1372"
"197315.0024","8.4320","9.6919","2.1664"
"197494.9951","8.4920","9.7609","2.1961"
"197675.0031","8.5519","9.8297","2.2254"
"197854.9957","8.6118","9.8987","2.2534"
"198035.0037","8.6718","9.9676","2.2810"
"198214.9963","8.7320","10.0368","2.3092"
"198395.0043","8.7920","10.1057","2.3384"
"198574.9969","8.8520","10.1747","2.3668"
"198755.0049","8.9121","10.2437","2.3926"
"198934.9976","8.9720","10.3127","2.3412"
"199115.0055","9.0319","10.3815","1.8868"
"199294.9982","9.0919","10.4505","1.8103"
"199475.0061","9.1518","10.5194","1.8501"
"199654.9988","9.2120","10.5885","1.8928"
"199835.0067","9.2719","10.6573","1.9325"
"200014.9994","9.3318","10.7262","1.9702"
"200195.0073","9.3921","10.7955","1.9964"
"200375.0000","9.4521","10.8645","1.9232"
"200554.9927","9.5120","10.9334","1.9076"
"200735.0006","9.5720","11.0023","1.9496"
"200914.9933","9.6320","11.0713","1.9889"
"201095.0012","9.6920","11.1402","2.0258"
"201274.9939","9.7520","11.2091","2.0618"
"201455.0018","9.8118","11.2780","2.0958"
"201634.9945","9.8720","11.3472","2.1303"
"201815.0024","9.9320","11.4160","2.1636"
"201994.9951","9.9918","11.4848","2.1968"
"202130.0049","10.0347","11.5342","2.2183"
"202309.9976","10.0349","11.5344","2.2134"
"202490.0055","10.0334","11.5326","2.2090"
"202669.9982","10.0321","11.5312","2.2053"
"202850.0061","10.0313","11.5303","2.2012"
"203029.9988","10.0309","11.5297","2.1979"
"203210.0067","10.0306","11.5295","2.1948"
"203389.9994","10.0305","11.5293","2.1912"
"203570.0073","10.0304","11.5293","2.1892"
"203750.0000","10.0304","11.5292","2.1866"
"203929.9927","10.0304","11.5292","2.1841"
"204110.0006","10.0304","11.5292","2.1830"
"204289.9933","10.0304","11.5292","2.1799"
"204470.0012","10.0304","11.5292","2.0885"
"204649.9939","10.0304","11.5292","1.5233"
"204830.0018","10.0304","11.5292","1.4727"
"205009.9945","10.0304","11.5292","1.5012"
"205190.0024","10.0304","11.5292","1.5158"
"205369.9951","10.0304","11.5292","1.5243"
"205550.0031","10.0304","11.5292","1.5317"
"205729.9957","10.0304","11.5292","1.5353"
"205910.0037","10.0304","11.5292","1.5392"
"206089.9963","10.0304","11.5292","1.5391"
"206270.0043","10.0304","11.5292","1.5402"
"206449.9969","10.0304","11.5292","1.5417"
"206630.0049","10.0304","11.5292","1.4495"
"206735.9924","10.0304","11.5292","0.8583"