File: data/four_circular_test/FourCircular-10mm_to_40mm_2.csv
Time,Displacement,Tensile strain (Displacement),Force
(ms),(mm),(%),(N)
"0.0000","0.2056","0.3427","0.0024"
"620.0000","0.2101","0.3501","-0.0360"
"1240.0000","0.2091","0.3485","-0.0610"
"1860.0000","0.2089","0.3481","-0.0533"
"2480.0000","0.2088","0.3480","-0.0753"
"3100.0000","0.2088","0.3480","-0.0521"
"3720.0000","0.2088","0.3480","-0.0395"
"4340.0000","0.2088","0.3480","-0.0660"
"4960.0000","0.2088","0.3480","-0.0460"
"5580.0000","0.2088","0.3480","-0.0592"
"6200.0000","0.2088","0.3480","-0.0526"
"6820.0000","0.2088","0.3480","-0.0422"
"7440.0000","0.2088","0.3480","-0.0633"
"8060.0000","0.2088","0.3480","-0.0402"
"8680.0000","0.2088","0.3480","-0.0459"
"9300.0000","0.2088","0.3480","-0.0559"
"9920.0000","0.2088","0.3480","-0.0473"
"10514.0000","0.0579","0.0965","-0.2383"
"11134.0000","-0.1485","-0.2475","-0.3929"
"11754.0000","-0.3554","-0.5923","-0.5166"
"12374.0000","-0.5619","-0.9365","-0.6717"
"12994.0000","-0.7689","-1.2815","-0.8209"
"13614.0000","-0.9753","-1.6255","-0.9537"
"14234.0000","-1.1819","-1.9698","-1.0796"
"14854.0000","-1.3887","-2.3145","-1.2289"
"15474.0000","-1.5953","-2.6588","-1.3919"
"16094.0000","-1.8021","-3.0035","-1.5329"
"16714.0000","-2.0087","-3.3478","-1.7007"
"17334.0000","-2.2156","-3.6926","-1.8332"
"17954.0000","-2.4217","-4.0362","-1.9790"
"18574.0000","-2.6286","-4.3811","-2.1630"
"19194.0000","-2.8354","-4.7256","-2.3092"
"19814.0000","-3.0420","-5.0699","-2.4528"
"20434.0000","-3.2487","-5.4146","-2.6485"
"21054.0000","-3.4553","-5.7588","-2.8185"
"21674.0000","-3.6620","-6.1033","-2.9640"
"22294.0000","-3.8686","-6.4477","-3.1406"
"22914.0000","-4.0754","-6.7924","-3.3208"
"23534.0000","-4.2819","-7.1365","-3.4787"
"24154.0000","-4.4889","-7.4814","-3.6957"
"24774.0000","-4.6953","-7.8255","-3.8924"
"25394.0000","-4.9018","-8.1697","-4.0500"
"26014.0000","-5.1088","-8.5146","-4.2716"
"26634.0000","-5.3154","-8.8590","-4.4877"
"27254.0000","-5.5218","-9.2030","-4.6902"
"27874.0000","-5.7286","-9.5477","-4.9161"
"28494.0000","-5.9356","-9.8927","-5.1582"
"29114.0000","-6.1418","-10.2363","-5.3948"
"29734.0000","-6.3488","-10.5814","-5.6626"
"30354.0000","-6.5554","-10.9257","-5.9014"
"30974.0000","-6.7619","-11.2699","-6.1478"
"31594.0000","-6.9685","-11.6142","-6.4075"
"32214.0000","-7.1755","-11.9591","-6.6745"
"32834.0000","-7.3821","-12.3035","-6.9423"
"33454.0000","-7.5885","-12.6475","-7.2512"
"34074.0000","-7.7955","-12.9925","-7.5241"
"34694.0000","-8.0017","-13.3362","-7.8305"
"35314.0000","-8.2088","-13.6813","-8.1505"
"35934.0000","-8.4154","-14.0257","-8.4784"
"36554.0000","-8.6220","-14.3700","-8.7806"
"37174.0000","-8.8287","-14.7145","-9.1141"
"37794.0000","-9.0354","-15.0589","-9.4312"
"38414.0000","-9.2419","-15.4032","-9.7954"
"39034.0000","-9.4485","-15.7475","-10.1044"
"39654.0000","-9.6557","-16.0928","-10.4633"
"40274.0000","-9.8618","-16.4363","-10.8257"
"40851.0000","-10.0045","-16.6743","-10.9336"
"41471.0000","-10.0008","-16.6679","-10.9104"
"42091.0000","-10.0000","-16.6667","-10.8582"
"42711.0000","-10.0000","-16.6666","-10.8789"
"43331.0000","-10.0000","-16.6666","-10.8768"
"43951.0000","-10.0000","-16.6666","-10.8420"
"44571.0000","-10.0000","-16.6666","-10.8196"
"45191.0000","-10.0000","-16.6666","-10.7985"
"45811.0000","-10.0000","-16.6667","-10.8140"
"46431.0000","-10.0000","-16.6667","-10.8295"
"47051.0000","-10.0000","-16.6667","-10.8095"
"47671.0000","-10.0000","-16.6667","-10.7977"
"48291.0000","-10.0000","-16.6667","-10.8371"
"48911.0000","-10.0000","-16.6667","-10.8681"
"49531.0000","-10.0000","-16.6667","-10.8971"
"50151.0000","-10.0000","-16.6667","-32.6723"
"50771.0000","-10.0000","-16.6666","-95.0179"
"51391.0000","-10.0000","-16.6666","-143.6133"
"52011.0000","-10.0000","-16.6667","-155.4045"
"52631.0000","-10.0000","-16.6667","-158.8313"
"53251.0000","-10.0000","-16.6667","-161.8958"
"53871.0000","-10.0000","-16.6667","-164.1152"
"54491.0000","-10.0000","-16.6667","-164.3389"
"55111.0000","-10.0000","-16.6667","-164.8937"
"55731.0000","-10.0000","-16.6667","-165.6437"
"56351.0000","-10.0000","-16.6667","-165.1923"
"56971.0000","-10.0000","-16.6667","-163.7051"
"57591.0000","-10.0000","-16.6667","-162.0441"
"58211.0000","-10.0000","-16.6667","-159.6276"
"58831.0000","-10.0000","-16.6667","-158.8740"
"59451.0000","-10.0000","-16.6667","-173.3046"
"60071.0000","-10.0000","-16.6667","-187.3387"
"60691.0000","-10.0000","-16.6667","-193.9368"
"61311.0000","-10.0000","-16.6667","-193.7183"
"61931.0000","-10.0000","-16.6667","-177.3075"
"62551.0000","-10.0000","-16.6667","-170.4363"
"63171.0000","-10.0000","-16.6667","-190.5993"
"63791.0000","-10.0000","-16.6667","-195.1882"
"64411.0000","-10.0000","-16.6667","-199.3104"
"65031.0000","-10.0000","-16.6667","-181.7676"
"65651.0000","-10.0000","-16.6667","-170.6095"
"66271.0000","-10.0000","-16.6667","-184.2082"
"66891.0000","-10.0000","-16.6667","-168.9608"
"67511.0000","-10.0000","-16.6667","-156.0777"
"68131.0000","-10.0000","-16.6667","-145.7245"
"68751.0000","-10.0000","-16.6667","-136.7966"
"69371.0000","-10.0000","-16.6667","-133.5110"
"69991.0000","-10.0000","-16.6667","-143.4702"
"70611.0000","-10.0000","-16.6667","-138.8128"
"71231.0000","-10.0000","-16.6667","-142.7930"
"71851.0000","-10.0000","-16.6667","-133.3415"
"72471.0000","-10.0000","-16.6667","-123.8638"
"73091.0000","-10.0000","-16.6667","-115.9414"
"73711.0000","-10.0000","-16.6667","-107.9609"
"74331.0000","-10.0000","-16.6667","-99.8680"
"74951.0000","-10.0000","-16.6667","-92.0857"
"75571.0000","-10.0000","-16.6667","-84.5547"
"76191.0000","-10.0000","-16.6667","-77.0514"
"76811.0000","-10.0000","-16.6667","-69.4524"
"77431.0000","-10.0000","-16.6667","-60.5414"
"78051.0000","-10.0000","-16.6667","-36.9433"
"78671.0000","-10.0000","-16.6667","-25.3510"
"79291.0000","-10.0000","-16.6667","-20.4145"
"79911.0000","-10.0000","-16.6667","-17.9249"
"80531.0000","-10.0000","-16.6667","-9.5214"
"81151.0000","-10.0000","-16.6667","-9.0347"
"81771.0000","-10.0000","-16.6667","-9.0168"
"82391.0000","-10.0000","-16.6667","-8.9940"
"83011.0000","-10.0000","-16.6667","-9.0066"
"83631.0000","-10.0000","-16.6667","-9.0203"
"84251.0000","-10.0000","-16.6667","-8.9999"
"84871.0000","-10.0000","-16.6667","-8.9919"
"85491.0000","-10.0000","-16.6667","-8.9849"
"86081.0000","-9.8942","-16.4903","-8.7168"
"86701.0000","-9.6875","-16.1459","-8.3663"
"87321.0000","-9.4810","-15.8016","-8.0571"
"87941.0000","-9.2744","-15.4573","-7.7474"
"88561.0000","-9.0675","-15.1125","-7.4776"
"89181.0000","-8.8610","-14.7683","-7.2089"
"89801.0000","-8.6542","-14.4237","-6.9146"
"90421.0000","-8.4476","-14.0793","-6.6762"
"91041.0000","-8.2410","-13.7349","-6.3826"
"91661.0000","-8.0343","-13.3905","-6.1370"
"92281.0000","-7.8276","-13.0460","-5.8789"
"92901.0000","-7.6209","-12.7014","-5.6766"
"93521.0000","-7.4143","-12.3572","-5.4231"
"94141.0000","-7.2077","-12.0129","-5.1697"
"94761.0000","-7.0009","-11.6682","-4.9462"
"95381.0000","-6.7942","-11.3237","-4.7300"
"96001.0000","-6.5877","-10.9794","-4.4850"
"96621.0000","-6.3808","-10.6347","-4.2798"
"97241.0000","-6.1743","-10.2905","-4.0711"
"97861.0000","-5.9677","-9.9462","-3.8742"
"98481.0000","-5.7610","-9.6016","-3.6701"
"99101.0000","-5.5542","-9.2571","-3.4548"
"99721.0000","-5.3476","-8.9126","-3.2554"
"100341.0000","-5.1410","-8.5683","-3.1226"
"100906.0000","-4.9875","-8.3125","-3.0698"
"101526.0000","-4.9916","-8.3193","-3.1246"
"102146.0000","-4.9924","-8.3207","-3.1451"
"102766.0000","-4.9925","-8.3208","-3.1712"
"103386.0000","-4.9925","-8.3208","-3.1722"
"104006.0000","-4.9925","-8.3208","-3.1776"
"104626.0000","-4.9925","-8.3208","-3.1708"
"105246.0000","-4.9925","-8.3208","-3.1793"
"105866.0000","-4.9925","-8.3208","-3.1779"
"106486.0000","-4.9925","-8.3208","-3.1967"
"107106.0000","-4.9925","-8.3208","-3.1648"
"107726.0000","-4.9925","-8.3208","-3.1852"
"108346.0000","-4.9925","-8.3208","-3.1925"
"108966.0000","-4.9925","-8.3208","-3.1745"
"109586.0000","-4.9925","-8.3208","-3.1981"
"110206.0000","-4.9925","-8.3208","-15.1400"
"110826.0000","-4.9925","-8.3208","-54.5338"
"111446.0000","-4.9925","-8.3208","-98.6837"
"112066.0000","-4.9925","-8.3208","-123.2007"
"112686.0000","-4.9925","-8.3208","-137.2397"
"113306.0000","-4.9925","-8.3208","-141.8875"
"113926.0000","-4.9925","-8.3208","-144.9715"
"114546.0000","-4.9925","-8.3208","-146.1918"
"115166.0000","-4.9925","-8.3208","-147.0668"
"115786.0000","-4.9925","-8.3208","-161.4089"
"116406.0000","-4.9925","-8.3208","-171.2915"
"117026.0000","-4.9925","-8.3208","-173.3521"
"117646.0000","-4.9925","-8.3208","-178.2858"
"118266.0000","-4.9925","-8.3208","-177.5076"
"118886.0000","-4.9925","-8.3208","-182.6103"
"119506.0000","-4.9925","-8.3208","-171.8583"
"120126.0000","-4.9925","-8.3208","-158.6246"
"120746.0000","-4.9925","-8.3208","-168.6157"
"121366.0000","-4.9925","-8.3208","-170.6000"
"121986.0000","-4.9925","-8.3208","-156.8934"
"122606.0000","-4.9925","-8.3208","-150.3538"
"123226.0000","-4.9925","-8.3208","-167.5099"
"123846.0000","-4.9925","-8.3208","-161.0035"
"124466.0000","-4.9925","-8.3208","-148.6526"
"125086.0000","-4.9925","-8.3208","-137.8876"
"125706.0000","-4.9925","-8.3208","-128.3513"
"126326.0000","-4.9925","-8.3208","-118.7016"
"126946.0000","-4.9925","-8.3208","-109.2553"
"127566.0000","-4.9925","-8.3208","-100.1093"
"128186.0000","-4.9925","-8.3208","-91.1400"
"128806.0000","-4.9925","-8.3208","-82.1424"
"129426.0000","-4.9925","-8.3208","-72.7813"
"130046.0000","-4.9925","-8.3208","-59.3333"
"130666.0000","-4.9925","-8.3208","-33.1601"
"131286.0000","-4.9925","-8.3208","-21.0427"
"131906.0000","-4.9925","-8.3208","-14.8104"
"132526.0000","-4.9925","-8.3208","-11.4329"
"133146.0000","-4.9925","-8.3208","-10.2804"
"133766.0000","-4.9925","-8.3208","-9.1568"
"134386.0000","-4.9925","-8.3208","-8.1949"
"135006.0000","-4.9925","-8.3208","-7.3540"
"135626.0000","-4.9925","-8.3208","-22.8815"
"136246.0000","-4.9925","-8.3208","-51.3875"
"136866.0000","-4.9925","-8.3208","-64.6958"
"137486.0000","-4.9925","-8.3208","-71.0857"
"138106.0000","-4.9925","-8.3208","-118.7023"
"138726.0000","-4.9925","-8.3208","-144.9010"
"139346.0000","-4.9925","-8.3208","-129.7513"
"139966.0000","-4.9925","-8.3208","-87.3711"
"140586.0000","-4.9925","-8.3208","-43.6383"
"141206.0000","-4.9925","-8.3208","-20.4305"
"141826.0000","-4.9925","-8.3208","-8.1562"
"142446.0000","-4.9925","-8.3208","-3.8284"
"143066.0000","-4.9925","-8.3208","-3.4842"
"143686.0000","-4.9925","-8.3208","-3.4109"
"144306.0000","-4.9925","-8.3208","-3.4153"
"144926.0000","-4.9925","-8.3208","-3.3918"
"145546.0000","-4.9925","-8.3208","-3.3715"
"146134.0000","-4.8963","-8.1604","-3.1598"
"146754.0000","-4.6897","-7.8161","-2.9580"
"147374.0000","-4.4831","-7.4718","-2.7974"
"147994.0000","-4.2764","-7.1273","-2.6142"
"148614.0000","-4.0697","-6.7829","-2.4377"
"149234.0000","-3.8631","-6.4384","-2.2882"
"149854.0000","-3.6564","-6.0940","-2.1148"
"150474.0000","-3.4497","-5.7495","-1.9519"
"151094.0000","-3.2430","-5.4049","-1.7777"
"151714.0000","-3.0365","-5.0608","-1.6350"
"152334.0000","-2.8297","-4.7162","-1.4720"
"152954.0000","-2.6230","-4.3717","-1.3362"
"153574.0000","-2.4163","-4.0272","-1.1768"
"154194.0000","-2.2098","-3.6830","-1.0354"
"154814.0000","-2.0031","-3.3385","-0.8965"
"155434.0000","-1.7963","-2.9938","-0.7521"
"156054.0000","-1.5898","-2.6497","-0.6149"
"156674.0000","-1.3831","-2.3051","-0.4750"
"157294.0000","-1.1763","-1.9605","-0.3667"
"157914.0000","-0.9698","-1.6163","-0.2320"
"158534.0000","-0.7632","-1.2720","-0.1340"
"159154.0000","-0.5563","-0.9271","-0.0119"
"159774.0000","-0.3497","-0.5828","0.1097"
"160394.0000","-0.1431","-0.2384","0.2219"
"160968.0000","0.0202","0.0337","0.2400"
"161588.0000","0.0161","0.0268","0.2067"
"162208.0000","0.0151","0.0252","0.1748"
"162828.0000","0.0151","0.0251","0.1993"
"163448.0000","0.0151","0.0251","0.1855"
"164068.0000","0.0151","0.0251","0.1676"
"164688.0000","0.0151","0.0251","0.1658"
"165308.0000","0.0151","0.0251","0.1535"
"165928.0000","0.0151","0.0251","0.1573"
"166548.0000","0.0151","0.0251","0.1661"
"167168.0000","0.0151","0.0251","0.1270"
"167788.0000","0.0151","0.0252","0.1286"
"168408.0000","0.0151","0.0252","0.1218"
"169028.0000","0.0151","0.0252","0.0948"
"169648.0000","0.0151","0.0252","-15.7702"
"170268.0000","0.0151","0.0252","-72.3295"
"170888.0000","0.0151","0.0252","-136.9970"
"171508.0000","0.0151","0.0252","-153.0891"
"172128.0000","0.0151","0.0252","-159.7341"
"172748.0000","0.0151","0.0252","-161.7262"
"173368.0000","0.0151","0.0252","-168.6222"
"173988.0000","0.0151","0.0252","-173.4566"
"174608.0000","0.0151","0.0252","-174.7899"
"175228.0000","0.0151","0.0252","-178.2912"
"175848.0000","0.0151","0.0252","-183.6337"
"176468.0000","0.0151","0.0252","-187.1300"
"177088.0000","0.0151","0.0252","-173.8575"
"177708.0000","0.0151","0.0252","-161.0907"
"178328.0000","0.0151","0.0252","-161.2723"
"178948.0000","0.0151","0.0252","-161.4293"
"179568.0000","0.0151","0.0252","-175.2963"
"180188.0000","0.0151","0.0252","-162.0242"
"180808.0000","0.0151","0.0252","-151.3800"
"181428.0000","0.0151","0.0252","-142.3679"
"182048.0000","0.0151","0.0252","-133.7589"
"182668.0000","0.0151","0.0252","-140.3404"
"183288.0000","0.0151","0.0252","-140.5357"
"183908.0000","0.0151","0.0252","-138.5726"
"184528.0000","0.0151","0.0252","-136.0257"
"185148.0000","0.0151","0.0252","-133.3187"
"185768.0000","0.0151","0.0252","-130.5313"
"186388.0000","0.0151","0.0252","-125.5177"
"187008.0000","0.0151","0.0252","-120.3672"
"187628.0000","0.0151","0.0252","-116.0318"
"188248.0000","0.0151","0.0252","-106.2861"
"188868.0000","0.0151","0.0251","-96.1456"
"189488.0000","0.0151","0.0251","-85.9016"
"190108.0000","0.0151","0.0251","-75.6412"
"190728.0000","0.0151","0.0251","-71.3740"
"191348.0000","0.0151","0.0252","-90.9011"
"191968.0000","0.0151","0.0252","-101.6828"
"192588.0000","0.0151","0.0252","-103.7723"
"193208.0000","0.0151","0.0252","-98.4060"
"193828.0000","0.0151","0.0252","-89.8144"
"194448.0000","0.0151","0.0252","-76.3324"
"195068.0000","0.0151","0.0252","-64.2033"
"195688.0000","0.0151","0.0251","-38.5605"
"196308.0000","0.0151","0.0251","-23.9686"
"196928.0000","0.0151","0.0251","-16.0553"
"197548.0000","0.0151","0.0251","-11.6578"
"198168.0000","0.0151","0.0252","-9.2416"
"198788.0000","0.0151","0.0252","-7.4965"
"199408.0000","0.0151","0.0251","-3.7853"
"200028.0000","0.0151","0.0252","-0.1980"
"200648.0000","0.0151","0.0252","-0.0422"
"201268.0000","0.0151","0.0252","-0.0361"
"201888.0000","0.0151","0.0252","-0.0327"
"202508.0000","0.0151","0.0252","-0.0062"
"203128.0000","0.0151","0.0252","-0.0088"
"203748.0000","0.0151","0.0252","-0.0219"
"204368.0000","0.0151","0.0252","-0.0071"
"204988.0000","0.0151","0.0252","-0.0203"
"205608.0000","0.0151","0.0252","-0.0117"
"206192.0000","0.1048","0.1746","0.1520"
"206812.0000","0.3112","0.5187","0.2865"
"207432.0000","0.5176","0.8627","0.4207"
"208052.0000","0.7245","1.2075","0.5449"
"208672.0000","0.9310","1.5517","0.6610"
"209292.0000","1.1377","1.8962","0.8149"
"209912.0000","1.3445","2.2408","0.9195"
"210532.0000","1.5512","2.5853","1.0920"
"211152.0000","1.7577","2.9295","1.1887"
"211772.0000","1.9643","3.2739","1.3107"
"212392.0000","2.1711","3.6184","1.4289"
"213012.0000","2.3777","3.9628","1.5555"
"213632.0000","2.5845","4.3075","1.7086"
"214252.0000","2.7911","4.6518","1.7990"
"214872.0000","2.9976","4.9960","1.9338"
"215492.0000","3.2045","5.3408","2.0307"
"216112.0000","3.4112","5.6853","2.1634"
"216732.0000","3.6177","6.0295","2.3048"
"217352.0000","3.8245","6.3742","2.4305"
"217972.0000","4.0312","6.7186","2.5207"
"218592.0000","4.2376","7.0626","2.6420"
"219212.0000","4.4444","7.4073","2.7619"
"219832.0000","4.6512","7.7520","2.8724"
"220452.0000","4.8577","8.0962","3.0002"
"221026.0000","5.0280","8.3800","3.0279"
"221646.0000","5.0236","8.3727","2.9671"
"222266.0000","5.0226","8.3710","2.9834"
"222886.0000","5.0225","8.3709","2.9731"
"223506.0000","5.0226","8.3709","2.9618"
"224126.0000","5.0226","8.3709","2.9350"
"224746.0000","5.0226","8.3710","2.9159"
"225366.0000","5.0226","8.3710","2.9361"
"225986.0000","5.0226","8.3710","2.9454"
"226606.0000","5.0226","8.3710","2.9229"
"227226.0000","5.0226","8.3710","2.9192"
"227846.0000","5.0226","8.3710","2.9380"
"228466.0000","5.0226","8.3710","2.9334"
"229086.0000","5.0226","8.3710","2.9304"
"229706.0000","5.0226","8.3710","2.9236"
"230326.0000","5.0226","8.3710","2.9231"
"230946.0000","5.0226","8.3710","2.9042"
"231566.0000","5.0226","8.3710","-1.0755"
"232186.0000","5.0226","8.3710","-28.4727"
"232806.0000","5.0226","8.3710","-61.3889"
"233426.0000","5.0226","8.3710","-102.2031"
"234046.0000","5.0226","8.3710","-143.3904"
"234666.0000","5.0226","8.3710","-155.9444"
"235286.0000","5.0226","8.3710","-161.9901"
"235906.0000","5.0226","8.3710","-164.9632"
"236526.0000","5.0226","8.3710","-166.5746"
"237146.0000","5.0226","8.3710","-166.8086"
"237766.0000","5.0226","8.3710","-165.3343"
"238386.0000","5.0226","8.3710","-155.2063"
"239006.0000","5.0226","8.3710","-143.8559"
"239626.0000","5.0226","8.3710","-162.1674"
"240246.0000","5.0226","8.3710","-172.3902"
"240866.0000","5.0226","8.3710","-164.3136"
"241486.0000","5.0226","8.3710","-165.3409"
"242106.0000","5.0226","8.3710","-170.4469"
"242726.0000","5.0226","8.3710","-172.2725"
"243346.0000","5.0226","8.3710","-160.4156"
"243966.0000","5.0226","8.3710","-150.0480"
"244586.0000","5.0226","8.3710","-140.0718"
"245206.0000","5.0226","8.3710","-129.9294"
"245826.0000","5.0226","8.3710","-119.9693"
"246446.0000","5.0226","8.3710","-110.4277"
"247066.0000","5.0226","8.3710","-101.1207"
"247686.0000","5.0226","8.3710","-91.8156"
"248306.0000","5.0226","8.3710","-82.6711"
"248926.0000","5.0226","8.3710","-73.9373"
"249546.0000","5.0226","8.3710","-65.7749"
"250166.0000","5.0226","8.3710","-58.1695"
"250786.0000","5.0226","8.3710","-50.5871"
"251406.0000","5.0226","8.3710","-36.8398"
"252026.0000","5.0226","8.3710","-19.2594"
"252646.0000","5.0226","8.3710","-14.5029"
"253266.0000","5.0226","8.3710","-11.7726"
"253886.0000","5.0226","8.3710","-8.6805"
"254506.0000","5.0226","8.3710","-6.2496"
"255126.0000","5.0226","8.3710","-4.5232"
"255746.0000","5.0226","8.3710","0.1965"
"256366.0000","5.0226","8.3710","2.6313"
"256986.0000","5.0226","8.3710","2.7489"
"257606.0000","5.0226","8.3710","2.7510"
"258226.0000","5.0226","8.3710","2.7604"
"258846.0000","5.0226","8.3710","2.7583"
"259466.0000","5.0226","8.3710","2.7758"
"260086.0000","5.0226","8.3710","2.7729"
"260706.0000","5.0226","8.3710","2.7703"
"261326.0000","5.0226","8.3710","2.7724"
"261946.0000","5.0226","8.3710","2.7596"
"262566.0000","5.0226","8.3710","2.7679"
"263186.0000","5.0226","8.3710","2.7725"
"263806.0000","5.0226","8.3710","2.7703"
"264426.0000","5.0226","8.3710","2.7662"
"265046.0000","5.0226","8.3710","2.7426"
"265666.0000","5.0226","8.3710","2.7522"
"266265.0000","5.1121","8.5201","2.8982"
"266885.0000","5.3187","8.8645","3.0418"
"267505.0000","5.5251","9.2085","3.1714"
"268125.0000","5.7317","9.5529","3.3310"
"268745.0000","5.9385","9.8976","3.4474"
"269365.0000","6.1451","10.2419","3.5640"
"269985.0000","6.3517","10.5862","3.6718"
"270605.0000","6.5586","10.9310","3.8167"
"271225.0000","6.7652","11.2753","3.9360"
"271845.0000","6.9717","11.6195","4.0725"
"272465.0000","7.1784","11.9641","4.1824"
"273085.0000","7.3852","12.3087","4.3266"
"273705.0000","7.5919","12.6531","4.4405"
"274325.0000","7.7984","12.9973","4.5977"
"274945.0000","8.0052","13.3420","4.7198"
"275565.0000","8.2117","13.6861","4.8574"
"276185.0000","8.4185","14.0308","4.9938"
"276805.0000","8.6252","14.3753","5.1122"
"277425.0000","8.8319","14.7198","5.2395"
"278045.0000","9.0385","15.0641","5.3671"
"278665.0000","9.2451","15.4086","5.4795"
"279285.0000","9.4518","15.7530","5.6126"
"279905.0000","9.6584","16.0974","5.7650"
"280525.0000","9.8653","16.4422","5.8928"
"281099.0000","10.0352","16.7253","5.9348"
"281719.0000","10.0310","16.7184","5.8929"
"282339.0000","10.0300","16.7167","5.8575"
"282959.0000","10.0299","16.7166","5.8983"
"283579.0000","10.0299","16.7166","5.8498"
"284199.0000","10.0299","16.7166","5.8586"
"284819.0000","10.0300","16.7166","5.8465"
"285439.0000","10.0300","16.7166","5.8489"
"286059.0000","10.0300","16.7166","5.8382"
"286679.0000","10.0300","16.7166","5.7999"
"287299.0000","10.0300","16.7166","5.8210"
"287919.0000","10.0300","16.7166","5.8294"
"288539.0000","10.0300","16.7166","5.8152"
"289159.0000","10.0300","16.7166","5.8232"
"289779.0000","10.0300","16.7166","5.8353"
"290399.0000","10.0300","16.7166","5.8194"
"291019.0000","10.0300","16.7166","5.8280"
"291639.0000","10.0300","16.7166","5.8118"
"292259.0000","10.0300","16.7166","5.7968"
"292879.0000","10.0300","16.7166","5.8196"
"293499.0000","10.0300","16.7166","5.8084"
"294119.0000","10.0300","16.7166","5.7923"
"294739.0000","10.0300","16.7166","5.5952"
"295359.0000","10.0300","16.7166","-18.1151"
"295979.0000","10.0300","16.7166","-56.4461"
"296599.0000","10.0300","16.7166","-94.9149"
"297219.0000","10.0300","16.7166","-130.1112"
"297839.0000","10.0300","16.7166","-149.8969"
"298459.0000","10.0300","16.7166","-153.7514"
"299079.0000","10.0300","16.7166","-147.2136"
"299699.0000","10.0300","16.7166","-157.3195"
"300319.0000","10.0300","16.7166","-154.5734"
"300939.0000","10.0300","16.7166","-142.0100"
"301559.0000","10.0300","16.7166","-147.6933"
"302179.0000","10.0300","16.7166","-136.0088"
"302799.0000","10.0300","16.7166","-136.0888"
"303419.0000","10.0300","16.7166","-151.6915"
"304039.0000","10.0300","16.7166","-158.8866"
"304659.0000","10.0300","16.7166","-162.7039"
"305279.0000","10.0300","16.7166","-164.3373"
"305899.0000","10.0300","16.7166","-164.2746"
"306519.0000","10.0300","16.7166","-164.7981"
"307139.0000","10.0300","16.7166","-164.5312"
"307759.0000","10.0300","16.7166","-158.6808"
"308379.0000","10.0300","16.7166","-147.7603"
"308999.0000","10.0300","16.7166","-152.0831"
"309619.0000","10.0300","16.7166","-153.1420"
"310239.0000","10.0300","16.7166","-157.7123"
"310859.0000","10.0300","16.7166","-155.7939"
"311479.0000","10.0300","16.7166","-145.2066"
"312099.0000","10.0300","16.7166","-133.9090"
"312719.0000","10.0300","16.7166","-122.9361"
"313339.0000","10.0300","16.7166","-112.0910"
"313959.0000","10.0300","16.7166","-101.5337"
"314579.0000","10.0300","16.7166","-91.4764"
"315199.0000","10.0300","16.7166","-81.8286"
"315819.0000","10.0300","16.7166","-72.8597"
"316439.0000","10.0300","16.7166","-64.2374"
"317059.0000","10.0300","16.7166","-55.1359"
"317679.0000","10.0300","16.7166","-45.2928"
"318299.0000","10.0300","16.7166","-29.1450"
"318919.0000","10.0300","16.7166","-13.1382"
"319539.0000","10.0300","16.7166","-7.1313"
"320159.0000","10.0300","16.7166","-5.0430"
"320779.0000","10.0300","16.7166","-3.1070"
"321399.0000","10.0300","16.7166","-1.3234"
"322019.0000","10.0300","16.7166","-0.0059"
"322639.0000","10.0300","16.7166","0.7486"
"323259.0000","10.0300","16.7166","3.8778"
"323879.0000","10.0300","16.7166","5.5997"
"324499.0000","10.0300","16.7166","5.6630"
"325119.0000","10.0300","16.7166","5.6884"
"325739.0000","10.0300","16.7166","5.6456"
"326321.0000","10.1128","16.8547","5.8189"
"326941.0000","10.3193","17.1989","5.9600"
"327561.0000","10.5259","17.5432","6.1312"
"328181.0000","10.7325","17.8875","6.2835"
"328801.0000","10.9392","18.2320","6.4231"
"329421.0000","11.1459","18.5766","6.5771"
"330041.0000","11.3525","18.9208","6.7164"
"330661.0000","11.5592","19.2654","6.8742"
"331281.0000","11.7659","19.6099","7.0121"
"331901.0000","11.9725","19.9541","7.1488"
"332521.0000","12.1791","20.2985","7.3090"
"333141.0000","12.3859","20.6432","7.4371"
"333761.0000","12.5926","20.9877","7.5856"
"334381.0000","12.7992","21.3320","7.7229"
"335001.0000","13.0058","21.6763","7.8566"
"335621.0000","13.2125","22.0209","8.0207"
"336241.0000","13.4193","22.3654","8.1512"
"336861.0000","13.6258","22.7097","8.3065"
"337481.0000","13.8327","23.0545","8.4618"
"338101.0000","14.0392","23.3986","8.6030"
"338721.0000","14.2458","23.7430","8.7575"
"339341.0000","14.4525","24.0875","8.9158"
"339961.0000","14.6592","24.4320","9.0641"
"340581.0000","14.8660","24.7767","9.2128"
"341155.0000","15.0431","25.0718","9.3230"
"341775.0000","15.0385","25.0642","9.2390"
"342395.0000","15.0375","25.0624","9.2468"
"343015.0000","15.0373","25.0622","9.2370"
"343635.0000","15.0373","25.0622","9.2360"
"344255.0000","15.0373","25.0622","9.2234"
"344875.0000","15.0374","25.0623","9.2194"
"345495.0000","15.0374","25.0623","9.2159"
"346115.0000","15.0374","25.0623","9.2004"
"346735.0000","15.0374","25.0623","9.1913"
"347355.0000","15.0374","25.0623","9.2138"
"347975.0000","15.0374","25.0623","9.1872"
"348595.0000","15.0374","25.0623","9.1902"
"349215.0000","15.0374","25.0623","9.1736"
"349835.0000","15.0374","25.0623","9.1659"
"350455.0000","15.0374","25.0623","9.1569"
"351075.0000","15.0374","25.0623","9.1524"
"351695.0000","15.0374","25.0623","9.1553"
"352315.0000","15.0374","25.0623","9.1665"
"352935.0000","15.0374","25.0623","9.1717"
"353555.0000","15.0374","25.0623","9.1650"
"354175.0000","15.0374","25.0623","9.1737"
"354795.0000","15.0374","25.0623","8.2309"
"355415.0000","15.0374","25.0623","-4.5778"
"356035.0000","15.0374","25.0623","-48.4857"
"356655.0000","15.0374","25.0623","-88.9611"
"357275.0000","15.0374","25.0623","-122.7120"
"357895.0000","15.0374","25.0623","-145.2706"
"358515.0000","15.0374","25.0623","-154.1549"
"359135.0000","15.0374","25.0623","-157.9684"
"359755.0000","15.0374","25.0623","-161.0506"
"360375.0000","15.0374","25.0623","-162.6376"
"360995.0000","15.0374","25.0623","-163.3153"
"361615.0000","15.0374","25.0623","-163.3104"
"362235.0000","15.0374","25.0623","-163.3658"
"362855.0000","15.0374","25.0623","-162.7713"
"363475.0000","15.0374","25.0623","-167.8421"
"364095.0000","15.0374","25.0623","-171.8910"
"364715.0000","15.0374","25.0623","-173.1057"
"365335.0000","15.0374","25.0623","-164.7913"
"365955.0000","15.0374","25.0623","-156.6143"
"366575.0000","15.0374","25.0623","-167.7003"
"367195.0000","15.0374","25.0623","-174.7633"
"367815.0000","15.0374","25.0623","-177.9109"
"368435.0000","15.0374","25.0623","-169.9931"
"369055.0000","15.0374","25.0623","-158.3871"
"369675.0000","15.0374","25.0623","-149.4318"
"370295.0000","15.0374","25.0623","-141.3674"
"370915.0000","15.0374","25.0623","-133.6774"
"371535.0000","15.0374","25.0623","-125.7321"
"372155.0000","15.0374","25.0623","-117.5412"
"372775.0000","15.0374","25.0623","-108.4845"
"373395.0000","15.0374","25.0623","-98.8734"
"374015.0000","15.0374","25.0623","-89.1117"
"374635.0000","15.0374","25.0623","-78.8939"
"375255.0000","15.0374","25.0623","-65.2025"
"375875.0000","15.0374","25.0623","-38.7628"
"376495.0000","15.0374","25.0623","-15.6861"
"377115.0000","15.0374","25.0623","-3.5221"
"377735.0000","15.0374","25.0623","1.9341"
"378355.0000","15.0374","25.0623","4.5628"
"378975.0000","15.0374","25.0623","5.7232"
"379595.0000","15.0374","25.0623","6.2826"
"380215.0000","15.0374","25.0623","6.6878"
"380835.0000","15.0374","25.0623","7.0289"
"381455.0000","15.0374","25.0623","7.3243"
"382075.0000","15.0374","25.0623","7.5438"
"382695.0000","15.0374","25.0623","7.7021"
"383315.0000","15.0374","25.0623","7.8762"
"383935.0000","15.0374","25.0623","8.0089"
"384555.0000","15.0374","25.0623","8.1213"
"385175.0000","15.0374","25.0623","8.2309"
"385795.0000","15.0374","25.0623","8.3269"
"386385.0000","15.1134","25.1890","8.6382"
"387005.0000","15.3199","25.5331","9.2123"
"387625.0000","15.5267","25.8778","9.7290"
"388245.0000","15.7332","26.2220","10.1216"
"388865.0000","15.9398","26.5663","9.9243"
"389485.0000","16.1465","26.9109","9.9605"
"390105.0000","16.3532","27.2554","10.1101"
"390725.0000","16.5598","27.5996","10.2786"
"391345.0000","16.7666","27.9443","10.4485"
"391965.0000","16.9732","28.2887","10.6290"
"392585.0000","17.1797","28.6328","10.7875"
"393205.0000","17.3867","28.9778","10.9622"
"393825.0000","17.5933","29.3221","11.1400"
"394445.0000","17.7999","29.6665","11.3091"
"395065.0000","18.0064","30.0107","11.4751"
"395685.0000","18.2133","30.3554","11.6513"
"396305.0000","18.4198","30.6996","11.8341"
"396925.0000","18.6264","31.0441","11.9987"
"397545.0000","18.8333","31.3888","12.1734"
"398165.0000","19.0398","31.7330","12.3543"
"398785.0000","19.2466","32.0777","12.5229"
"399405.0000","19.4531","32.4219","12.7095"
"400025.0000","19.6599","32.7665","12.8809"
"400645.0000","19.8665","33.1108","13.0539"
"401220.0000","20.0509","33.4182","13.2005"
"401840.0000","20.0463","33.4104","13.1356"
"402460.0000","20.0451","33.4085","13.1274"
"403080.0000","20.0450","33.4083","13.1071"
"403700.0000","20.0450","33.4083","13.1107"
"404320.0000","20.0450","33.4083","13.0690"
"404940.0000","20.0450","33.4083","13.0600"
"405560.0000","20.0450","33.4083","13.0524"
"406180.0000","20.0450","33.4084","13.0788"
"406800.0000","20.0450","33.4084","13.0724"
"407420.0000","20.0450","33.4084","13.0456"
"408040.0000","20.0450","33.4084","13.0631"
"408660.0000","20.0450","33.4084","13.0525"
"409280.0000","20.0450","33.4084","13.0280"
"409900.0000","20.0450","33.4084","13.0074"
"410520.0000","20.0450","33.4084","6.8223"
"411140.0000","20.0450","33.4084","-7.1956"
"411760.0000","20.0450","33.4084","-16.3627"
"412380.0000","20.0450","33.4084","-18.2501"
"413000.0000","20.0450","33.4084","-17.2516"
"413620.0000","20.0450","33.4084","-13.7026"
"414240.0000","20.0450","33.4084","-10.4260"
"414860.0000","20.0450","33.4084","-7.3523"
"415480.0000","20.0450","33.4084","-25.6778"
"416100.0000","20.0450","33.4084","-55.8658"
"416720.0000","20.0450","33.4084","-94.6821"
"417340.0000","20.0450","33.4084","-126.4538"
"417960.0000","20.0450","33.4084","-142.3099"
"418580.0000","20.0450","33.4084","-146.9433"
"419200.0000","20.0450","33.4084","-142.4799"
"419820.0000","20.0450","33.4084","-129.5500"
"420440.0000","20.0450","33.4084","-115.9918"
"421060.0000","20.0450","33.4084","-133.5637"
"421680.0000","20.0450","33.4084","-145.2961"
"422300.0000","20.0450","33.4084","-152.9003"
"422920.0000","20.0450","33.4084","-141.3450"
"423540.0000","20.0450","33.4084","-127.2192"
"424160.0000","20.0450","33.4084","-113.2555"
"424780.0000","20.0450","33.4084","-128.2798"
"425400.0000","20.0450","33.4084","-132.1648"
"426020.0000","20.0450","33.4084","-143.4588"
"426640.0000","20.0450","33.4084","-152.8106"
"427260.0000","20.0450","33.4084","-149.9740"
"427880.0000","20.0450","33.4084","-153.3104"
"428500.0000","20.0450","33.4084","-140.9809"
"429120.0000","20.0450","33.4084","-127.9482"
"429740.0000","20.0450","33.4084","-134.8178"
"430360.0000","20.0450","33.4084","-143.0054"
"430980.0000","20.0450","33.4084","-129.2671"
"431600.0000","20.0450","33.4084","-115.3895"
"432220.0000","20.0450","33.4084","-102.3953"
"432840.0000","20.0450","33.4084","-90.1890"
"433460.0000","20.0450","33.4084","-61.4700"
"434080.0000","20.0450","33.4084","-29.7957"
"434700.0000","20.0450","33.4084","-8.9747"
"435320.0000","20.0450","33.4084","2.0386"
"435940.0000","20.0450","33.4084","7.4339"
"436560.0000","20.0450","33.4084","11.7798"
"437180.0000","20.0450","33.4084","12.7048"
"437800.0000","20.0450","33.4084","12.8033"
"438420.0000","20.0450","33.4084","12.8313"
"439040.0000","20.0450","33.4084","12.8344"
"439660.0000","20.0450","33.4084","12.8366"
"440280.0000","20.0450","33.4084","12.8561"
"440900.0000","20.0450","33.4084","12.8396"
"441520.0000","20.0450","33.4084","12.8445"
"442140.0000","20.0450","33.4084","12.8546"
"442760.0000","20.0450","33.4084","12.8496"
"443380.0000","20.0450","33.4084","12.8440"
"444000.0000","20.0450","33.4084","12.8462"
"444620.0000","20.0450","33.4084","12.8518"
"445240.0000","20.0450","33.4084","12.8457"
"445860.0000","20.0450","33.4084","12.8541"
"446455.0000","20.1144","33.5240","12.9660"
"447075.0000","20.3209","33.8682","13.1973"
"447695.0000","20.5274","34.2124","13.3917"
"448315.0000","20.7341","34.5568","13.6120"
"448935.0000","20.9408","34.9014","13.8271"
"449555.0000","21.1474","35.2456","13.9883"
"450175.0000","21.3541","35.5902","14.1981"
"450795.0000","21.5607","35.9346","14.4011"
"451415.0000","21.7674","36.2790","14.6010"
"452035.0000","21.9741","36.6236","14.7953"
"452655.0000","22.1808","36.9680","15.0222"
"453275.0000","22.3873","37.3122","15.2215"
"453895.0000","22.5941","37.6569","15.4185"
"454515.0000","22.8010","38.0016","15.6396"
"455135.0000","23.0072","38.3454","15.8619"
"455755.0000","23.2141","38.6902","16.0355"
"456375.0000","23.4209","39.0348","16.2463"
"456995.0000","23.6274","39.3790","16.4704"
"457615.0000","23.8341","39.7235","16.6744"
"458235.0000","24.0409","40.0682","16.8899"
"458855.0000","24.2474","40.4123","17.0927"
"459475.0000","24.4539","40.7565","17.3416"
"460095.0000","24.6609","41.1015","17.5238"
"460715.0000","24.8674","41.4457","17.7621"
"461290.0000","25.0568","41.7613","17.9286"
"461910.0000","25.0539","41.7564","17.8734"
"462530.0000","25.0527","41.7544","17.8484"
"463150.0000","25.0526","41.7543","17.8460"
"463770.0000","25.0526","41.7543","17.8291"
"464390.0000","25.0526","41.7543","17.7985"
"465010.0000","25.0526","41.7543","17.8034"
"465630.0000","25.0526","41.7543","17.8156"
"466250.0000","25.0526","41.7543","17.7955"
"466870.0000","25.0526","41.7543","17.8043"
"467490.0000","25.0526","41.7543","17.7971"
"468110.0000","25.0526","41.7543","17.7679"
"468730.0000","25.0526","41.7543","17.7804"
"469350.0000","25.0526","41.7543","17.7810"
"469970.0000","25.0526","41.7543","17.7568"
"470590.0000","25.0526","41.7543","17.7038"
"471210.0000","25.0526","41.7543","8.7126"
"471830.0000","25.0526","41.7543","-22.9143"
"472450.0000","25.0526","41.7543","-53.7701"
"473070.0000","25.0526","41.7543","-84.9654"
"473690.0000","25.0526","41.7543","-113.6989"
"474310.0000","25.0526","41.7543","-129.0466"
"474930.0000","25.0526","41.7543","-124.9193"
"475550.0000","25.0526","41.7543","-109.9534"
"476170.0000","25.0526","41.7543","-131.6475"
"476790.0000","25.0526","41.7543","-144.3736"
"477410.0000","25.0526","41.7543","-149.3355"
"478030.0000","25.0526","41.7543","-151.7509"
"478650.0000","25.0526","41.7543","-152.6415"
"479270.0000","25.0526","41.7543","-151.8925"
"479890.0000","25.0526","41.7543","-144.0650"
"480510.0000","25.0526","41.7543","-131.6951"
"481130.0000","25.0526","41.7543","-140.6022"
"481750.0000","25.0526","41.7543","-150.0048"
"482370.0000","25.0526","41.7543","-156.8736"
"482990.0000","25.0526","41.7543","-160.1388"
"483610.0000","25.0526","41.7543","-163.1343"
"484230.0000","25.0526","41.7543","-161.5558"
"484850.0000","25.0526","41.7543","-151.2169"
"485470.0000","25.0526","41.7543","-140.8271"
"486090.0000","25.0526","41.7543","-131.4826"
"486710.0000","25.0526","41.7543","-121.8398"
"487330.0000","25.0526","41.7543","-111.1978"
"487950.0000","25.0526","41.7543","-99.8785"
"488570.0000","25.0526","41.7543","-88.6786"
"489190.0000","25.0526","41.7543","-78.1198"
"489810.0000","25.0526","41.7543","-68.4523"
"490430.0000","25.0526","41.7543","-59.7784"
"491050.0000","25.0526","41.7543","-51.8175"
"491670.0000","25.0526","41.7543","-44.5940"
"492290.0000","25.0526","41.7543","-38.0419"
"492910.0000","25.0526","41.7543","-32.1167"
"493530.0000","25.0526","41.7543","-26.7520"
"494150.0000","25.0526","41.7543","-21.8683"
"494770.0000","25.0526","41.7543","-17.4624"
"495390.0000","25.0526","41.7543","-10.8386"
"496010.0000","25.0526","41.7543","0.1418"
"496630.0000","25.0526","41.7543","5.1829"
"497250.0000","25.0526","41.7543","14.9045"
"497870.0000","25.0526","41.7543","17.1992"
"498490.0000","25.0526","41.7543","17.3749"
"499110.0000","25.0526","41.7543","17.4260"
"499730.0000","25.0526","41.7543","17.4574"
"500350.0000","25.0526","41.7543","17.4603"
"500970.0000","25.0526","41.7543","17.4634"
"501590.0000","25.0526","41.7543","17.4744"
"502210.0000","25.0526","41.7543","17.4569"
"502830.0000","25.0526","41.7543","17.4492"
"503450.0000","25.0526","41.7543","17.4587"
"504070.0000","25.0526","41.7543","17.4668"
"504690.0000","25.0526","41.7543","17.4576"
"505310.0000","25.0526","41.7543","17.4616"
"505930.0000","25.0526","41.7543","17.4581"
"506522.0000","25.1155","41.8592","17.5893"
"507142.0000","25.3222","42.2037","17.8475"
"507762.0000","25.5288","42.5481","18.0725"
"508382.0000","25.7353","42.8922","18.3214"
"509002.0000","25.9420","43.2367","18.5396"
"509622.0000","26.1488","43.5813","18.7942"
"510242.0000","26.3554","43.9256","19.0232"
"510862.0000","26.5620","44.2701","19.2453"
"511482.0000","26.7689","44.6148","19.5033"
"512102.0000","26.9752","44.9586","19.7496"
"512722.0000","27.1821","45.3034","19.9982"
"513342.0000","27.3887","45.6478","20.2292"
"513962.0000","27.5955","45.9925","20.4780"
"514582.0000","27.8021","46.3368","20.7359"
"515202.0000","28.0088","46.6814","20.9592"
"515822.0000","28.2153","47.0255","21.2071"
"516442.0000","28.4220","47.3700","21.4723"
"517062.0000","28.6290","47.7150","21.7292"
"517682.0000","28.8352","48.0586","21.9747"
"518302.0000","29.0420","48.4034","22.2510"
"518922.0000","29.2488","48.7480","22.4885"
"519542.0000","29.4553","49.0922","22.7551"
"520162.0000","29.6621","49.4368","23.0101"
"520782.0000","29.8689","49.7815","23.2691"
"521356.0000","30.0598","50.0997","23.5175"
"521976.0000","30.0616","50.1027","23.4319"
"522596.0000","30.0603","50.1005","23.4215"
"523216.0000","30.0602","50.1003","23.4238"
"523836.0000","30.0602","50.1003","23.3998"
"524456.0000","30.0602","50.1003","23.3900"
"525076.0000","30.0602","50.1004","23.3987"
"525696.0000","30.0602","50.1004","23.3860"
"526316.0000","30.0602","50.1004","23.3625"
"526936.0000","30.0602","50.1004","23.3554"
"527556.0000","30.0602","50.1004","23.3474"
"528176.0000","30.0602","50.1004","23.3553"
"528796.0000","30.0602","50.1004","23.3457"
"529416.0000","30.0602","50.1004","23.3317"
"530036.0000","30.0602","50.1004","23.3389"
"530656.0000","30.0602","50.1004","23.3235"
"531276.0000","30.0602","50.1004","23.3236"
"531896.0000","30.0602","50.1004","23.3262"
"532516.0000","30.0602","50.1004","23.3091"
"533136.0000","30.0602","50.1004","23.3109"
"533756.0000","30.0602","50.1004","22.4110"
"534376.0000","30.0602","50.1004","-8.2565"
"534996.0000","30.0602","50.1004","-55.5998"
"535616.0000","30.0602","50.1004","-86.9913"
"536236.0000","30.0602","50.1004","-104.2081"
"536856.0000","30.0602","50.1004","-113.1039"
"537476.0000","30.0602","50.1004","-120.4224"
"538096.0000","30.0602","50.1004","-124.5760"
"538716.0000","30.0602","50.1004","-126.1916"
"539336.0000","30.0602","50.1004","-127.0871"
"539956.0000","30.0602","50.1004","-127.3658"
"540576.0000","30.0602","50.1004","-127.0809"
"541196.0000","30.0602","50.1004","-136.4910"
"541816.0000","30.0602","50.1004","-137.8217"
"542436.0000","30.0602","50.1004","-122.0750"
"543056.0000","30.0602","50.1004","-106.2433"
"543676.0000","30.0602","50.1004","-132.7348"
"544296.0000","30.0602","50.1004","-146.9351"
"544916.0000","30.0602","50.1004","-151.3882"
"545536.0000","30.0602","50.1004","-153.3594"
"546156.0000","30.0602","50.1004","-149.6374"
"546776.0000","30.0602","50.1004","-147.7552"
"547396.0000","30.0602","50.1004","-152.5398"
"548016.0000","30.0602","50.1004","-156.5800"
"548636.0000","30.0602","50.1004","-157.4378"
"549256.0000","30.0602","50.1004","-150.7771"
"549876.0000","30.0602","50.1004","-139.5162"
"550496.0000","30.0602","50.1004","-132.3247"
"551116.0000","30.0602","50.1004","-147.2301"
"551736.0000","30.0602","50.1004","-156.0700"
"552356.0000","30.0602","50.1004","-159.9919"
"552976.0000","30.0602","50.1004","-163.2491"
"553596.0000","30.0602","50.1004","-165.4981"
"554216.0000","30.0602","50.1004","-165.5476"
"554836.0000","30.0602","50.1004","-166.7712"
"555456.0000","30.0602","50.1004","-163.6188"
"556076.0000","30.0602","50.1004","-153.3327"
"556696.0000","30.0602","50.1004","-142.8386"
"557316.0000","30.0602","50.1004","-133.6536"
"557936.0000","30.0602","50.1004","-125.3236"
"558556.0000","30.0602","50.1004","-117.1802"
"559176.0000","30.0602","50.1004","-108.2526"
"559796.0000","30.0602","50.1004","-98.1863"
"560416.0000","30.0602","50.1004","-87.3540"
"561036.0000","30.0602","50.1004","-76.6163"
"561656.0000","30.0602","50.1004","-66.5742"
"562276.0000","30.0602","50.1004","-57.2121"
"562896.0000","30.0602","50.1004","-44.5925"
"563516.0000","30.0602","50.1004","-19.2669"
"564136.0000","30.0602","50.1004","-0.4330"
"564756.0000","30.0602","50.1004","9.7123"
"565376.0000","30.0602","50.1004","16.1841"
"565996.0000","30.0602","50.1004","21.8122"
"566592.0000","30.1165","50.1941","22.8083"
"567212.0000","30.3229","50.5382","23.2357"
"567832.0000","30.5297","50.8828","23.5472"
"568452.0000","30.7364","51.2273","23.8352"
"569072.0000","30.9428","51.5713","24.1182"
"569692.0000","31.1497","51.9162","24.4257"
"570312.0000","31.3563","52.2606","24.7151"
"570932.0000","31.5629","52.6049","25.0079"
"571552.0000","31.7696","52.9493","25.2987"
"572172.0000","31.9764","53.2939","25.5855"
"572792.0000","32.1830","53.6383","25.8925"
"573412.0000","32.3896","53.9826","26.1703"
"574032.0000","32.5964","54.3274","26.4645"
"574652.0000","32.8029","54.6715","26.7688"
"575272.0000","33.0097","55.0161","27.0447"
"575892.0000","33.2163","55.3604","27.3500"
"576512.0000","33.4230","55.7050","27.6567"
"577132.0000","33.6297","56.0495","27.9695"
"577752.0000","33.8363","56.3938","28.2500"
"578372.0000","34.0429","56.7382","28.5597"
"578992.0000","34.2495","57.0825","28.8672"
"579612.0000","34.4564","57.4273","29.1762"
"580232.0000","34.6629","57.7715","29.4968"
"580852.0000","34.8696","58.1160","29.8437"
"581426.0000","35.0610","58.4350","30.1105"
"582046.0000","35.0693","58.4489","30.0388"
"582666.0000","35.0679","58.4465","30.0350"
"583286.0000","35.0678","58.4463","30.0009"
"583906.0000","35.0678","58.4463","30.0091"
"584526.0000","35.0678","58.4463","29.9962"
"585146.0000","35.0678","58.4463","29.9842"
"585766.0000","35.0678","58.4463","29.9589"
"586386.0000","35.0678","58.4463","29.9455"
"587006.0000","35.0678","58.4463","29.9373"
"587626.0000","35.0678","58.4463","29.9715"
"588246.0000","35.0678","58.4463","29.9272"
"588866.0000","35.0678","58.4463","29.9374"
"589486.0000","35.0678","58.4463","29.9317"
"590106.0000","35.0678","58.4463","29.9204"
"590726.0000","35.0678","58.4463","29.9113"
"591346.0000","35.0678","58.4463","29.9153"
"591966.0000","35.0678","58.4463","29.9082"
"592586.0000","35.0678","58.4463","29.8839"
"593206.0000","35.0678","58.4463","29.8779"
"593826.0000","35.0678","58.4463","29.8887"
"594446.0000","35.0678","58.4463","27.0087"
"595066.0000","35.0678","58.4463","-1.6446"
"595686.0000","35.0678","58.4463","-28.5809"
"596306.0000","35.0678","58.4463","-52.5904"
"596926.0000","35.0678","58.4463","-76.7534"
"597546.0000","35.0678","58.4463","-93.2413"
"598166.0000","35.0678","58.4463","-102.1670"
"598786.0000","35.0678","58.4463","-107.9201"
"599406.0000","35.0678","58.4463","-111.5221"
"600026.0000","35.0678","58.4463","-127.0479"
"600646.0000","35.0678","58.4463","-136.5921"
"601266.0000","35.0678","58.4463","-129.6131"
"601886.0000","35.0678","58.4463","-135.0268"
"602506.0000","35.0678","58.4463","-140.9179"
"603126.0000","35.0678","58.4463","-144.3311"
"603746.0000","35.0678","58.4463","-145.6655"
"604366.0000","35.0678","58.4463","-151.1828"
"604986.0000","35.0678","58.4463","-156.7736"
"605606.0000","35.0678","58.4463","-160.8303"
"606226.0000","35.0678","58.4463","-157.3562"
"606846.0000","35.0678","58.4463","-160.9017"
"607466.0000","35.0678","58.4463","-164.9013"
"608086.0000","35.0678","58.4463","-163.8154"
"608706.0000","35.0678","58.4463","-168.0491"
"609326.0000","35.0678","58.4463","-162.1256"
"609946.0000","35.0678","58.4463","-164.5953"
"610566.0000","35.0678","58.4463","-150.8334"
"611186.0000","35.0678","58.4463","-147.0140"
"611806.0000","35.0678","58.4463","-150.6733"
"612426.0000","35.0678","58.4463","-139.2747"
"613046.0000","35.0678","58.4463","-129.8978"
"613666.0000","35.0678","58.4463","-121.5381"
"614286.0000","35.0678","58.4463","-113.8191"
"614906.0000","35.0678","58.4463","-106.4457"
"615526.0000","35.0678","58.4463","-98.7348"
"616146.0000","35.0678","58.4463","-90.8017"
"616766.0000","35.0678","58.4463","-82.8057"
"617386.0000","35.0678","58.4463","-75.1451"
"618006.0000","35.0678","58.4463","-68.1064"
"618626.0000","35.0678","58.4463","-61.6792"
"619246.0000","35.0678","58.4463","-55.7081"
"619866.0000","35.0678","58.4463","-49.8613"
"620486.0000","35.0678","58.4463","-43.7863"
"621106.0000","35.0678","58.4463","-32.4240"
"621726.0000","35.0678","58.4463","-11.8380"
"622346.0000","35.0678","58.4463","4.6953"
"622966.0000","35.0678","58.4463","15.1724"
"623586.0000","35.0678","58.4463","21.1096"
"624206.0000","35.0678","58.4463","24.1626"
"624826.0000","35.0678","58.4463","25.7896"
"625446.0000","35.0678","58.4463","26.4572"
"626066.0000","35.0678","58.4463","28.9502"
"626653.0000","35.1172","58.5287","29.3572"
"627273.0000","35.3237","58.8729","29.7234"
"627893.0000","35.5305","59.2175","30.0872"
"628513.0000","35.7372","59.5620","30.4313"
"629133.0000","35.9436","59.9060","30.7685"
"629753.0000","36.1504","60.2507","31.1205"
"630373.0000","36.3571","60.5951","31.4642"
"630993.0000","36.5638","60.9396","31.8086"
"631613.0000","36.7704","61.2840","32.1309"
"632233.0000","36.9772","61.6287","32.4919"
"632853.0000","37.1837","61.9728","32.8264"
"633473.0000","37.3903","62.3172","33.1847"
"634093.0000","37.5972","62.6620","33.5335"
"634713.0000","37.8037","63.0062","33.9174"
"635333.0000","38.0105","63.3509","34.2330"
"635953.0000","38.2170","63.6949","34.5925"
"636573.0000","38.4238","64.0397","34.9724"
"637193.0000","38.6304","64.3840","35.3306"
"637813.0000","38.8371","64.7286","35.6870"
"638433.0000","39.0438","65.0729","36.0601"
"639053.0000","39.2503","65.4172","36.4306"
"639673.0000","39.4571","65.7619","36.7889"
"640293.0000","39.6637","66.1061","37.1650"
"640913.0000","39.8704","66.4507","37.5393"
"641507.0000","40.0684","66.7806","37.8529"
"642108.0000","40.0772","66.7954","37.7853"
"642728.0000","40.0757","66.7929","37.7545"
"643348.0000","40.0755","66.7926","37.7311"
"643968.0000","40.0755","66.7926","37.7153"
"644588.0000","40.0756","66.7926","37.6882"
"645208.0000","40.0756","66.7926","37.6786"
"645828.0000","40.0756","66.7926","37.6595"
"646448.0000","40.0756","66.7926","37.6634"
"647068.0000","40.0756","66.7926","37.6457"
"647688.0000","40.0756","66.7926","37.6472"
"648308.0000","40.0756","66.7926","37.6334"
"648928.0000","40.0756","66.7926","37.6282"
"649548.0000","40.0756","66.7926","37.6385"
"650168.0000","40.0756","66.7926","37.6250"
"650788.0000","40.0756","66.7926","37.6247"
"651408.0000","40.0756","66.7926","37.5940"
"652028.0000","40.0756","66.7926","37.5770"
"652648.0000","40.0756","66.7926","34.5219"
"653268.0000","40.0756","66.7926","13.1217"
"653888.0000","40.0756","66.7926","-11.1975"
"654508.0000","40.0756","66.7926","-39.4775"
"655128.0000","40.0756","66.7926","-68.4154"
"655748.0000","40.0756","66.7926","-68.0501"
"656368.0000","40.0756","66.7926","-80.4230"
"656988.0000","40.0756","66.7926","-99.1779"
"657608.0000","40.0756","66.7926","-110.7088"
"658228.0000","40.0756","66.7926","-117.7309"
"658848.0000","40.0756","66.7926","-120.7010"
"659468.0000","40.0756","66.7926","-122.3181"
"660088.0000","40.0756","66.7926","-128.5633"
"660708.0000","40.0756","66.7926","-129.1260"
"661328.0000","40.0756","66.7926","-127.2947"
"661948.0000","40.0756","66.7926","-126.4034"
"662568.0000","40.0756","66.7926","-128.0697"
"663188.0000","40.0756","66.7926","-120.0164"
"663808.0000","40.0756","66.7926","-113.7216"
"664428.0000","40.0756","66.7926","-125.2653"
"665048.0000","40.0756","66.7926","-136.9600"
"665668.0000","40.0756","66.7926","-121.4996"
"666288.0000","40.0756","66.7926","-102.7677"
"666908.0000","40.0756","66.7926","-88.5543"
"667528.0000","40.0756","66.7926","-77.7163"
"668148.0000","40.0756","66.7926","-58.1089"
"668768.0000","40.0756","66.7926","-38.8460"
"669388.0000","40.0756","66.7926","-25.3870"
"670008.0000","40.0756","66.7926","-15.7811"
"670628.0000","40.0756","66.7926","-8.1540"
"671248.0000","40.0756","66.7926","-1.9684"
"671868.0000","40.0756","66.7926","3.4429"
"672488.0000","40.0756","66.7926","8.7753"
"673108.0000","40.0756","66.7926","15.1101"
"673728.0000","40.0756","66.7926","22.5002"
"674348.0000","40.0756","66.7926","28.8994"
"674968.0000","40.0756","66.7926","32.7989"
"675588.0000","40.0756","66.7926","34.5817"
"676208.0000","40.0756","66.7926","35.4841"
"676828.0000","40.0756","66.7926","35.8920"
"677448.0000","40.0756","66.7926","36.0594"
"678068.0000","40.0756","66.7926","36.1547"
"678688.0000","40.0756","66.7926","36.2581"
"679308.0000","40.0756","66.7926","36.2795"
"679928.0000","40.0756","66.7926","36.3280"
"680548.0000","40.0756","66.7926","36.3773"
"681168.0000","40.0756","66.7926","36.3955"
"681788.0000","40.0756","66.7926","36.4384"
"682408.0000","40.0756","66.7926","36.4639"
"683028.0000","40.0756","66.7926","36.4964"
"683648.0000","40.0756","66.7926","36.5090"
"684268.0000","40.0756","66.7926","36.5003"
"684888.0000","40.0756","66.7926","36.5223"
"685508.0000","40.0756","66.7926","36.5454"
"686128.0000","40.0756","66.7926","36.5426"
"686507.0000","40.0756","66.7926","36.5669"