File: data/four_circular_test/FourCircular-10mm_to_40mm_1.csv
Time,Displacement,Tensile strain (Displacement),Force
(ms),(mm),(%),(N)
"0.0000","0.0299","0.0498","0.0016"
"620.0000","0.0344","0.0574","-0.0869"
"1240.0000","0.0335","0.0558","-0.0793"
"1860.0000","0.0333","0.0554","-0.0738"
"2480.0000","0.0332","0.0554","-0.0776"
"3100.0000","0.0332","0.0553","-0.0739"
"3720.0000","0.0332","0.0553","-0.0944"
"4340.0000","0.0332","0.0553","-0.0750"
"4960.0000","0.0332","0.0554","-0.0719"
"5580.0000","0.0332","0.0554","-0.0861"
"6200.0000","0.0332","0.0554","-0.0742"
"6820.0000","0.0332","0.0554","-0.0759"
"7440.0000","0.0332","0.0554","-0.0841"
"8060.0000","0.0332","0.0554","-0.0725"
"8680.0000","0.0332","0.0554","-0.0810"
"9300.0000","0.0332","0.0554","-0.0926"
"9920.0000","0.0332","0.0554","-0.0814"
"10502.0000","-0.1111","-0.1851","-0.2961"
"11122.0000","-0.3173","-0.5288","-0.4358"
"11742.0000","-0.5243","-0.8738","-0.5606"
"12362.0000","-0.7308","-1.2180","-0.6876"
"12982.0000","-0.9374","-1.5623","-0.8480"
"13602.0000","-1.1441","-1.9069","-0.9734"
"14222.0000","-1.3509","-2.2516","-1.1194"
"14842.0000","-1.5575","-2.5958","-1.2464"
"15462.0000","-1.7640","-2.9401","-1.3901"
"16082.0000","-1.9710","-3.2850","-1.4947"
"16702.0000","-2.1772","-3.6287","-1.6408"
"17322.0000","-2.3844","-3.9739","-1.7692"
"17942.0000","-2.5908","-4.3180","-1.9015"
"18562.0000","-2.7974","-4.6623","-2.0298"
"19182.0000","-3.0042","-5.0069","-2.1853"
"19802.0000","-3.2109","-5.3514","-2.3039"
"20422.0000","-3.4174","-5.6957","-2.4427"
"21042.0000","-3.6240","-6.0400","-2.5925"
"21662.0000","-3.8311","-6.3851","-2.7433"
"22282.0000","-4.0372","-6.7287","-2.8724"
"22902.0000","-4.2441","-7.0735","-3.0408"
"23522.0000","-4.4509","-7.4181","-3.2043"
"24142.0000","-4.6575","-7.7624","-3.3576"
"24762.0000","-4.8641","-8.1068","-3.5387"
"25382.0000","-5.0708","-8.4513","-3.7305"
"26002.0000","-5.2776","-8.7960","-3.9100"
"26622.0000","-5.4840","-9.1399","-4.1075"
"27242.0000","-5.6909","-9.4849","-4.3230"
"27862.0000","-5.8974","-9.8290","-4.5125"
"28482.0000","-6.1042","-10.1737","-4.7528"
"29102.0000","-6.3108","-10.5180","-4.9696"
"29722.0000","-6.5174","-10.8623","-5.2070"
"30342.0000","-6.7242","-11.2070","-5.4766"
"30962.0000","-6.9309","-11.5514","-5.7425"
"31582.0000","-7.1374","-11.8957","-6.0061"
"32202.0000","-7.3440","-12.2401","-6.2837"
"32822.0000","-7.5510","-12.5849","-6.5696"
"33442.0000","-7.7574","-12.9290","-6.8882"
"34062.0000","-7.9642","-13.2737","-7.1997"
"34682.0000","-8.1707","-13.6178","-7.5270"
"35302.0000","-8.3775","-13.9625","-7.8530"
"35922.0000","-8.5841","-14.3069","-8.1652"
"36542.0000","-8.7908","-14.6513","-8.5166"
"37162.0000","-8.9975","-14.9959","-8.8688"
"37782.0000","-9.2041","-15.3402","-9.2292"
"38402.0000","-9.4108","-15.6846","-9.5888"
"39022.0000","-9.6173","-16.0288","-9.9463"
"39642.0000","-9.8244","-16.3740","-10.3289"
"40213.0000","-10.0057","-16.6761","-10.6019"
"40833.0000","-10.0012","-16.6686","-10.4951"
"41453.0000","-10.0001","-16.6668","-10.4807"
"42073.0000","-10.0000","-16.6666","-10.4520"
"42693.0000","-10.0000","-16.6666","-10.4531"
"43313.0000","-10.0000","-16.6666","-10.4282"
"43933.0000","-10.0000","-16.6666","-10.4454"
"44553.0000","-10.0000","-16.6666","-10.4134"
"45173.0000","-10.0000","-16.6666","-10.4235"
"45793.0000","-10.0000","-16.6667","-10.4181"
"46413.0000","-10.0000","-16.6667","-10.4115"
"47033.0000","-10.0000","-16.6667","-10.3966"
"47653.0000","-10.0000","-16.6667","-10.4027"
"48273.0000","-10.0000","-16.6667","-10.3843"
"48893.0000","-10.0000","-16.6667","-10.4092"
"49513.0000","-10.0000","-16.6667","-10.4331"
"50133.0000","-10.0000","-16.6667","-10.4002"
"50753.0000","-10.0000","-16.6667","-10.3930"
"51373.0000","-10.0000","-16.6667","-10.3961"
"51993.0000","-10.0000","-16.6667","-10.4006"
"52613.0000","-10.0000","-16.6667","-10.4006"
"53233.0000","-10.0000","-16.6667","-10.3882"
"53853.0000","-10.0000","-16.6667","-10.3736"
"54473.0000","-10.0000","-16.6667","-10.4049"
"55093.0000","-10.0000","-16.6667","-10.3887"
"55713.0000","-10.0000","-16.6667","-10.3883"
"56333.0000","-10.0000","-16.6667","-10.3425"
"56953.0000","-10.0000","-16.6667","-10.3923"
"57573.0000","-10.0000","-16.6667","-10.3612"
"58193.0000","-10.0000","-16.6667","-10.3541"
"58813.0000","-10.0000","-16.6667","-10.3644"
"59433.0000","-10.0000","-16.6667","-10.3554"
"60053.0000","-10.0000","-16.6667","-10.3601"
"60673.0000","-10.0000","-16.6667","-68.1055"
"61293.0000","-10.0000","-16.6666","-154.5231"
"61913.0000","-10.0000","-16.6666","-197.4215"
"62533.0000","-10.0000","-16.6666","-210.3061"
"63153.0000","-10.0000","-16.6667","-204.9077"
"63773.0000","-10.0000","-16.6667","-192.6095"
"64393.0000","-10.0000","-16.6667","-181.0143"
"65013.0000","-10.0000","-16.6667","-170.6164"
"65633.0000","-10.0000","-16.6667","-161.4697"
"66253.0000","-10.0000","-16.6667","-152.8769"
"66873.0000","-10.0000","-16.6667","-139.4170"
"67493.0000","-10.0000","-16.6667","-112.6513"
"68113.0000","-10.0000","-16.6667","-79.2700"
"68733.0000","-10.0000","-16.6667","-46.0066"
"69353.0000","-10.0000","-16.6667","-30.2679"
"69973.0000","-10.0000","-16.6667","-20.7819"
"70593.0000","-10.0000","-16.6667","-15.7929"
"71213.0000","-10.0000","-16.6667","-11.9699"
"71833.0000","-10.0000","-16.6667","-9.2541"
"72453.0000","-10.0000","-16.6667","-9.1774"
"73073.0000","-10.0000","-16.6667","-9.1610"
"73693.0000","-10.0000","-16.6667","-9.1594"
"74313.0000","-10.0000","-16.6667","-9.1633"
"74933.0000","-10.0000","-16.6667","-9.1830"
"75553.0000","-10.0000","-16.6667","-9.1394"
"76173.0000","-10.0000","-16.6667","-9.1828"
"76793.0000","-10.0000","-16.6667","-9.1667"
"77413.0000","-10.0000","-16.6667","-9.1780"
"78033.0000","-10.0000","-16.6667","-9.1680"
"78653.0000","-10.0000","-16.6667","-9.1650"
"79273.0000","-10.0000","-16.6667","-9.1881"
"79893.0000","-10.0000","-16.6667","-9.1791"
"80513.0000","-10.0000","-16.6667","-9.1801"
"81133.0000","-10.0000","-16.6667","-9.1838"
"81753.0000","-10.0000","-16.6667","-9.1642"
"82373.0000","-10.0000","-16.6667","-9.1886"
"82993.0000","-10.0000","-16.6667","-9.1857"
"83613.0000","-10.0000","-16.6667","-9.1899"
"84233.0000","-10.0000","-16.6667","-9.1856"
"84853.0000","-10.0000","-16.6667","-9.1905"
"85451.0000","-9.9274","-16.5457","-8.9365"
"86071.0000","-9.7210","-16.2016","-8.5485"
"86691.0000","-9.5144","-15.8573","-8.1927"
"87311.0000","-9.3076","-15.5127","-7.8669"
"87931.0000","-9.1010","-15.1683","-7.5696"
"88551.0000","-8.8941","-14.8235","-7.2366"
"89171.0000","-8.6877","-14.4796","-6.9536"
"89791.0000","-8.4810","-14.1350","-6.6681"
"90411.0000","-8.2742","-13.7903","-6.3486"
"91031.0000","-8.0677","-13.4462","-6.0924"
"91651.0000","-7.8610","-13.1016","-5.7823"
"92271.0000","-7.6543","-12.7572","-5.5271"
"92891.0000","-7.4476","-12.4126","-5.2745"
"93511.0000","-7.2411","-12.0685","-5.0181"
"94131.0000","-7.0341","-11.7236","-4.7746"
"94751.0000","-6.8276","-11.3793","-4.5447"
"95371.0000","-6.6211","-11.0351","-4.2689"
"95991.0000","-6.4143","-10.6905","-4.0958"
"96611.0000","-6.2075","-10.3459","-3.8672"
"97231.0000","-6.0010","-10.0016","-3.6554"
"97851.0000","-5.7943","-9.6572","-3.4835"
"98471.0000","-5.5875","-9.3126","-3.2945"
"99091.0000","-5.3811","-8.9685","-3.0824"
"99711.0000","-5.1743","-8.6238","-2.9128"
"100276.0000","-4.9882","-8.3137","-2.7886"
"100896.0000","-4.9912","-8.3186","-2.8969"
"101516.0000","-4.9923","-8.3206","-2.8720"
"102136.0000","-4.9925","-8.3208","-2.9239"
"102756.0000","-4.9925","-8.3208","-2.9373"
"103376.0000","-4.9925","-8.3208","-2.9566"
"103996.0000","-4.9925","-8.3208","-2.9411"
"104616.0000","-4.9925","-8.3208","-2.9154"
"105236.0000","-4.9925","-8.3208","-2.9233"
"105856.0000","-4.9925","-8.3208","-2.9296"
"106476.0000","-4.9925","-8.3208","-2.9335"
"107096.0000","-4.9925","-8.3208","-2.8936"
"107716.0000","-4.9925","-8.3208","-2.9635"
"108336.0000","-4.9925","-8.3208","-2.9704"
"108956.0000","-4.9925","-8.3208","-2.9861"
"109576.0000","-4.9925","-8.3208","-12.7972"
"110196.0000","-4.9925","-8.3208","-40.2487"
"110816.0000","-4.9925","-8.3208","-76.3742"
"111436.0000","-4.9925","-8.3208","-126.1067"
"112056.0000","-4.9924","-8.3207","-166.4631"
"112676.0000","-4.9925","-8.3208","-179.9344"
"113296.0000","-4.9925","-8.3208","-188.6542"
"113916.0000","-4.9925","-8.3208","-198.3054"
"114536.0000","-4.9925","-8.3208","-201.2961"
"115156.0000","-4.9925","-8.3208","-213.0549"
"115776.0000","-4.9925","-8.3208","-198.0519"
"116396.0000","-4.9925","-8.3208","-182.6690"
"117016.0000","-4.9925","-8.3208","-173.6458"
"117636.0000","-4.9925","-8.3208","-181.8070"
"118256.0000","-4.9925","-8.3208","-188.4898"
"118876.0000","-4.9925","-8.3208","-194.4718"
"119496.0000","-4.9925","-8.3208","-190.3631"
"120116.0000","-4.9925","-8.3208","-180.6522"
"120736.0000","-4.9925","-8.3208","-172.9242"
"121356.0000","-4.9925","-8.3208","-166.7753"
"121976.0000","-4.9925","-8.3208","-161.4955"
"122596.0000","-4.9925","-8.3208","-154.6692"
"123216.0000","-4.9925","-8.3208","-146.6740"
"123836.0000","-4.9925","-8.3208","-138.9498"
"124456.0000","-4.9925","-8.3208","-130.5737"
"125076.0000","-4.9925","-8.3208","-121.5478"
"125696.0000","-4.9925","-8.3208","-112.2326"
"126316.0000","-4.9925","-8.3208","-102.8738"
"126936.0000","-4.9925","-8.3208","-93.0568"
"127556.0000","-4.9925","-8.3208","-75.6537"
"128176.0000","-4.9925","-8.3208","-49.7981"
"128796.0000","-4.9925","-8.3208","-28.6284"
"129416.0000","-4.9925","-8.3208","-16.2625"
"130036.0000","-4.9925","-8.3208","-11.5192"
"130656.0000","-4.9925","-8.3208","-10.0454"
"131276.0000","-4.9925","-8.3208","-9.0800"
"131896.0000","-4.9925","-8.3208","-8.0473"
"132516.0000","-4.9925","-8.3208","-7.2207"
"133136.0000","-4.9925","-8.3208","-6.4868"
"133756.0000","-4.9925","-8.3208","-5.8854"
"134376.0000","-4.9925","-8.3208","-3.9407"
"134996.0000","-4.9925","-8.3208","-3.1438"
"135616.0000","-4.9925","-8.3208","-3.1127"
"136236.0000","-4.9925","-8.3208","-3.1017"
"136856.0000","-4.9925","-8.3208","-3.1185"
"137476.0000","-4.9925","-8.3208","-3.0902"
"138096.0000","-4.9925","-8.3208","-3.1110"
"138716.0000","-4.9925","-8.3208","-3.1125"
"139336.0000","-4.9925","-8.3208","-3.0888"
"139956.0000","-4.9925","-8.3208","-3.1068"
"140576.0000","-4.9925","-8.3208","-3.0958"
"141196.0000","-4.9925","-8.3208","-3.1040"
"141816.0000","-4.9925","-8.3208","-3.0855"
"142436.0000","-4.9925","-8.3208","-3.0963"
"143056.0000","-4.9925","-8.3208","-3.0969"
"143676.0000","-4.9925","-8.3208","-3.0694"
"144296.0000","-4.9925","-8.3208","-3.0851"
"144916.0000","-4.9925","-8.3208","-3.1104"
"145510.0000","-4.9229","-8.2048","-2.9119"
"146130.0000","-4.7164","-7.8607","-2.7258"
"146750.0000","-4.5099","-7.5165","-2.5611"
"147370.0000","-4.3031","-7.1718","-2.3712"
"147990.0000","-4.0964","-6.8273","-2.2189"
"148610.0000","-3.8897","-6.4828","-2.0575"
"149230.0000","-3.6832","-6.1387","-1.8966"
"149850.0000","-3.4766","-5.7943","-1.7470"
"150470.0000","-3.2698","-5.4496","-1.5894"
"151090.0000","-3.0631","-5.1052","-1.4583"
"151710.0000","-2.8565","-4.7608","-1.2925"
"152330.0000","-2.6498","-4.4163","-1.1783"
"152950.0000","-2.4430","-4.0717","-1.0385"
"153570.0000","-2.2365","-3.7276","-0.8929"
"154190.0000","-2.0298","-3.3830","-0.7515"
"154810.0000","-1.8231","-3.0384","-0.6481"
"155430.0000","-1.6164","-2.6941","-0.5231"
"156050.0000","-1.4099","-2.3499","-0.3976"
"156670.0000","-1.2030","-2.0051","-0.2766"
"157290.0000","-0.9965","-1.6608","-0.1544"
"157910.0000","-0.7898","-1.3164","-0.0385"
"158530.0000","-0.5832","-0.9719","0.0935"
"159150.0000","-0.3765","-0.6274","0.1908"
"159770.0000","-0.1698","-0.2830","0.3297"
"160344.0000","0.0193","0.0321","0.4234"
"160964.0000","0.0163","0.0272","0.3273"
"161584.0000","0.0151","0.0252","0.3111"
"162204.0000","0.0150","0.0250","0.2933"
"162824.0000","0.0150","0.0250","0.2870"
"163444.0000","0.0150","0.0250","0.2937"
"164064.0000","0.0150","0.0250","0.2926"
"164684.0000","0.0150","0.0250","0.2882"
"165304.0000","0.0150","0.0250","0.2741"
"165924.0000","0.0150","0.0250","0.2763"
"166544.0000","0.0150","0.0250","0.2706"
"167164.0000","0.0150","0.0250","0.2883"
"167784.0000","0.0150","0.0250","0.2744"
"168404.0000","0.0150","0.0250","0.2683"
"169024.0000","0.0150","0.0250","0.2598"
"169644.0000","0.0150","0.0250","0.2531"
"170264.0000","0.0150","0.0250","0.2404"
"170884.0000","0.0150","0.0250","-2.3488"
"171504.0000","0.0150","0.0250","-43.0343"
"172124.0000","0.0150","0.0251","-99.1316"
"172744.0000","0.0150","0.0251","-157.4630"
"173364.0000","0.0150","0.0251","-171.7450"
"173984.0000","0.0150","0.0250","-180.6800"
"174604.0000","0.0150","0.0250","-185.0619"
"175224.0000","0.0150","0.0250","-185.2656"
"175844.0000","0.0150","0.0250","-185.0033"
"176464.0000","0.0150","0.0250","-189.4383"
"177084.0000","0.0150","0.0250","-188.9141"
"177704.0000","0.0150","0.0250","-182.2426"
"178324.0000","0.0150","0.0250","-179.3002"
"178944.0000","0.0150","0.0250","-188.7848"
"179564.0000","0.0150","0.0250","-194.4691"
"180184.0000","0.0150","0.0250","-205.0753"
"180804.0000","0.0150","0.0250","-216.1933"
"181424.0000","0.0150","0.0250","-220.5556"
"182044.0000","0.0150","0.0250","-211.2531"
"182664.0000","0.0150","0.0250","-200.3607"
"183284.0000","0.0150","0.0250","-189.1367"
"183904.0000","0.0150","0.0250","-179.2587"
"184524.0000","0.0150","0.0250","-170.6755"
"185144.0000","0.0150","0.0250","-162.9751"
"185764.0000","0.0150","0.0250","-155.9424"
"186384.0000","0.0150","0.0250","-149.2952"
"187004.0000","0.0150","0.0250","-142.4262"
"187624.0000","0.0150","0.0250","-134.6138"
"188244.0000","0.0150","0.0250","-125.1848"
"188864.0000","0.0150","0.0250","-104.8946"
"189484.0000","0.0150","0.0250","-78.2719"
"190104.0000","0.0150","0.0250","-46.8646"
"190724.0000","0.0150","0.0250","-26.9328"
"191344.0000","0.0150","0.0250","-17.2642"
"191964.0000","0.0150","0.0250","-12.7641"
"192584.0000","0.0150","0.0250","-8.4284"
"193204.0000","0.0150","0.0250","-6.0233"
"193824.0000","0.0150","0.0250","-4.7154"
"194444.0000","0.0150","0.0250","-4.0355"
"195064.0000","0.0150","0.0250","-3.3958"
"195684.0000","0.0150","0.0250","-2.8339"
"196304.0000","0.0150","0.0250","-2.3390"
"196924.0000","0.0150","0.0250","-1.9259"
"197544.0000","0.0150","0.0250","-1.6232"
"198164.0000","0.0150","0.0250","-1.3768"
"198784.0000","0.0150","0.0250","-0.9894"
"199404.0000","0.0150","0.0250","0.0562"
"200024.0000","0.0150","0.0250","0.0945"
"200644.0000","0.0150","0.0250","0.1250"
"201264.0000","0.0150","0.0250","0.1033"
"201884.0000","0.0150","0.0250","0.1059"
"202504.0000","0.0150","0.0250","0.1154"
"203124.0000","0.0150","0.0250","0.1187"
"203744.0000","0.0150","0.0250","0.1098"
"204364.0000","0.0150","0.0250","0.1075"
"204984.0000","0.0150","0.0250","0.0867"
"205568.0000","0.0781","0.1302","0.2563"
"206188.0000","0.2843","0.4738","0.3925"
"206808.0000","0.4910","0.8183","0.5343"
"207428.0000","0.6977","1.1629","0.6497"
"208048.0000","0.9044","1.5073","0.7983"
"208668.0000","1.1110","1.8516","0.8973"
"209288.0000","1.3176","2.1960","1.0098"
"209908.0000","1.5243","2.5405","1.1628"
"210528.0000","1.7310","2.8849","1.2849"
"211148.0000","1.9377","3.2296","1.4214"
"211768.0000","2.1443","3.5739","1.5276"
"212388.0000","2.3509","3.9181","1.6564"
"213008.0000","2.5576","4.2627","1.7677"
"213628.0000","2.7643","4.6071","1.9007"
"214248.0000","2.9708","4.9514","2.0190"
"214868.0000","3.1778","5.2964","2.1537"
"215488.0000","3.3844","5.6407","2.2536"
"216108.0000","3.5908","5.9847","2.3738"
"216728.0000","3.7976","6.3293","2.4842"
"217348.0000","4.0043","6.6739","2.5992"
"217968.0000","4.2111","7.0184","2.7394"
"218588.0000","4.4176","7.3626","2.8664"
"219208.0000","4.6244","7.7074","2.9473"
"219828.0000","4.8309","8.0515","3.0825"
"220402.0000","5.0221","8.3702","3.1616"
"221022.0000","5.0239","8.3732","3.0802"
"221642.0000","5.0226","8.3709","3.0612"
"222262.0000","5.0224","8.3707","3.0868"
"222882.0000","5.0225","8.3708","3.0860"
"223502.0000","5.0225","8.3708","3.0604"
"224122.0000","5.0225","8.3708","3.0461"
"224742.0000","5.0225","8.3708","3.0523"
"225362.0000","5.0225","8.3708","3.0438"
"225982.0000","5.0225","8.3708","3.0402"
"226602.0000","5.0225","8.3708","3.0502"
"227222.0000","5.0225","8.3708","3.0430"
"227842.0000","5.0225","8.3708","3.0218"
"228462.0000","5.0225","8.3708","3.0302"
"229082.0000","5.0225","8.3708","3.0200"
"229702.0000","5.0225","8.3708","3.0461"
"230322.0000","5.0225","8.3708","2.9928"
"230942.0000","5.0225","8.3708","-6.7137"
"231562.0000","5.0225","8.3708","-38.5805"
"232182.0000","5.0225","8.3708","-79.2506"
"232802.0000","5.0225","8.3708","-103.4739"
"233422.0000","5.0225","8.3708","-133.5968"
"234042.0000","5.0225","8.3708","-162.3416"
"234662.0000","5.0225","8.3708","-174.9310"
"235282.0000","5.0225","8.3708","-181.5301"
"235902.0000","5.0225","8.3708","-191.5391"
"236522.0000","5.0225","8.3708","-193.2337"
"237142.0000","5.0225","8.3708","-188.3835"
"237762.0000","5.0225","8.3708","-198.8490"
"238382.0000","5.0225","8.3708","-189.7664"
"239002.0000","5.0225","8.3708","-180.8364"
"239622.0000","5.0225","8.3708","-188.0685"
"240242.0000","5.0225","8.3708","-193.4680"
"240862.0000","5.0225","8.3708","-191.1122"
"241482.0000","5.0225","8.3708","-202.2186"
"242102.0000","5.0225","8.3708","-205.9854"
"242722.0000","5.0225","8.3708","-209.7294"
"243342.0000","5.0225","8.3708","-208.1240"
"243962.0000","5.0225","8.3708","-209.7763"
"244582.0000","5.0225","8.3708","-196.1628"
"245202.0000","5.0225","8.3708","-185.7021"
"245822.0000","5.0225","8.3708","-176.9535"
"246442.0000","5.0225","8.3708","-169.0658"
"247062.0000","5.0225","8.3708","-162.5623"
"247682.0000","5.0225","8.3708","-156.6073"
"248302.0000","5.0225","8.3708","-150.7228"
"248922.0000","5.0225","8.3708","-144.4020"
"249542.0000","5.0225","8.3708","-137.6015"
"250162.0000","5.0225","8.3708","-130.3038"
"250782.0000","5.0225","8.3708","-122.6079"
"251402.0000","5.0225","8.3708","-114.1837"
"252022.0000","5.0225","8.3708","-105.2002"
"252642.0000","5.0225","8.3708","-85.0697"
"253262.0000","5.0225","8.3708","-48.9073"
"253882.0000","5.0225","8.3708","-23.1969"
"254502.0000","5.0225","8.3708","-9.7998"
"255122.0000","5.0225","8.3708","-3.9543"
"255742.0000","5.0225","8.3708","-0.0887"
"256362.0000","5.0225","8.3708","2.5874"
"256982.0000","5.0225","8.3708","2.8270"
"257602.0000","5.0225","8.3708","2.8678"
"258222.0000","5.0225","8.3708","2.8758"
"258842.0000","5.0225","8.3708","2.8926"
"259462.0000","5.0225","8.3708","2.8893"
"260082.0000","5.0225","8.3708","2.8777"
"260702.0000","5.0225","8.3708","2.8706"
"261322.0000","5.0225","8.3708","2.8764"
"261942.0000","5.0225","8.3708","2.9034"
"262562.0000","5.0225","8.3708","2.8701"
"263182.0000","5.0225","8.3708","2.8754"
"263802.0000","5.0225","8.3708","2.8912"
"264422.0000","5.0225","8.3708","2.8837"
"265042.0000","5.0225","8.3708","2.8728"
"265625.0000","5.0787","8.4645","3.0137"
"266245.0000","5.2851","8.8086","3.1542"
"266865.0000","5.4917","9.1529","3.2907"
"267485.0000","5.6982","9.4970","3.4393"
"268105.0000","5.9051","9.8419","3.5589"
"268725.0000","6.1117","10.1862","3.7073"
"269345.0000","6.3181","10.5302","3.8226"
"269965.0000","6.5250","10.8749","3.9527"
"270585.0000","6.7317","11.2195","4.0744"
"271205.0000","6.9383","11.5638","4.2086"
"271825.0000","7.1450","11.9083","4.3156"
"272445.0000","7.3516","12.2527","4.4455"
"273065.0000","7.5582","12.5970","4.5772"
"273685.0000","7.7651","12.9418","4.6914"
"274305.0000","7.9717","13.2862","4.8335"
"274925.0000","8.1783","13.6304","4.9574"
"275545.0000","8.3850","13.9751","5.0857"
"276165.0000","8.5916","14.3194","5.2186"
"276785.0000","8.7981","14.6635","5.3345"
"277405.0000","9.0051","15.0085","5.4795"
"278025.0000","9.2119","15.3531","5.5943"
"278645.0000","9.4182","15.6969","5.7371"
"279265.0000","9.6250","16.0417","5.8639"
"279885.0000","9.8316","16.3860","5.9988"
"280460.0000","10.0235","16.7058","6.1206"
"281080.0000","10.0317","16.7195","6.0270"
"281700.0000","10.0303","16.7171","6.0197"
"282320.0000","10.0301","16.7169","6.0148"
"282940.0000","10.0301","16.7169","6.0098"
"283560.0000","10.0301","16.7169","5.9678"
"284180.0000","10.0301","16.7169","5.9703"
"284800.0000","10.0301","16.7169","5.9352"
"285420.0000","10.0302","16.7169","5.9455"
"286040.0000","10.0302","16.7169","5.9557"
"286660.0000","10.0302","16.7169","5.9634"
"287280.0000","10.0302","16.7169","5.9413"
"287900.0000","10.0302","16.7169","5.9436"
"288520.0000","10.0302","16.7169","-19.6298"
"289140.0000","10.0302","16.7169","-61.4073"
"289760.0000","10.0302","16.7169","-104.4883"
"290380.0000","10.0302","16.7169","-129.1167"
"291000.0000","10.0302","16.7169","-154.4870"
"291620.0000","10.0302","16.7169","-173.7924"
"292240.0000","10.0302","16.7169","-169.4998"
"292860.0000","10.0302","16.7169","-180.7348"
"293480.0000","10.0302","16.7169","-178.9544"
"294100.0000","10.0302","16.7169","-188.2469"
"294720.0000","10.0302","16.7169","-195.5923"
"295340.0000","10.0302","16.7169","-196.6836"
"295960.0000","10.0302","16.7169","-200.2423"
"296580.0000","10.0302","16.7169","-189.2526"
"297200.0000","10.0302","16.7169","-199.8062"
"297820.0000","10.0302","16.7169","-202.8102"
"298440.0000","10.0302","16.7169","-190.4776"
"299060.0000","10.0302","16.7169","-181.0590"
"299680.0000","10.0302","16.7169","-172.7279"
"300300.0000","10.0302","16.7169","-165.9244"
"300920.0000","10.0302","16.7169","-159.6758"
"301540.0000","10.0302","16.7169","-153.4890"
"302160.0000","10.0302","16.7169","-147.2140"
"302780.0000","10.0302","16.7169","-140.6523"
"303400.0000","10.0302","16.7169","-133.8940"
"304020.0000","10.0302","16.7169","-126.8703"
"304640.0000","10.0302","16.7169","-119.7302"
"305260.0000","10.0302","16.7169","-112.0284"
"305880.0000","10.0302","16.7169","-103.7855"
"306500.0000","10.0302","16.7169","-95.0411"
"307120.0000","10.0302","16.7169","-86.2206"
"307740.0000","10.0302","16.7169","-77.8239"
"308360.0000","10.0302","16.7169","-69.8587"
"308980.0000","10.0302","16.7169","-62.3204"
"309600.0000","10.0302","16.7169","-55.2673"
"310220.0000","10.0302","16.7169","-48.6547"
"310840.0000","10.0302","16.7169","-42.5620"
"311460.0000","10.0302","16.7169","-37.0000"
"312080.0000","10.0302","16.7169","-31.9222"
"312700.0000","10.0302","16.7169","-13.8940"
"313320.0000","10.0302","16.7169","0.1560"
"313940.0000","10.0302","16.7169","4.7965"
"314560.0000","10.0302","16.7169","5.6243"
"315180.0000","10.0302","16.7169","5.7505"
"315800.0000","10.0302","16.7169","5.7771"
"316420.0000","10.0302","16.7169","5.7820"
"317040.0000","10.0302","16.7169","5.8119"
"317660.0000","10.0302","16.7169","5.8200"
"318280.0000","10.0302","16.7169","5.8254"
"318900.0000","10.0302","16.7169","5.8294"
"319520.0000","10.0302","16.7169","5.8364"
"320140.0000","10.0302","16.7169","5.8321"
"320760.0000","10.0302","16.7169","5.8077"
"321380.0000","10.0302","16.7169","5.8146"
"322000.0000","10.0302","16.7169","5.8204"
"322620.0000","10.0302","16.7169","5.8314"
"323240.0000","10.0302","16.7169","5.8328"
"323860.0000","10.0302","16.7169","5.8164"
"324480.0000","10.0302","16.7169","5.8155"
"325100.0000","10.0302","16.7169","5.8308"
"325683.0000","10.0797","16.7995","5.9192"
"326303.0000","10.2859","17.1432","6.1085"
"326923.0000","10.4928","17.4880","6.2400"
"327543.0000","10.6992","17.8321","6.4019"
"328163.0000","10.9060","18.1766","6.5220"
"328783.0000","11.1127","18.5212","6.6870"
"329403.0000","11.3194","18.8656","6.8212"
"330023.0000","11.5258","19.2097","6.9723"
"330643.0000","11.7327","19.5545","7.0932"
"331263.0000","11.9393","19.8988","7.2258"
"331883.0000","12.1459","20.2432","7.3974"
"332503.0000","12.3526","20.5877","7.5435"
"333123.0000","12.5594","20.9323","7.6976"
"333743.0000","12.7659","21.2766","7.8444"
"334363.0000","12.9726","21.6210","7.9886"
"334983.0000","13.1795","21.9658","8.1232"
"335603.0000","13.3859","22.3098","8.2856"
"336223.0000","13.5927","22.6544","8.4376"
"336843.0000","13.7993","22.9988","8.5789"
"337463.0000","14.0060","23.3433","8.7264"
"338083.0000","14.2127","23.6878","8.8947"
"338703.0000","14.4194","24.0323","9.0536"
"339323.0000","14.6259","24.3765","9.2095"
"339943.0000","14.8326","24.7210","9.3569"
"340536.0000","15.0305","25.0508","9.5349"
"341137.0000","15.0391","25.0652","9.4194"
"341757.0000","15.0376","25.0627","9.4221"
"342377.0000","15.0374","25.0624","9.4065"
"342997.0000","15.0374","25.0624","9.4059"
"343617.0000","15.0374","25.0624","9.4046"
"344237.0000","15.0375","25.0624","9.4112"
"344857.0000","15.0375","25.0624","9.3958"
"345477.0000","15.0375","25.0624","9.3928"
"346097.0000","15.0375","25.0624","9.3779"
"346717.0000","15.0375","25.0624","9.3813"
"347337.0000","15.0375","25.0624","9.3935"
"347957.0000","15.0375","25.0624","9.3941"
"348577.0000","15.0375","25.0624","9.3850"
"349197.0000","15.0375","25.0624","9.3819"
"349817.0000","15.0375","25.0624","9.3752"
"350437.0000","15.0375","25.0624","9.3720"
"351057.0000","15.0375","25.0624","9.3550"
"351677.0000","15.0375","25.0624","9.3687"
"352297.0000","15.0375","25.0624","9.3736"
"352917.0000","15.0375","25.0624","9.3790"
"353537.0000","15.0375","25.0624","9.3541"
"354157.0000","15.0375","25.0624","9.3734"
"354777.0000","15.0375","25.0624","9.3788"
"355397.0000","15.0375","25.0624","9.3617"
"356017.0000","15.0375","25.0624","9.3447"
"356637.0000","15.0375","25.0624","9.3521"
"357257.0000","15.0375","25.0624","9.3706"
"357877.0000","15.0375","25.0624","9.3484"
"358497.0000","15.0375","25.0624","9.3405"
"359117.0000","15.0375","25.0624","9.3429"
"359737.0000","15.0375","25.0624","9.2277"
"360357.0000","15.0375","25.0625","-20.8092"
"360977.0000","15.0375","25.0625","-66.2789"
"361597.0000","15.0375","25.0625","-123.1365"
"362217.0000","15.0375","25.0625","-153.3176"
"362837.0000","15.0375","25.0625","-165.8614"
"363457.0000","15.0375","25.0625","-176.3374"
"364077.0000","15.0375","25.0625","-184.7321"
"364697.0000","15.0375","25.0625","-192.6775"
"365317.0000","15.0375","25.0625","-201.8421"
"365937.0000","15.0375","25.0625","-211.8061"
"366557.0000","15.0375","25.0625","-220.8736"
"367177.0000","15.0375","25.0625","-223.4530"
"367797.0000","15.0375","25.0625","-210.3481"
"368417.0000","15.0375","25.0625","-196.4831"
"369037.0000","15.0375","25.0625","-185.0507"
"369657.0000","15.0375","25.0625","-175.7634"
"370277.0000","15.0375","25.0625","-167.8794"
"370897.0000","15.0375","25.0625","-161.0903"
"371517.0000","15.0375","25.0625","-154.7814"
"372137.0000","15.0375","25.0624","-148.6313"
"372757.0000","15.0375","25.0624","-142.4617"
"373377.0000","15.0375","25.0624","-136.2203"
"373997.0000","15.0375","25.0624","-129.5106"
"374617.0000","15.0375","25.0624","-122.4737"
"375237.0000","15.0375","25.0624","-114.5184"
"375857.0000","15.0375","25.0624","-105.9314"
"376477.0000","15.0375","25.0624","-97.1127"
"377097.0000","15.0375","25.0624","-88.3672"
"377717.0000","15.0375","25.0624","-79.8918"
"378337.0000","15.0375","25.0624","-71.7605"
"378957.0000","15.0375","25.0624","-64.0062"
"379577.0000","15.0375","25.0624","-56.6653"
"380197.0000","15.0375","25.0624","-49.8318"
"380817.0000","15.0375","25.0624","-43.4464"
"381437.0000","15.0375","25.0624","-37.5610"
"382057.0000","15.0375","25.0624","-32.2050"
"382677.0000","15.0375","25.0624","-17.0082"
"383297.0000","15.0375","25.0624","0.3911"
"383917.0000","15.0375","25.0624","7.1681"
"384537.0000","15.0375","25.0624","8.8139"
"385157.0000","15.0375","25.0624","8.9992"
"385740.0000","15.0802","25.1337","9.1777"
"386360.0000","15.2866","25.4776","9.4007"
"386980.0000","15.4932","25.8221","9.5858"
"387600.0000","15.6999","26.1665","9.7743"
"388220.0000","15.9066","26.5110","9.9465"
"388840.0000","16.1133","26.8555","10.0954"
"389460.0000","16.3200","27.1999","10.2801"
"390080.0000","16.5264","27.5440","10.4485"
"390700.0000","16.7331","27.8886","10.6138"
"391320.0000","16.9399","28.2332","10.7866"
"391940.0000","17.1467","28.5778","10.9769"
"392560.0000","17.3531","28.9218","11.1336"
"393180.0000","17.5599","29.2665","11.3126"
"393800.0000","17.7665","29.6109","11.4842"
"394420.0000","17.9732","29.9553","11.6389"
"395040.0000","18.1799","30.2999","11.8158"
"395660.0000","18.3867","30.6444","12.0042"
"396280.0000","18.5932","30.9886","12.1790"
"396900.0000","18.7998","31.3330","12.3729"
"397520.0000","19.0066","31.6777","12.5178"
"398140.0000","19.2131","32.0219","12.7326"
"398760.0000","19.4200","32.3667","12.8861"
"399380.0000","19.6266","32.7110","13.0848"
"400000.0000","19.8332","33.0553","13.2694"
"400613.0000","20.0376","33.3961","13.4608"
"401195.0000","20.0468","33.4114","13.3779"
"401815.0000","20.0452","33.4087","13.3800"
"402435.0000","20.0450","33.4084","13.3780"
"403055.0000","20.0450","33.4084","13.3408"
"403675.0000","20.0450","33.4084","13.3496"
"404295.0000","20.0450","33.4084","13.3433"
"404915.0000","20.0450","33.4084","13.3253"
"405535.0000","20.0450","33.4084","13.3311"
"406155.0000","20.0450","33.4084","13.3374"
"406775.0000","20.0450","33.4084","13.2967"
"407395.0000","20.0450","33.4084","13.2955"
"408015.0000","20.0450","33.4084","13.2906"
"408635.0000","20.0450","33.4084","13.2934"
"409255.0000","20.0450","33.4084","12.5950"
"409875.0000","20.0451","33.4084","-47.6980"
"410495.0000","20.0451","33.4084","-85.5118"
"411115.0000","20.0451","33.4084","-100.0905"
"411735.0000","20.0451","33.4084","-86.5070"
"412355.0000","20.0451","33.4084","-75.1627"
"412975.0000","20.0451","33.4084","-65.4061"
"413595.0000","20.0451","33.4084","-56.7881"
"414215.0000","20.0450","33.4084","-49.1587"
"414835.0000","20.0450","33.4084","-65.9337"
"415455.0000","20.0451","33.4084","-112.9481"
"416075.0000","20.0451","33.4084","-153.3716"
"416695.0000","20.0451","33.4084","-170.3492"
"417315.0000","20.0451","33.4084","-177.1004"
"417935.0000","20.0451","33.4084","-186.4547"
"418555.0000","20.0451","33.4084","-195.1350"
"419175.0000","20.0451","33.4084","-199.0814"
"419795.0000","20.0451","33.4084","-195.9881"
"420415.0000","20.0451","33.4084","-189.4010"
"421035.0000","20.0451","33.4084","-188.2590"
"421655.0000","20.0451","33.4084","-186.5239"
"422275.0000","20.0451","33.4084","-190.3365"
"422895.0000","20.0451","33.4084","-183.4685"
"423515.0000","20.0451","33.4084","-187.7326"
"424135.0000","20.0451","33.4084","-177.0210"
"424755.0000","20.0451","33.4084","-168.1822"
"425375.0000","20.0451","33.4084","-170.6140"
"425995.0000","20.0451","33.4084","-162.1032"
"426615.0000","20.0450","33.4084","-159.7372"
"427235.0000","20.0450","33.4084","-159.3563"
"427855.0000","20.0450","33.4084","-170.5575"
"428475.0000","20.0451","33.4084","-187.5390"
"429095.0000","20.0451","33.4084","-204.2098"
"429715.0000","20.0451","33.4084","-212.3814"
"430335.0000","20.0451","33.4084","-217.9516"
"430955.0000","20.0451","33.4084","-202.0411"
"431575.0000","20.0451","33.4084","-188.5302"
"432195.0000","20.0451","33.4084","-177.5784"
"432815.0000","20.0450","33.4084","-168.5574"
"433435.0000","20.0450","33.4084","-160.7806"
"434055.0000","20.0450","33.4084","-153.5916"
"434675.0000","20.0450","33.4084","-146.4207"
"435295.0000","20.0450","33.4084","-135.2320"
"435915.0000","20.0450","33.4084","-123.5040"
"436535.0000","20.0450","33.4084","-107.0510"
"437155.0000","20.0450","33.4084","-84.9291"
"437775.0000","20.0450","33.4084","-58.3635"
"438395.0000","20.0450","33.4084","-30.2848"
"439015.0000","20.0450","33.4084","-9.9557"
"439635.0000","20.0450","33.4084","0.4770"
"440255.0000","20.0450","33.4084","6.2723"
"440875.0000","20.0450","33.4084","12.0211"
"441495.0000","20.0450","33.4084","12.8592"
"442115.0000","20.0450","33.4084","12.9407"
"442735.0000","20.0450","33.4084","12.9731"
"443355.0000","20.0450","33.4084","12.9988"
"443975.0000","20.0450","33.4084","13.0098"
"444595.0000","20.0450","33.4084","13.0332"
"445215.0000","20.0450","33.4084","13.0031"
"445803.0000","20.0812","33.4687","13.0950"
"446423.0000","20.2874","33.8124","13.3166"
"447043.0000","20.4940","34.1566","13.5243"
"447663.0000","20.7009","34.5015","13.7407"
"448283.0000","20.9075","34.8458","13.9268"
"448903.0000","21.1141","35.1902","14.1244"
"449523.0000","21.3207","35.5346","14.3211"
"450143.0000","21.5273","35.8789","14.5215"
"450763.0000","21.7340","36.2233","14.7266"
"451383.0000","21.9408","36.5680","14.9302"
"452003.0000","22.1475","36.9125","15.1285"
"452623.0000","22.3540","37.2567","15.3390"
"453243.0000","22.5607","37.6011","15.5210"
"453863.0000","22.7674","37.9457","15.7493"
"454483.0000","22.9741","38.2902","15.9533"
"455103.0000","23.1807","38.6345","16.1347"
"455723.0000","23.3875","38.9792","16.3636"
"456343.0000","23.5940","39.3234","16.5863"
"456963.0000","23.8006","39.6677","16.7926"
"457583.0000","24.0073","40.0122","17.0039"
"458203.0000","24.2141","40.3567","17.2278"
"458823.0000","24.4209","40.7014","17.4351"
"459443.0000","24.6273","41.0455","17.6760"
"460063.0000","24.8341","41.3902","17.8816"
"460683.0000","25.0407","41.7345","18.0996"
"461258.0000","25.0543","41.7572","18.0336"
"461878.0000","25.0527","41.7545","18.0008"
"462498.0000","25.0525","41.7542","18.0133"
"463118.0000","25.0525","41.7542","17.9914"
"463738.0000","25.0525","41.7542","17.9980"
"464358.0000","25.0526","41.7543","17.9900"
"464978.0000","25.0526","41.7543","17.9998"
"465598.0000","25.0526","41.7543","18.0128"
"466218.0000","25.0526","41.7543","17.9852"
"466838.0000","25.0526","41.7543","17.9796"
"467458.0000","25.0526","41.7543","17.9646"
"468078.0000","25.0526","41.7543","17.9549"
"468698.0000","25.0526","41.7543","17.9287"
"469318.0000","25.0526","41.7543","17.9433"
"469938.0000","25.0526","41.7543","17.9422"
"470558.0000","25.0526","41.7543","17.8791"
"471178.0000","25.0526","41.7543","17.8839"
"471798.0000","25.0526","41.7543","17.8782"
"472418.0000","25.0526","41.7543","17.8548"
"473038.0000","25.0526","41.7543","17.9042"
"473658.0000","25.0526","41.7543","17.9116"
"474278.0000","25.0526","41.7543","-4.7575"
"474898.0000","25.0526","41.7543","-74.5179"
"475518.0000","25.0526","41.7543","-124.3585"
"476138.0000","25.0526","41.7543","-135.4880"
"476758.0000","25.0526","41.7543","-146.4656"
"477378.0000","25.0526","41.7543","-150.1033"
"477998.0000","25.0526","41.7543","-155.4071"
"478618.0000","25.0526","41.7543","-162.0452"
"479238.0000","25.0526","41.7543","-164.1557"
"479858.0000","25.0526","41.7543","-169.7676"
"480478.0000","25.0526","41.7543","-175.3122"
"481098.0000","25.0526","41.7543","-180.3054"
"481718.0000","25.0526","41.7543","-184.6332"
"482338.0000","25.0526","41.7543","-184.5350"
"482958.0000","25.0526","41.7543","-184.0907"
"483578.0000","25.0526","41.7543","-180.9946"
"484198.0000","25.0526","41.7543","-173.1574"
"484818.0000","25.0526","41.7543","-166.8095"
"485438.0000","25.0526","41.7543","-161.0182"
"486058.0000","25.0526","41.7543","-163.1592"
"486678.0000","25.0526","41.7543","-168.1625"
"487298.0000","25.0526","41.7543","-175.7321"
"487918.0000","25.0526","41.7543","-183.4917"
"488538.0000","25.0526","41.7543","-188.8140"
"489158.0000","25.0526","41.7543","-192.2308"
"489778.0000","25.0526","41.7543","-195.6124"
"490398.0000","25.0526","41.7543","-200.9590"
"491018.0000","25.0526","41.7543","-203.0369"
"491638.0000","25.0526","41.7543","-189.3298"
"492258.0000","25.0526","41.7543","-175.9856"
"492878.0000","25.0526","41.7543","-165.1159"
"493498.0000","25.0526","41.7543","-154.2451"
"494118.0000","25.0526","41.7543","-141.2349"
"494738.0000","25.0526","41.7543","-129.4391"
"495358.0000","25.0526","41.7543","-117.3985"
"495978.0000","25.0526","41.7543","-100.6097"
"496598.0000","25.0526","41.7543","-75.8434"
"497218.0000","25.0526","41.7543","-47.6598"
"497838.0000","25.0526","41.7543","-21.4203"
"498458.0000","25.0526","41.7543","-3.4565"
"499078.0000","25.0526","41.7543","5.1172"
"499698.0000","25.0526","41.7543","8.7656"
"500318.0000","25.0526","41.7543","10.2101"
"500938.0000","25.0526","41.7543","11.0893"
"501558.0000","25.0526","41.7543","11.9332"
"502178.0000","25.0526","41.7543","12.7498"
"502798.0000","25.0526","41.7543","13.4524"
"503418.0000","25.0526","41.7543","14.1080"
"504038.0000","25.0526","41.7543","17.3165"
"504658.0000","25.0526","41.7543","17.6710"
"505278.0000","25.0526","41.7543","17.7077"
"505862.0000","25.0824","41.8039","17.7614"
"506482.0000","25.2888","42.1480","18.0136"
"507102.0000","25.4954","42.4923","18.2348"
"507722.0000","25.7020","42.8366","18.5048"
"508342.0000","25.9087","43.1812","18.7256"
"508962.0000","26.1154","43.5257","18.9529"
"509582.0000","26.3219","43.8699","19.2067"
"510202.0000","26.5288","44.2146","19.4516"
"510822.0000","26.7353","44.5589","19.6839"
"511442.0000","26.9419","44.9032","19.9065"
"512062.0000","27.1488","45.2480","20.1680"
"512682.0000","27.3553","45.5922","20.4036"
"513302.0000","27.5619","45.9365","20.6494"
"513922.0000","27.7687","46.2812","20.8891"
"514542.0000","27.9755","46.6259","21.1333"
"515162.0000","28.1819","46.9698","21.4120"
"515782.0000","28.3888","47.3147","21.6403"
"516402.0000","28.5953","47.6589","21.9115"
"517022.0000","28.8019","48.0032","22.1627"
"517642.0000","29.0086","48.3477","22.4060"
"518262.0000","29.2155","48.6926","22.6648"
"518882.0000","29.4220","49.0367","22.9161"
"519502.0000","29.6286","49.3810","23.1954"
"520122.0000","29.8353","49.7256","23.4772"
"520742.0000","30.0419","50.0698","23.7072"
"521316.0000","30.0621","50.1035","23.6611"
"521936.0000","30.0604","50.1006","23.6371"
"522556.0000","30.0602","50.1003","23.6403"
"523176.0000","30.0602","50.1003","23.6248"
"523796.0000","30.0602","50.1003","23.5990"
"524416.0000","30.0602","50.1003","23.6078"
"525036.0000","30.0602","50.1003","23.5850"
"525656.0000","30.0602","50.1003","23.5423"
"526276.0000","30.0602","50.1003","23.5597"
"526896.0000","30.0602","50.1003","23.5535"
"527516.0000","30.0602","50.1003","23.5688"
"528136.0000","30.0602","50.1003","23.5675"
"528756.0000","30.0602","50.1003","23.5510"
"529376.0000","30.0602","50.1003","23.5436"
"529996.0000","30.0602","50.1003","23.5394"
"530616.0000","30.0602","50.1003","23.5526"
"531236.0000","30.0602","50.1003","23.5533"
"531856.0000","30.0602","50.1003","23.5331"
"532476.0000","30.0602","50.1003","23.5288"
"533096.0000","30.0602","50.1003","23.5096"
"533716.0000","30.0602","50.1003","23.5045"
"534336.0000","30.0602","50.1003","20.7977"
"534956.0000","30.0602","50.1003","-2.1978"
"535576.0000","30.0602","50.1003","-32.6021"
"536196.0000","30.0602","50.1003","-61.4076"
"536816.0000","30.0602","50.1003","-77.8263"
"537436.0000","30.0602","50.1003","-85.6726"
"538056.0000","30.0602","50.1003","-84.5794"
"538676.0000","30.0602","50.1003","-83.4623"
"539296.0000","30.0602","50.1003","-80.2109"
"539916.0000","30.0602","50.1003","-79.3583"
"540536.0000","30.0602","50.1003","-122.2428"
"541156.0000","30.0602","50.1003","-145.8981"
"541776.0000","30.0602","50.1003","-155.0816"
"542396.0000","30.0602","50.1003","-158.7957"
"543016.0000","30.0602","50.1003","-155.0034"
"543636.0000","30.0602","50.1003","-145.2030"
"544256.0000","30.0602","50.1003","-153.3666"
"544876.0000","30.0602","50.1003","-164.2101"
"545496.0000","30.0602","50.1003","-168.4322"
"546116.0000","30.0602","50.1003","-175.0112"
"546736.0000","30.0602","50.1003","-180.7307"
"547356.0000","30.0602","50.1003","-186.0135"
"547976.0000","30.0602","50.1003","-189.7936"
"548596.0000","30.0602","50.1003","-188.9300"
"549216.0000","30.0602","50.1003","-193.1307"
"549836.0000","30.0602","50.1003","-189.0293"
"550456.0000","30.0602","50.1003","-194.7307"
"551076.0000","30.0602","50.1003","-198.3056"
"551696.0000","30.0602","50.1003","-200.9055"
"552316.0000","30.0602","50.1003","-200.5233"
"552936.0000","30.0602","50.1003","-202.9208"
"553556.0000","30.0602","50.1003","-204.2601"
"554176.0000","30.0602","50.1003","-205.6236"
"554796.0000","30.0602","50.1003","-198.4108"
"555416.0000","30.0602","50.1003","-184.5836"
"556036.0000","30.0602","50.1003","-172.3683"
"556656.0000","30.0602","50.1003","-162.0049"
"557276.0000","30.0602","50.1003","-153.1432"
"557896.0000","30.0602","50.1003","-145.4020"
"558516.0000","30.0602","50.1003","-138.4346"
"559136.0000","30.0602","50.1003","-131.8813"
"559756.0000","30.0602","50.1003","-125.7501"
"560376.0000","30.0602","50.1003","-119.1772"
"560996.0000","30.0602","50.1003","-111.6066"
"561616.0000","30.0602","50.1003","-102.8572"
"562236.0000","30.0602","50.1003","-93.1457"
"562856.0000","30.0602","50.1003","-82.8936"
"563476.0000","30.0602","50.1003","-71.7439"
"564096.0000","30.0602","50.1003","-59.2849"
"564716.0000","30.0602","50.1003","-43.3634"
"565336.0000","30.0602","50.1003","-22.2223"
"565936.0000","30.0901","50.1501","-5.0777"
"566556.0000","30.2962","50.4936","5.1318"
"567176.0000","30.5029","50.8381","11.8230"
"567796.0000","30.7096","51.1826","15.5448"
"568416.0000","30.9161","51.5268","17.6457"
"569036.0000","31.1230","51.8716","19.0633"
"569656.0000","31.3296","52.2160","20.3147"
"570276.0000","31.5362","52.5603","21.4521"
"570896.0000","31.7427","52.9045","22.5148"
"571516.0000","31.9496","53.2493","23.4149"
"572136.0000","32.1561","53.5935","25.7755"
"572756.0000","32.3630","53.9383","26.2271"
"573376.0000","32.5695","54.2825","26.5145"
"573996.0000","32.7762","54.6269","26.8275"
"574616.0000","32.9829","54.9715","27.1355"
"575236.0000","33.1895","55.3159","27.4466"
"575856.0000","33.3962","55.6604","27.7794"
"576476.0000","33.6028","56.0047","28.0779"
"577096.0000","33.8097","56.3495","28.3634"
"577716.0000","34.0161","56.6936","28.6877"
"578336.0000","34.2229","57.0381","29.0087"
"578956.0000","34.4297","57.3828","29.2971"
"579576.0000","34.6361","57.7268","29.6345"
"580196.0000","34.8428","58.0713","29.9596"
"580816.0000","35.0496","58.4160","30.2756"
"581390.0000","35.0697","58.4495","30.2433"
"582010.0000","35.0679","58.4465","30.2181"
"582630.0000","35.0677","58.4461","30.2163"
"583250.0000","35.0677","58.4461","30.1897"
"583870.0000","35.0677","58.4461","30.1967"
"584490.0000","35.0677","58.4461","30.1747"
"585110.0000","35.0677","58.4461","30.1692"
"585730.0000","35.0677","58.4462","30.1622"
"586350.0000","35.0677","58.4462","30.1403"
"586970.0000","35.0677","58.4462","30.1496"
"587590.0000","35.0677","58.4462","30.1605"
"588210.0000","35.0677","58.4462","30.1435"
"588830.0000","35.0677","58.4462","30.1264"
"589450.0000","35.0677","58.4462","30.1435"
"590070.0000","35.0677","58.4462","30.1459"
"590690.0000","35.0677","58.4462","30.0999"
"591310.0000","35.0677","58.4462","30.0953"
"591930.0000","35.0677","58.4462","30.0805"
"592550.0000","35.0677","58.4462","30.0890"
"593170.0000","35.0677","58.4462","30.0948"
"593790.0000","35.0677","58.4462","30.0862"
"594410.0000","35.0677","58.4462","30.0436"
"595030.0000","35.0677","58.4462","30.0607"
"595650.0000","35.0677","58.4462","30.0564"
"596270.0000","35.0677","58.4462","30.0437"
"596890.0000","35.0677","58.4462","20.4300"
"597510.0000","35.0677","58.4462","11.2968"
"598130.0000","35.0677","58.4462","-31.6495"
"598750.0000","35.0677","58.4462","-88.2546"
"599370.0000","35.0677","58.4462","-121.9285"
"599990.0000","35.0677","58.4462","-140.5792"
"600610.0000","35.0677","58.4462","-146.8729"
"601230.0000","35.0677","58.4462","-152.5047"
"601850.0000","35.0677","58.4462","-152.3752"
"602470.0000","35.0677","58.4462","-152.0425"
"603090.0000","35.0677","58.4462","-158.9789"
"603710.0000","35.0677","58.4462","-164.7641"
"604330.0000","35.0677","58.4462","-169.5369"
"604950.0000","35.0677","58.4462","-174.4076"
"605570.0000","35.0677","58.4462","-182.9190"
"606190.0000","35.0677","58.4462","-183.1982"
"606810.0000","35.0677","58.4462","-191.4788"
"607430.0000","35.0677","58.4462","-201.5433"
"608050.0000","35.0677","58.4462","-207.3015"
"608670.0000","35.0677","58.4462","-213.1581"
"609290.0000","35.0677","58.4462","-218.4418"
"609910.0000","35.0677","58.4462","-198.9582"
"610530.0000","35.0677","58.4462","-179.2122"
"611150.0000","35.0677","58.4462","-164.5023"
"611770.0000","35.0677","58.4462","-153.0952"
"612390.0000","35.0677","58.4462","-137.6899"
"613010.0000","35.0677","58.4462","-122.1326"
"613630.0000","35.0677","58.4462","-107.7650"
"614250.0000","35.0677","58.4462","-91.8862"
"614870.0000","35.0677","58.4462","-72.0005"
"615490.0000","35.0677","58.4462","-50.4325"
"616110.0000","35.0677","58.4462","-29.4456"
"616730.0000","35.0677","58.4462","-9.0181"
"617350.0000","35.0677","58.4462","6.3493"
"617970.0000","35.0677","58.4462","17.0336"
"618590.0000","35.0677","58.4462","23.6353"
"619210.0000","35.0677","58.4462","27.0764"
"619830.0000","35.0677","58.4462","28.1512"
"620450.0000","35.0677","58.4462","28.5018"
"621070.0000","35.0677","58.4462","28.5990"
"621690.0000","35.0677","58.4462","28.6106"
"622310.0000","35.0677","58.4462","28.6281"
"622930.0000","35.0677","58.4462","28.6373"
"623550.0000","35.0677","58.4462","28.6876"
"624170.0000","35.0677","58.4462","28.7315"
"624790.0000","35.0677","58.4462","28.9068"
"625410.0000","35.0677","58.4462","29.1864"
"626010.0000","35.0975","58.4958","29.2574"
"626630.0000","35.3035","58.8392","29.6500"
"627250.0000","35.5103","59.1838","29.9918"
"627870.0000","35.7170","59.5283","30.3225"
"628490.0000","35.9235","59.8725","30.6745"
"629110.0000","36.1303","60.2172","31.0427"
"629730.0000","36.3370","60.5617","31.3729"
"630350.0000","36.5437","60.9061","31.7132"
"630970.0000","36.7501","61.2502","32.0583"
"631590.0000","36.9571","61.5952","32.4044"
"632210.0000","37.1636","61.9394","32.7719"
"632830.0000","37.3704","62.2840","33.1127"
"633450.0000","37.5770","62.6284","33.4573"
"634070.0000","37.7836","62.9727","33.8187"
"634690.0000","37.9903","63.3171","34.1820"
"635310.0000","38.1970","63.6616","34.5315"
"635930.0000","38.4037","64.0062","34.9125"
"636550.0000","38.6103","64.3505","35.2694"
"637170.0000","38.8171","64.6952","35.6345"
"637790.0000","39.0236","65.0393","36.0037"
"638410.0000","39.2303","65.3838","36.1014"
"639030.0000","39.4370","65.7283","37.5294"
"639650.0000","39.6437","66.0729","38.2776"
"640270.0000","39.8502","66.4170","41.4095"
"640890.0000","40.0570","66.7616","39.6143"
"641465.0000","40.0775","66.7958","42.5330"
"642085.0000","40.0757","66.7928","42.5084"
"642705.0000","40.0755","66.7924","37.5219"
"643325.0000","40.0754","66.7924","37.4859"
"643945.0000","40.0755","66.7924","37.4550"
"644565.0000","40.0755","66.7924","37.4440"
"645185.0000","40.0755","66.7924","37.4441"
"645805.0000","40.0755","66.7924","37.4301"
"646425.0000","40.0755","66.7925","37.4380"
"647045.0000","40.0755","66.7925","37.4439"
"647665.0000","40.0755","66.7925","37.4316"
"648285.0000","40.0755","66.7925","37.4326"
"648905.0000","40.0755","66.7925","37.4148"
"649525.0000","40.0755","66.7925","37.4032"
"650145.0000","40.0755","66.7925","37.4020"
"650765.0000","40.0755","66.7925","37.4084"
"651385.0000","40.0755","66.7925","37.3938"
"652005.0000","40.0755","66.7925","37.3805"
"652625.0000","40.0755","66.7925","37.3909"
"653245.0000","40.0755","66.7925","37.3671"
"653865.0000","40.0755","66.7925","37.3563"
"654485.0000","40.0755","66.7925","37.3314"
"655105.0000","40.0755","66.7925","37.3556"
"655725.0000","40.0755","66.7925","37.3334"
"656345.0000","40.0755","66.7925","37.3157"
"656965.0000","40.0755","66.7925","37.3251"
"657585.0000","40.0755","66.7925","37.3148"
"658205.0000","40.0755","66.7925","37.3207"
"658825.0000","40.0755","66.7925","37.2982"
"659445.0000","40.0755","66.7925","30.7931"
"660065.0000","40.0755","66.7925","-13.6529"
"660685.0000","40.0755","66.7925","-82.3086"
"661305.0000","40.0755","66.7925","-112.1748"
"661925.0000","40.0755","66.7925","-133.9429"
"662545.0000","40.0755","66.7925","-141.2787"
"663165.0000","40.0755","66.7925","-145.7972"
"663785.0000","40.0755","66.7925","-147.9963"
"664405.0000","40.0755","66.7925","-152.2780"
"665025.0000","40.0755","66.7925","-155.8619"
"665645.0000","40.0755","66.7925","-159.2072"
"666265.0000","40.0755","66.7925","-159.4099"
"666885.0000","40.0755","66.7925","-163.5275"
"667505.0000","40.0755","66.7925","-170.8341"
"668125.0000","40.0755","66.7925","-170.2796"
"668745.0000","40.0755","66.7925","-170.2551"
"669365.0000","40.0755","66.7925","-170.8069"
"669985.0000","40.0755","66.7925","-170.5554"
"670605.0000","40.0755","66.7925","-166.3383"
"671225.0000","40.0755","66.7925","-164.4449"
"671845.0000","40.0755","66.7925","-166.9042"
"672465.0000","40.0755","66.7925","-155.2162"
"673085.0000","40.0755","66.7925","-144.5044"
"673705.0000","40.0755","66.7925","-134.9919"
"674325.0000","40.0755","66.7925","-126.5616"
"674945.0000","40.0755","66.7925","-123.4035"
"675565.0000","40.0755","66.7925","-131.3165"
"676185.0000","40.0755","66.7925","-139.1612"
"676805.0000","40.0755","66.7925","-142.3235"
"677425.0000","40.0755","66.7925","-137.8979"
"678045.0000","40.0755","66.7925","-127.5769"
"678665.0000","40.0755","66.7925","-118.8868"
"679285.0000","40.0755","66.7925","-111.3886"
"679905.0000","40.0755","66.7925","-115.3966"
"680525.0000","40.0755","66.7925","-122.4926"
"681145.0000","40.0755","66.7925","-118.7091"
"681765.0000","40.0755","66.7925","-109.1161"
"682385.0000","40.0755","66.7925","-100.0722"
"683005.0000","40.0755","66.7925","-90.0613"
"683625.0000","40.0755","66.7925","-79.1394"
"684245.0000","40.0755","66.7925","-67.7353"
"684865.0000","40.0755","66.7925","-51.9508"
"685485.0000","40.0755","66.7925","-25.3520"
"685924.0000","40.0755","66.7925","-9.5163"